Workbook

Sheet CONSOLIDADO
B1: AUTOMÓVILES VAGONETAS Y JEEP | C1: CAMIONETAS | D1: MINIBUSES | E1: MICROBUSES (DOS EJES) | F1: BÚS MEDIANO (DOS EJES) | G1: BÚS GRANDE (DOS O MAS EJES) | H1: CAMIÓN MEDIANO (DOS EJES) | I1: CAMIÓN GRANDE ( DOS EJES) | J1: CAMION GRANDE (TRES EJES) | K1: CAMIÓN CON SEMIRREMOLQUE | L1: CAMION CON REMOLQUE | M1: MOTOCICLETAS | N1: OTROS VEHICULOS
A2: Sabado | B2: ='[1]DP8 CAIHUASI S1'!B35 -> 549 | C2: ='[1]DP8 CAIHUASI S1'!C35 -> 94 | D2: ='[1]DP8 CAIHUASI S1'!D35 -> 323 | E2: ='[1]DP8 CAIHUASI S1'!E35 -> 0 | F2: ='[1]DP8 CAIHUASI S1'!F35 -> 40 | G2: ='[1]DP8 CAIHUASI S1'!G35 -> 268 | H2: ='[1]DP8 CAIHUASI S1'!H35 -> 44 | I2: ='[1]DP8 CAIHUASI S1'!I35 -> 110 | ... N2: ='[1]DP8 CAIHUASI S1'!N35 -> 0
A3: Domingo | B3: ='[2]DP8 CAIHUASI S1'!B35 -> 642 | C3: ='[2]DP8 CAIHUASI S1'!C35 -> 74 | D3: ='[2]DP8 CAIHUASI S1'!D35 -> 273 | E3: ='[2]DP8 CAIHUASI S1'!E35 -> 0 | F3: ='[2]DP8 CAIHUASI S1'!F35 -> 48 | G3: ='[2]DP8 CAIHUASI S1'!G35 -> 245 | H3: ='[2]DP8 CAIHUASI S1'!H35 -> 20 | I3: ='[2]DP8 CAIHUASI S1'!I35 -> 109 | ... N3: ='[2]DP8 CAIHUASI S1'!N35 -> 0
A4: Lunes | B4: ='[3]DP8 CAIHUASI S1'!B35 -> 512 | C4: ='[3]DP8 CAIHUASI S1'!C35 -> 90 | D4: ='[3]DP8 CAIHUASI S1'!D35 -> 242 | E4: ='[3]DP8 CAIHUASI S1'!E35 -> 4 | F4: ='[3]DP8 CAIHUASI S1'!F35 -> 24 | G4: ='[3]DP8 CAIHUASI S1'!G35 -> 307 | H4: ='[3]DP8 CAIHUASI S1'!H35 -> 25 | I4: ='[3]DP8 CAIHUASI S1'!I35 -> 101 | ... N4: ='[3]DP8 CAIHUASI S1'!N35 -> 0
A5: Martes | B5: ='[4]DP8 CAIHUASI S1'!B35 -> 369 | C5: ='[4]DP8 CAIHUASI S1'!C35 -> 64 | D5: ='[4]DP8 CAIHUASI S1'!D35 -> 240 | E5: ='[4]DP8 CAIHUASI S1'!E35 -> 1 | F5: ='[4]DP8 CAIHUASI S1'!F35 -> 44 | G5: ='[4]DP8 CAIHUASI S1'!G35 -> 254 | H5: ='[4]DP8 CAIHUASI S1'!H35 -> 22 | I5: ='[4]DP8 CAIHUASI S1'!I35 -> 113 | ... N5: ='[4]DP8 CAIHUASI S1'!N35 -> 0
A6: Miércoles | B6: ='[5]DP8 CAIHUASI S1'!B35 -> 373 | C6: ='[5]DP8 CAIHUASI S1'!C35 -> 77 | D6: ='[5]DP8 CAIHUASI S1'!D35 -> 230 | E6: ='[5]DP8 CAIHUASI S1'!E35 -> 1 | F6: ='[5]DP8 CAIHUASI S1'!F35 -> 45 | G6: ='[5]DP8 CAIHUASI S1'!G35 -> 316 | H6: ='[5]DP8 CAIHUASI S1'!H35 -> 34 | I6: ='[5]DP8 CAIHUASI S1'!I35 -> 159 | ... N6: ='[5]DP8 CAIHUASI S1'!N35 -> 0
A7: Jueves | B7: ='[6]DP8 CAIHUASI S1'!B35 -> 359 | C7: ='[6]DP8 CAIHUASI S1'!C35 -> 82 | D7: ='[6]DP8 CAIHUASI S1'!D35 -> 260 | E7: ='[6]DP8 CAIHUASI S1'!E35 -> 1 | F7: ='[6]DP8 CAIHUASI S1'!F35 -> 46 | G7: ='[6]DP8 CAIHUASI S1'!G35 -> 315 | H7: ='[6]DP8 CAIHUASI S1'!H35 -> 26 | I7: ='[6]DP8 CAIHUASI S1'!I35 -> 121 | ... N7: ='[6]DP8 CAIHUASI S1'!N35 -> 0
A8: Viernes | B8: ='[7]DP8 CAIHUASI S1'!B35 -> 389 | C8: ='[7]DP8 CAIHUASI S1'!C35 -> 81 | D8: ='[7]DP8 CAIHUASI S1'!D35 -> 249 | E8: ='[7]DP8 CAIHUASI S1'!E35 -> 1 | F8: ='[7]DP8 CAIHUASI S1'!F35 -> 53 | G8: ='[7]DP8 CAIHUASI S1'!G35 -> 371 | H8: ='[7]DP8 CAIHUASI S1'!H35 -> 39 | I8: ='[7]DP8 CAIHUASI S1'!I35 -> 121 | ... N8: ='[7]DP8 CAIHUASI S1'!N35 -> 0
A9: TOTAL | B9: =SUM(B2:B8) -> 3193 | C9: =SUM(C2:C8) -> 562 | D9: =SUM(D2:D8) -> 1817 | E9: =SUM(E2:E8) -> 8 | F9: =SUM(F2:F8) -> 300 | G9: =SUM(G2:G8) -> 2076 | H9: =SUM(H2:H8) -> 210 | I9: =SUM(I2:I8) -> 834 | ... N9: =SUM(N2:N8) -> 0 | Q9: =O9/O35 -> #DIV/0!
A10: PROMEDIO
B14: AUTOMÓVILES VAGONETAS Y JEEP | C14: CAMIONETAS | D14: MINIBUSES | E14: MICROBUSES (DOS EJES) | F14: BÚS MEDIANO (DOS EJES) | G14: BÚS GRANDE (DOS O MAS EJES) | H14: CAMIÓN MEDIANO (DOS EJES) | I14: CAMIÓN GRANDE ( DOS EJES) | J14: CAMION GRANDE (TRES EJES) | K14: CAMIÓN CON SEMIRREMOLQUE | L14: CAMION CON REMOLQUE | M14: MOTOCICLETAS | N14: OTROS VEHICULOS
A15: Sabado | B15: ='[1]DP6 CAIHUASI S2'!B35 -> 531 | C15: ='[1]DP6 CAIHUASI S2'!C35 -> 87 | D15: ='[1]DP6 CAIHUASI S2'!D35 -> 247 | E15: ='[1]DP6 CAIHUASI S2'!E35 -> 3 | F15: ='[1]DP6 CAIHUASI S2'!F35 -> 26 | G15: ='[1]DP6 CAIHUASI S2'!G35 -> 208 | H15: ='[1]DP6 CAIHUASI S2'!H35 -> 22 | I15: ='[1]DP6 CAIHUASI S2'!I35 -> 68 | ... N15: ='[1]DP6 CAIHUASI S2'!N35 -> 0
A16: Domingo | B16: ='[2]DP6 CAIHUASI S2'!B35 -> 781 | C16: ='[2]DP6 CAIHUASI S2'!C35 -> 103 | D16: ='[2]DP6 CAIHUASI S2'!D35 -> 295 | E16: ='[2]DP6 CAIHUASI S2'!E35 -> 1 | F16: ='[2]DP6 CAIHUASI S2'!F35 -> 34 | G16: ='[2]DP6 CAIHUASI S2'!G35 -> 293 | H16: ='[2]DP6 CAIHUASI S2'!H35 -> 29 | I16: ='[2]DP6 CAIHUASI S2'!I35 -> 99 | ... N16: ='[2]DP6 CAIHUASI S2'!N35 -> 0
A17: Lunes | B17: ='[3]DP6 CAIHUASI S2'!B35 -> 596 | C17: ='[3]DP6 CAIHUASI S2'!C35 -> 79 | D17: ='[3]DP6 CAIHUASI S2'!D35 -> 293 | E17: ='[3]DP6 CAIHUASI S2'!E35 -> 2 | F17: ='[3]DP6 CAIHUASI S2'!F35 -> 78 | G17: ='[3]DP6 CAIHUASI S2'!G35 -> 271 | H17: ='[3]DP6 CAIHUASI S2'!H35 -> 20 | I17: ='[3]DP6 CAIHUASI S2'!I35 -> 118 | ... N17: ='[3]DP6 CAIHUASI S2'!N35 -> 0
A18: Martes | B18: ='[4]DP6 CAIHUASI S2'!B35 -> 410 | C18: ='[4]DP6 CAIHUASI S2'!C35 -> 76 | D18: ='[4]DP6 CAIHUASI S2'!D35 -> 259 | E18: ='[4]DP6 CAIHUASI S2'!E35 -> 1 | F18: ='[4]DP6 CAIHUASI S2'!F35 -> 23 | G18: ='[4]DP6 CAIHUASI S2'!G35 -> 273 | H18: ='[4]DP6 CAIHUASI S2'!H35 -> 15 | I18: ='[4]DP6 CAIHUASI S2'!I35 -> 128 | ... N18: ='[4]DP6 CAIHUASI S2'!N35 -> 0
A19: Miércoles | B19: ='[5]DP6 CAIHUASI S2'!B35 -> 414 | C19: ='[5]DP6 CAIHUASI S2'!C35 -> 99 | D19: ='[5]DP6 CAIHUASI S2'!D35 -> 279 | E19: ='[5]DP6 CAIHUASI S2'!E35 -> 2 | F19: ='[5]DP6 CAIHUASI S2'!F35 -> 36 | G19: ='[5]DP6 CAIHUASI S2'!G35 -> 305 | H19: ='[5]DP6 CAIHUASI S2'!H35 -> 28 | I19: ='[5]DP6 CAIHUASI S2'!I35 -> 128 | ... N19: ='[5]DP6 CAIHUASI S2'!N35 -> 0
A20: Jueves | B20: ='[6]DP6 CAIHUASI S2'!B35 -> 370 | C20: ='[6]DP6 CAIHUASI S2'!C35 -> 86 | D20: ='[6]DP6 CAIHUASI S2'!D35 -> 249 | E20: ='[6]DP6 CAIHUASI S2'!E35 -> 5 | F20: ='[6]DP6 CAIHUASI S2'!F35 -> 46 | G20: ='[6]DP6 CAIHUASI S2'!G35 -> 311 | H20: ='[6]DP6 CAIHUASI S2'!H35 -> 30 | I20: ='[6]DP6 CAIHUASI S2'!I35 -> 132 | ... N20: ='[6]DP6 CAIHUASI S2'!N35 -> 0
A21: Viernes | B21: ='[7]DP6 CAIHUASI S2'!B35 -> 401 | C21: ='[7]DP6 CAIHUASI S2'!C35 -> 87 | D21: ='[7]DP6 CAIHUASI S2'!D35 -> 280 | E21: ='[7]DP6 CAIHUASI S2'!E35 -> 1 | F21: ='[7]DP6 CAIHUASI S2'!F35 -> 52 | G21: ='[7]DP6 CAIHUASI S2'!G35 -> 363 | H21: ='[7]DP6 CAIHUASI S2'!H35 -> 36 | I21: ='[7]DP6 CAIHUASI S2'!I35 -> 135 | ... N21: ='[7]DP6 CAIHUASI S2'!N35 -> 0
A22: TOTAL | B22: =SUM(B15:B21) -> 3503 | C22: =SUM(C15:C21) -> 617 | D22: =SUM(D15:D21) -> 1902 | E22: =SUM(E15:E21) -> 15 | F22: =SUM(F15:F21) -> 295 | G22: =SUM(G15:G21) -> 2024 | H22: =SUM(H15:H21) -> 180 | I22: =SUM(I15:I21) -> 808 | ... N22: =SUM(N15:N21) -> 0 | Q22: =O22/#REF! -> #REF!
B27: AUTOMÓVILES VAGONETAS Y JEEP | C27: CAMIONETAS | D27: MINIBUSES | E27: MICROBUSES (DOS EJES) | F27: BÚS MEDIANO (DOS EJES) | G27: BÚS GRANDE (DOS O MAS EJES) | H27: CAMIÓN MEDIANO (DOS EJES) | I27: CAMIÓN GRANDE ( DOS EJES) | J27: CAMION GRANDE (TRES EJES) | K27: CAMIÓN CON SEMIRREMOLQUE | L27: CAMION CON REMOLQUE | M27: MOTOCICLETAS | N27: OTROS VEHICULOS | P27: TOTAL
A28: Sabado | B28: =B2+B15 -> 1080 | C28: =C2+C15 -> 181 | D28: =D2+D15 -> 570 | E28: =E2+E15 -> 3 | F28: =F2+F15 -> 66 | G28: =G2+G15 -> 476 | H28: =H2+H15 -> 66 | I28: =I2+I15 -> 178 | ... N28: =N2+N15 -> 0 | P28: =O28/7 -> 0
A29: Domingo | B29: =B3+B16 -> 1423 | C29: =C3+C16 -> 177 | D29: =D3+D16 -> 568 | E29: =E3+E16 -> 1 | F29: =F3+F16 -> 82 | G29: =G3+G16 -> 538 | H29: =H3+H16 -> 49 | I29: =I3+I16 -> 208 | ... N29: =N3+N16 -> 0 | P29: =O29/7 -> 0
A30: Lunes | B30: =B4+B17 -> 1108 | C30: =C4+C17 -> 169 | D30: =D4+D17 -> 535 | E30: =E4+E17 -> 6 | F30: =F4+F17 -> 102 | G30: =G4+G17 -> 578 | H30: =H4+H17 -> 45 | I30: =I4+I17 -> 219 | ... N30: =N4+N17 -> 0 | P30: =O30/7 -> 0
A31: Martes | B31: =B5+B18 -> 779 | C31: =C5+C18 -> 140 | D31: =D5+D18 -> 499 | E31: =E5+E18 -> 2 | F31: =F5+F18 -> 67 | G31: =G5+G18 -> 527 | H31: =H5+H18 -> 37 | I31: =I5+I18 -> 241 | ... N31: =N5+N18 -> 0 | P31: =O31/7 -> 0
A32: Miércoles | B32: =B6+B19 -> 787 | C32: =C6+C19 -> 176 | D32: =D6+D19 -> 509 | E32: =E6+E19 -> 3 | F32: =F6+F19 -> 81 | G32: =G6+G19 -> 621 | H32: =H6+H19 -> 62 | I32: =I6+I19 -> 287 | ... N32: =N6+N19 -> 0 | P32: =O32/7 -> 0
A33: Jueves | B33: =B7+B20 -> 729 | C33: =C7+C20 -> 168 | D33: =D7+D20 -> 509 | E33: =E7+E20 -> 6 | F33: =F7+F20 -> 92 | G33: =G7+G20 -> 626 | H33: =H7+H20 -> 56 | I33: =I7+I20 -> 253 | ... N33: =N7+N20 -> 0 | P33: =O33/7 -> 0
A34: Viernes | B34: =B8+B21 -> 790 | C34: =C8+C21 -> 168 | D34: =D8+D21 -> 529 | E34: =E8+E21 -> 2 | F34: =F8+F21 -> 105 | G34: =G8+G21 -> 734 | H34: =H8+H21 -> 75 | I34: =I8+I21 -> 256 | ... N34: =N8+N21 -> 0 | P34: =O34/7 -> 0
A35: TOTAL | B35: =SUM(B28:B34) -> 6696 | C35: =C9+C22 -> 1179 | D35: =D9+D22 -> 3719 | E35: =E9+E22 -> 23 | F35: =F9+F22 -> 595 | G35: =G9+G22 -> 4100 | H35: =H9+H22 -> 390 | I35: =I9+I22 -> 1642 | J35: =J9+J22 -> 2751 | ... N35: =N9+N22 -> 0

Sheet FACTOR ESTACIONA
A1: N° | B1: VEHÍCULOS | C1: fe
A2: Enero | B2: 1752
A3: Febrero | B3: 1518
A4: Marzo | B4: 1424
A5: Abril | B5: 1500
A6: Mayo | B6: 1339
A7: Junio | B7: 1547
A8: Julio | B8: 1922
A9: Agosto | B9: 2039
A10: Septiembre | B10: 1666
A11: Octubre | B11: 1648
A12: Noviembre | B12: 1489
A13: Diciembre | B13: 1810

Sheet vpth
A1: HORA DE - A | B1: AUTOMÓVILES VAGONETAS Y JEEP | C1: CAMIONETAS | D1: MINIBUSES | E1: MICROBUSES (DOS EJES) | F1: BÚS MEDIANO (DOS EJES) | G1: BÚS GRANDE (DOS O MAS EJES) | H1: CAMIÓN MEDIANO (DOS EJES) | I1: CAMIÓN GRANDE ( DOS EJES) | J1: CAMION GRANDE (TRES EJES) | K1: CAMIÓN CON SEMIRREMOLQUE | L1: CAMION CON REMOLQUE | M1: MOTOCICLETAS | N1: OTROS VEHICULOS | O1: TOTAL | P1: PORCENTAJE
A2: 0 - 1 | B2: ='[1]Ambos lados'!B11+'[2]Ambos lados'!B11+'[3]Ambos lados'!B11+'[4]Ambos lados'!B11+'[5]Ambos lados'!B11+'[6]Ambos lados'!B11+'[7]Ambos lados'!B11 -> 149 | C2: ='[1]Ambos lados'!C11+'[2]Ambos lados'!C11+'[3]Ambos lados'!C11+'[4]Ambos lados'!C11+'[5]Ambos lados'!C11+'[6]Ambos lados'!C11+'[7]Ambos lados'!C11 -> 35 | D2: ='[1]Ambos lados'!D11+'[2]Ambos lados'!D11+'[3]Ambos lados'!D11+'[4]Ambos lados'!D11+'[5]Ambos lados'!D11+'[6]Ambos lados'!D11+'[7]Ambos lados'!D11 -> 41 | E2: ='[1]Ambos lados'!E11+'[2]Ambos lados'!E11+'[3]Ambos lados'!E11+'[4]Ambos lados'!E11+'[5]Ambos lados'!E11+'[6]Ambos lados'!E11+'[7]Ambos lados'!E11 -> 0 | F2: ='[1]Ambos lados'!F11+'[2]Ambos lados'!F11+'[3]Ambos lados'!F11+'[4]Ambos lados'!F11+'[5]Ambos lados'!F11+'[6]Ambos lados'!F11+'[7]Ambos lados'!F11 -> 32 | G2: ='[1]Ambos lados'!G11+'[2]Ambos lados'!G11+'[3]Ambos lados'!G11+'[4]Ambos lados'!G11+'[5]Ambos lados'!G11+'[6]Ambos lados'!G11+'[7]Ambos lados'!G11 -> 215 | H2: ='[1]Ambos lados'!H11+'[2]Ambos lados'!H11+'[3]Ambos lados'!H11+'[4]Ambos lados'!H11+'[5]Ambos lados'!H11+'[6]Ambos lados'!H11+'[7]Ambos lados'!H11 -> 23 | I2: ='[1]Ambos lados'!I11+'[2]Ambos lados'!I11+'[3]Ambos lados'!I11+'[4]Ambos lados'!I11+'[5]Ambos lados'!I11+'[6]Ambos lados'!I11+'[7]Ambos lados'!I11 -> 65 | ... N2: ='[1]Ambos lados'!N11+'[2]Ambos lados'!N11+'[3]Ambos lados'!N11+'[4]Ambos lados'!N11+'[5]Ambos lados'!N11+'[6]Ambos lados'!N11+'[7]Ambos lados'!N11 -> 0 | O2: =('[1]Ambos lados'!O11+'[2]Ambos lados'!O11+'[3]Ambos lados'!O11+'[4]Ambos lados'!O11+'[5]Ambos lados'!O11+'[6]Ambos lados'!O11+'[7]Ambos lados'!O11)/7 -> 122.85714 | P2: =O2/$O$26 -> 0.033167496
A3: 1 - 2 | B3: ='[1]Ambos lados'!B12+'[2]Ambos lados'!B12+'[3]Ambos lados'!B12+'[4]Ambos lados'!B12+'[5]Ambos lados'!B12+'[6]Ambos lados'!B12+'[7]Ambos lados'!B12 -> 87 | C3: ='[1]Ambos lados'!C12+'[2]Ambos lados'!C12+'[3]Ambos lados'!C12+'[4]Ambos lados'!C12+'[5]Ambos lados'!C12+'[6]Ambos lados'!C12+'[7]Ambos lados'!C12 -> 16 | D3: ='[1]Ambos lados'!D12+'[2]Ambos lados'!D12+'[3]Ambos lados'!D12+'[4]Ambos lados'!D12+'[5]Ambos lados'!D12+'[6]Ambos lados'!D12+'[7]Ambos lados'!D12 -> 63 | E3: ='[1]Ambos lados'!E12+'[2]Ambos lados'!E12+'[3]Ambos lados'!E12+'[4]Ambos lados'!E12+'[5]Ambos lados'!E12+'[6]Ambos lados'!E12+'[7]Ambos lados'!E12 -> 0 | F3: ='[1]Ambos lados'!F12+'[2]Ambos lados'!F12+'[3]Ambos lados'!F12+'[4]Ambos lados'!F12+'[5]Ambos lados'!F12+'[6]Ambos lados'!F12+'[7]Ambos lados'!F12 -> 29 | G3: ='[1]Ambos lados'!G12+'[2]Ambos lados'!G12+'[3]Ambos lados'!G12+'[4]Ambos lados'!G12+'[5]Ambos lados'!G12+'[6]Ambos lados'!G12+'[7]Ambos lados'!G12 -> 326 | H3: ='[1]Ambos lados'!H12+'[2]Ambos lados'!H12+'[3]Ambos lados'!H12+'[4]Ambos lados'!H12+'[5]Ambos lados'!H12+'[6]Ambos lados'!H12+'[7]Ambos lados'!H12 -> 11 | I3: ='[1]Ambos lados'!I12+'[2]Ambos lados'!I12+'[3]Ambos lados'!I12+'[4]Ambos lados'!I12+'[5]Ambos lados'!I12+'[6]Ambos lados'!I12+'[7]Ambos lados'!I12 -> 66 | ... N3: ='[1]Ambos lados'!N12+'[2]Ambos lados'!N12+'[3]Ambos lados'!N12+'[4]Ambos lados'!N12+'[5]Ambos lados'!N12+'[6]Ambos lados'!N12+'[7]Ambos lados'!N12 -> 0 | O3: =('[1]Ambos lados'!O12+'[2]Ambos lados'!O12+'[3]Ambos lados'!O12+'[4]Ambos lados'!O12+'[5]Ambos lados'!O12+'[6]Ambos lados'!O12+'[7]Ambos lados'!O12)/7 -> 124.57143 | P3: =O3/$O$26 -> 0.033630298
A4: 2 - 3 | B4: ='[1]Ambos lados'!B13+'[2]Ambos lados'!B13+'[3]Ambos lados'!B13+'[4]Ambos lados'!B13+'[5]Ambos lados'!B13+'[6]Ambos lados'!B13+'[7]Ambos lados'!B13 -> 103 | C4: ='[1]Ambos lados'!C13+'[2]Ambos lados'!C13+'[3]Ambos lados'!C13+'[4]Ambos lados'!C13+'[5]Ambos lados'!C13+'[6]Ambos lados'!C13+'[7]Ambos lados'!C13 -> 11 | D4: ='[1]Ambos lados'!D13+'[2]Ambos lados'!D13+'[3]Ambos lados'!D13+'[4]Ambos lados'!D13+'[5]Ambos lados'!D13+'[6]Ambos lados'!D13+'[7]Ambos lados'!D13 -> 48 | E4: ='[1]Ambos lados'!E13+'[2]Ambos lados'!E13+'[3]Ambos lados'!E13+'[4]Ambos lados'!E13+'[5]Ambos lados'!E13+'[6]Ambos lados'!E13+'[7]Ambos lados'!E13 -> 1 | F4: ='[1]Ambos lados'!F13+'[2]Ambos lados'!F13+'[3]Ambos lados'!F13+'[4]Ambos lados'!F13+'[5]Ambos lados'!F13+'[6]Ambos lados'!F13+'[7]Ambos lados'!F13 -> 16 | G4: ='[1]Ambos lados'!G13+'[2]Ambos lados'!G13+'[3]Ambos lados'!G13+'[4]Ambos lados'!G13+'[5]Ambos lados'!G13+'[6]Ambos lados'!G13+'[7]Ambos lados'!G13 -> 346 | H4: ='[1]Ambos lados'!H13+'[2]Ambos lados'!H13+'[3]Ambos lados'!H13+'[4]Ambos lados'!H13+'[5]Ambos lados'!H13+'[6]Ambos lados'!H13+'[7]Ambos lados'!H13 -> 12 | I4: ='[1]Ambos lados'!I13+'[2]Ambos lados'!I13+'[3]Ambos lados'!I13+'[4]Ambos lados'!I13+'[5]Ambos lados'!I13+'[6]Ambos lados'!I13+'[7]Ambos lados'!I13 -> 55 | ... N4: ='[1]Ambos lados'!N13+'[2]Ambos lados'!N13+'[3]Ambos lados'!N13+'[4]Ambos lados'!N13+'[5]Ambos lados'!N13+'[6]Ambos lados'!N13+'[7]Ambos lados'!N13 -> 0 | O4: =('[1]Ambos lados'!O13+'[2]Ambos lados'!O13+'[3]Ambos lados'!O13+'[4]Ambos lados'!O13+'[5]Ambos lados'!O13+'[6]Ambos lados'!O13+'[7]Ambos lados'!O13)/7 -> 112.85714 | P4: =O4/$O$26 -> 0.030467816
A5: 3 - 4 | B5: ='[1]Ambos lados'!B14+'[2]Ambos lados'!B14+'[3]Ambos lados'!B14+'[4]Ambos lados'!B14+'[5]Ambos lados'!B14+'[6]Ambos lados'!B14+'[7]Ambos lados'!B14 -> 110 | C5: ='[1]Ambos lados'!C14+'[2]Ambos lados'!C14+'[3]Ambos lados'!C14+'[4]Ambos lados'!C14+'[5]Ambos lados'!C14+'[6]Ambos lados'!C14+'[7]Ambos lados'!C14 -> 21 | D5: ='[1]Ambos lados'!D14+'[2]Ambos lados'!D14+'[3]Ambos lados'!D14+'[4]Ambos lados'!D14+'[5]Ambos lados'!D14+'[6]Ambos lados'!D14+'[7]Ambos lados'!D14 -> 39 | E5: ='[1]Ambos lados'!E14+'[2]Ambos lados'!E14+'[3]Ambos lados'!E14+'[4]Ambos lados'!E14+'[5]Ambos lados'!E14+'[6]Ambos lados'!E14+'[7]Ambos lados'!E14 -> 0 | F5: ='[1]Ambos lados'!F14+'[2]Ambos lados'!F14+'[3]Ambos lados'!F14+'[4]Ambos lados'!F14+'[5]Ambos lados'!F14+'[6]Ambos lados'!F14+'[7]Ambos lados'!F14 -> 60 | G5: ='[1]Ambos lados'!G14+'[2]Ambos lados'!G14+'[3]Ambos lados'!G14+'[4]Ambos lados'!G14+'[5]Ambos lados'!G14+'[6]Ambos lados'!G14+'[7]Ambos lados'!G14 -> 215 | H5: ='[1]Ambos lados'!H14+'[2]Ambos lados'!H14+'[3]Ambos lados'!H14+'[4]Ambos lados'!H14+'[5]Ambos lados'!H14+'[6]Ambos lados'!H14+'[7]Ambos lados'!H14 -> 7 | I5: ='[1]Ambos lados'!I14+'[2]Ambos lados'!I14+'[3]Ambos lados'!I14+'[4]Ambos lados'!I14+'[5]Ambos lados'!I14+'[6]Ambos lados'!I14+'[7]Ambos lados'!I14 -> 38 | ... N5: ='[1]Ambos lados'!N14+'[2]Ambos lados'!N14+'[3]Ambos lados'!N14+'[4]Ambos lados'!N14+'[5]Ambos lados'!N14+'[6]Ambos lados'!N14+'[7]Ambos lados'!N14 -> 0 | O5: =('[1]Ambos lados'!O14+'[2]Ambos lados'!O14+'[3]Ambos lados'!O14+'[4]Ambos lados'!O14+'[5]Ambos lados'!O14+'[6]Ambos lados'!O14+'[7]Ambos lados'!O14)/7 -> 103 | P5: =O5/$O$26 -> 0.027806703
A6: 4 - 5 | B6: ='[1]Ambos lados'!B15+'[2]Ambos lados'!B15+'[3]Ambos lados'!B15+'[4]Ambos lados'!B15+'[5]Ambos lados'!B15+'[6]Ambos lados'!B15+'[7]Ambos lados'!B15 -> 90 | C6: ='[1]Ambos lados'!C15+'[2]Ambos lados'!C15+'[3]Ambos lados'!C15+'[4]Ambos lados'!C15+'[5]Ambos lados'!C15+'[6]Ambos lados'!C15+'[7]Ambos lados'!C15 -> 21 | D6: ='[1]Ambos lados'!D15+'[2]Ambos lados'!D15+'[3]Ambos lados'!D15+'[4]Ambos lados'!D15+'[5]Ambos lados'!D15+'[6]Ambos lados'!D15+'[7]Ambos lados'!D15 -> 47 | E6: ='[1]Ambos lados'!E15+'[2]Ambos lados'!E15+'[3]Ambos lados'!E15+'[4]Ambos lados'!E15+'[5]Ambos lados'!E15+'[6]Ambos lados'!E15+'[7]Ambos lados'!E15 -> 0 | F6: ='[1]Ambos lados'!F15+'[2]Ambos lados'!F15+'[3]Ambos lados'!F15+'[4]Ambos lados'!F15+'[5]Ambos lados'!F15+'[6]Ambos lados'!F15+'[7]Ambos lados'!F15 -> 10 | G6: ='[1]Ambos lados'!G15+'[2]Ambos lados'!G15+'[3]Ambos lados'!G15+'[4]Ambos lados'!G15+'[5]Ambos lados'!G15+'[6]Ambos lados'!G15+'[7]Ambos lados'!G15 -> 149 | H6: ='[1]Ambos lados'!H15+'[2]Ambos lados'!H15+'[3]Ambos lados'!H15+'[4]Ambos lados'!H15+'[5]Ambos lados'!H15+'[6]Ambos lados'!H15+'[7]Ambos lados'!H15 -> 9 | I6: ='[1]Ambos lados'!I15+'[2]Ambos lados'!I15+'[3]Ambos lados'!I15+'[4]Ambos lados'!I15+'[5]Ambos lados'!I15+'[6]Ambos lados'!I15+'[7]Ambos lados'!I15 -> 50 | ... N6: ='[1]Ambos lados'!N15+'[2]Ambos lados'!N15+'[3]Ambos lados'!N15+'[4]Ambos lados'!N15+'[5]Ambos lados'!N15+'[6]Ambos lados'!N15+'[7]Ambos lados'!N15 -> 0 | O6: =('[1]Ambos lados'!O15+'[2]Ambos lados'!O15+'[3]Ambos lados'!O15+'[4]Ambos lados'!O15+'[5]Ambos lados'!O15+'[6]Ambos lados'!O15+'[7]Ambos lados'!O15)/7 -> 89.142857 | P6: =O6/$O$26 -> 0.024065718
A7: 5 - 6 | B7: ='[1]Ambos lados'!B16+'[2]Ambos lados'!B16+'[3]Ambos lados'!B16+'[4]Ambos lados'!B16+'[5]Ambos lados'!B16+'[6]Ambos lados'!B16+'[7]Ambos lados'!B16 -> 155 | C7: ='[1]Ambos lados'!C16+'[2]Ambos lados'!C16+'[3]Ambos lados'!C16+'[4]Ambos lados'!C16+'[5]Ambos lados'!C16+'[6]Ambos lados'!C16+'[7]Ambos lados'!C16 -> 31 | D7: ='[1]Ambos lados'!D16+'[2]Ambos lados'!D16+'[3]Ambos lados'!D16+'[4]Ambos lados'!D16+'[5]Ambos lados'!D16+'[6]Ambos lados'!D16+'[7]Ambos lados'!D16 -> 102 | E7: ='[1]Ambos lados'!E16+'[2]Ambos lados'!E16+'[3]Ambos lados'!E16+'[4]Ambos lados'!E16+'[5]Ambos lados'!E16+'[6]Ambos lados'!E16+'[7]Ambos lados'!E16 -> 0 | F7: ='[1]Ambos lados'!F16+'[2]Ambos lados'!F16+'[3]Ambos lados'!F16+'[4]Ambos lados'!F16+'[5]Ambos lados'!F16+'[6]Ambos lados'!F16+'[7]Ambos lados'!F16 -> 22 | G7: ='[1]Ambos lados'!G16+'[2]Ambos lados'!G16+'[3]Ambos lados'!G16+'[4]Ambos lados'!G16+'[5]Ambos lados'!G16+'[6]Ambos lados'!G16+'[7]Ambos lados'!G16 -> 137 | H7: ='[1]Ambos lados'!H16+'[2]Ambos lados'!H16+'[3]Ambos lados'!H16+'[4]Ambos lados'!H16+'[5]Ambos lados'!H16+'[6]Ambos lados'!H16+'[7]Ambos lados'!H16 -> 29 | I7: ='[1]Ambos lados'!I16+'[2]Ambos lados'!I16+'[3]Ambos lados'!I16+'[4]Ambos lados'!I16+'[5]Ambos lados'!I16+'[6]Ambos lados'!I16+'[7]Ambos lados'!I16 -> 81 | ... N7: ='[1]Ambos lados'!N16+'[2]Ambos lados'!N16+'[3]Ambos lados'!N16+'[4]Ambos lados'!N16+'[5]Ambos lados'!N16+'[6]Ambos lados'!N16+'[7]Ambos lados'!N16 -> 0 | O7: =('[1]Ambos lados'!O16+'[2]Ambos lados'!O16+'[3]Ambos lados'!O16+'[4]Ambos lados'!O16+'[5]Ambos lados'!O16+'[6]Ambos lados'!O16+'[7]Ambos lados'!O16)/7 -> 128.71429 | P7: =O7/$O$26 -> 0.034748737
A8: 6 - 7 | B8: ='[1]Ambos lados'!B17+'[2]Ambos lados'!B17+'[3]Ambos lados'!B17+'[4]Ambos lados'!B17+'[5]Ambos lados'!B17+'[6]Ambos lados'!B17+'[7]Ambos lados'!B17 -> 208 | C8: ='[1]Ambos lados'!C17+'[2]Ambos lados'!C17+'[3]Ambos lados'!C17+'[4]Ambos lados'!C17+'[5]Ambos lados'!C17+'[6]Ambos lados'!C17+'[7]Ambos lados'!C17 -> 39 | D8: ='[1]Ambos lados'!D17+'[2]Ambos lados'!D17+'[3]Ambos lados'!D17+'[4]Ambos lados'!D17+'[5]Ambos lados'!D17+'[6]Ambos lados'!D17+'[7]Ambos lados'!D17 -> 170 | E8: ='[1]Ambos lados'!E17+'[2]Ambos lados'!E17+'[3]Ambos lados'!E17+'[4]Ambos lados'!E17+'[5]Ambos lados'!E17+'[6]Ambos lados'!E17+'[7]Ambos lados'!E17 -> 1 | F8: ='[1]Ambos lados'!F17+'[2]Ambos lados'!F17+'[3]Ambos lados'!F17+'[4]Ambos lados'!F17+'[5]Ambos lados'!F17+'[6]Ambos lados'!F17+'[7]Ambos lados'!F17 -> 14 | G8: ='[1]Ambos lados'!G17+'[2]Ambos lados'!G17+'[3]Ambos lados'!G17+'[4]Ambos lados'!G17+'[5]Ambos lados'!G17+'[6]Ambos lados'!G17+'[7]Ambos lados'!G17 -> 91 | H8: ='[1]Ambos lados'!H17+'[2]Ambos lados'!H17+'[3]Ambos lados'!H17+'[4]Ambos lados'!H17+'[5]Ambos lados'!H17+'[6]Ambos lados'!H17+'[7]Ambos lados'!H17 -> 8 | I8: ='[1]Ambos lados'!I17+'[2]Ambos lados'!I17+'[3]Ambos lados'!I17+'[4]Ambos lados'!I17+'[5]Ambos lados'!I17+'[6]Ambos lados'!I17+'[7]Ambos lados'!I17 -> 44 | ... N8: ='[1]Ambos lados'!N17+'[2]Ambos lados'!N17+'[3]Ambos lados'!N17+'[4]Ambos lados'!N17+'[5]Ambos lados'!N17+'[6]Ambos lados'!N17+'[7]Ambos lados'!N17 -> 0 | O8: =('[1]Ambos lados'!O17+'[2]Ambos lados'!O17+'[3]Ambos lados'!O17+'[4]Ambos lados'!O17+'[5]Ambos lados'!O17+'[6]Ambos lados'!O17+'[7]Ambos lados'!O17)/7 -> 125.28571 | P8: =O8/$O$26 -> 0.033823132
A9: 7 - 8 | B9: ='[1]Ambos lados'!B18+'[2]Ambos lados'!B18+'[3]Ambos lados'!B18+'[4]Ambos lados'!B18+'[5]Ambos lados'!B18+'[6]Ambos lados'!B18+'[7]Ambos lados'!B18 -> 271 | C9: ='[1]Ambos lados'!C18+'[2]Ambos lados'!C18+'[3]Ambos lados'!C18+'[4]Ambos lados'!C18+'[5]Ambos lados'!C18+'[6]Ambos lados'!C18+'[7]Ambos lados'!C18 -> 52 | D9: ='[1]Ambos lados'!D18+'[2]Ambos lados'!D18+'[3]Ambos lados'!D18+'[4]Ambos lados'!D18+'[5]Ambos lados'!D18+'[6]Ambos lados'!D18+'[7]Ambos lados'!D18 -> 151 | E9: ='[1]Ambos lados'!E18+'[2]Ambos lados'!E18+'[3]Ambos lados'!E18+'[4]Ambos lados'!E18+'[5]Ambos lados'!E18+'[6]Ambos lados'!E18+'[7]Ambos lados'!E18 -> 2 | F9: ='[1]Ambos lados'!F18+'[2]Ambos lados'!F18+'[3]Ambos lados'!F18+'[4]Ambos lados'!F18+'[5]Ambos lados'!F18+'[6]Ambos lados'!F18+'[7]Ambos lados'!F18 -> 17 | G9: ='[1]Ambos lados'!G18+'[2]Ambos lados'!G18+'[3]Ambos lados'!G18+'[4]Ambos lados'!G18+'[5]Ambos lados'!G18+'[6]Ambos lados'!G18+'[7]Ambos lados'!G18 -> 59 | H9: ='[1]Ambos lados'!H18+'[2]Ambos lados'!H18+'[3]Ambos lados'!H18+'[4]Ambos lados'!H18+'[5]Ambos lados'!H18+'[6]Ambos lados'!H18+'[7]Ambos lados'!H18 -> 14 | I9: ='[1]Ambos lados'!I18+'[2]Ambos lados'!I18+'[3]Ambos lados'!I18+'[4]Ambos lados'!I18+'[5]Ambos lados'!I18+'[6]Ambos lados'!I18+'[7]Ambos lados'!I18 -> 46 | ... N9: ='[1]Ambos lados'!N18+'[2]Ambos lados'!N18+'[3]Ambos lados'!N18+'[4]Ambos lados'!N18+'[5]Ambos lados'!N18+'[6]Ambos lados'!N18+'[7]Ambos lados'!N18 -> 0 | O9: =('[1]Ambos lados'!O18+'[2]Ambos lados'!O18+'[3]Ambos lados'!O18+'[4]Ambos lados'!O18+'[5]Ambos lados'!O18+'[6]Ambos lados'!O18+'[7]Ambos lados'!O18)/7 -> 125.42857 | P9: =O9/$O$26 -> 0.033861699
A10: 8 - 9 | B10: ='[1]Ambos lados'!B19+'[2]Ambos lados'!B19+'[3]Ambos lados'!B19+'[4]Ambos lados'!B19+'[5]Ambos lados'!B19+'[6]Ambos lados'!B19+'[7]Ambos lados'!B19 -> 402 | C10: ='[1]Ambos lados'!C19+'[2]Ambos lados'!C19+'[3]Ambos lados'!C19+'[4]Ambos lados'!C19+'[5]Ambos lados'!C19+'[6]Ambos lados'!C19+'[7]Ambos lados'!C19 -> 78 | D10: ='[1]Ambos lados'!D19+'[2]Ambos lados'!D19+'[3]Ambos lados'!D19+'[4]Ambos lados'!D19+'[5]Ambos lados'!D19+'[6]Ambos lados'!D19+'[7]Ambos lados'!D19 -> 180 | E10: ='[1]Ambos lados'!E19+'[2]Ambos lados'!E19+'[3]Ambos lados'!E19+'[4]Ambos lados'!E19+'[5]Ambos lados'!E19+'[6]Ambos lados'!E19+'[7]Ambos lados'!E19 -> 2 | F10: ='[1]Ambos lados'!F19+'[2]Ambos lados'!F19+'[3]Ambos lados'!F19+'[4]Ambos lados'!F19+'[5]Ambos lados'!F19+'[6]Ambos lados'!F19+'[7]Ambos lados'!F19 -> 16 | G10: ='[1]Ambos lados'!G19+'[2]Ambos lados'!G19+'[3]Ambos lados'!G19+'[4]Ambos lados'!G19+'[5]Ambos lados'!G19+'[6]Ambos lados'!G19+'[7]Ambos lados'!G19 -> 78 | H10: ='[1]Ambos lados'!H19+'[2]Ambos lados'!H19+'[3]Ambos lados'!H19+'[4]Ambos lados'!H19+'[5]Ambos lados'!H19+'[6]Ambos lados'!H19+'[7]Ambos lados'!H19 -> 14 | I10: ='[1]Ambos lados'!I19+'[2]Ambos lados'!I19+'[3]Ambos lados'!I19+'[4]Ambos lados'!I19+'[5]Ambos lados'!I19+'[6]Ambos lados'!I19+'[7]Ambos lados'!I19 -> 39 | ... N10: ='[1]Ambos lados'!N19+'[2]Ambos lados'!N19+'[3]Ambos lados'!N19+'[4]Ambos lados'!N19+'[5]Ambos lados'!N19+'[6]Ambos lados'!N19+'[7]Ambos lados'!N19 -> 0 | O10: =('[1]Ambos lados'!O19+'[2]Ambos lados'!O19+'[3]Ambos lados'!O19+'[4]Ambos lados'!O19+'[5]Ambos lados'!O19+'[6]Ambos lados'!O19+'[7]Ambos lados'!O19)/7 -> 149.42857 | P10: =O10/$O$26 -> 0.040340931
A11: 9 - 10 | B11: ='[1]Ambos lados'!B20+'[2]Ambos lados'!B20+'[3]Ambos lados'!B20+'[4]Ambos lados'!B20+'[5]Ambos lados'!B20+'[6]Ambos lados'!B20+'[7]Ambos lados'!B20 -> 304 | C11: ='[1]Ambos lados'!C20+'[2]Ambos lados'!C20+'[3]Ambos lados'!C20+'[4]Ambos lados'!C20+'[5]Ambos lados'!C20+'[6]Ambos lados'!C20+'[7]Ambos lados'!C20 -> 65 | D11: ='[1]Ambos lados'!D20+'[2]Ambos lados'!D20+'[3]Ambos lados'!D20+'[4]Ambos lados'!D20+'[5]Ambos lados'!D20+'[6]Ambos lados'!D20+'[7]Ambos lados'!D20 -> 166 | E11: ='[1]Ambos lados'!E20+'[2]Ambos lados'!E20+'[3]Ambos lados'!E20+'[4]Ambos lados'!E20+'[5]Ambos lados'!E20+'[6]Ambos lados'!E20+'[7]Ambos lados'!E20 -> 1 | F11: ='[1]Ambos lados'!F20+'[2]Ambos lados'!F20+'[3]Ambos lados'!F20+'[4]Ambos lados'!F20+'[5]Ambos lados'!F20+'[6]Ambos lados'!F20+'[7]Ambos lados'!F20 -> 18 | G11: ='[1]Ambos lados'!G20+'[2]Ambos lados'!G20+'[3]Ambos lados'!G20+'[4]Ambos lados'!G20+'[5]Ambos lados'!G20+'[6]Ambos lados'!G20+'[7]Ambos lados'!G20 -> 121 | H11: ='[1]Ambos lados'!H20+'[2]Ambos lados'!H20+'[3]Ambos lados'!H20+'[4]Ambos lados'!H20+'[5]Ambos lados'!H20+'[6]Ambos lados'!H20+'[7]Ambos lados'!H20 -> 13 | I11: ='[1]Ambos lados'!I20+'[2]Ambos lados'!I20+'[3]Ambos lados'!I20+'[4]Ambos lados'!I20+'[5]Ambos lados'!I20+'[6]Ambos lados'!I20+'[7]Ambos lados'!I20 -> 46 | ... N11: ='[1]Ambos lados'!N20+'[2]Ambos lados'!N20+'[3]Ambos lados'!N20+'[4]Ambos lados'!N20+'[5]Ambos lados'!N20+'[6]Ambos lados'!N20+'[7]Ambos lados'!N20 -> 0 | O11: =('[1]Ambos lados'!O20+'[2]Ambos lados'!O20+'[3]Ambos lados'!O20+'[4]Ambos lados'!O20+'[5]Ambos lados'!O20+'[6]Ambos lados'!O20+'[7]Ambos lados'!O20)/7 -> 141.28571 | P11: =O11/$O$26 -> 0.03814262
A12: 10 - 11 | B12: ='[1]Ambos lados'!B21+'[2]Ambos lados'!B21+'[3]Ambos lados'!B21+'[4]Ambos lados'!B21+'[5]Ambos lados'!B21+'[6]Ambos lados'!B21+'[7]Ambos lados'!B21 -> 322 | C12: ='[1]Ambos lados'!C21+'[2]Ambos lados'!C21+'[3]Ambos lados'!C21+'[4]Ambos lados'!C21+'[5]Ambos lados'!C21+'[6]Ambos lados'!C21+'[7]Ambos lados'!C21 -> 75 | D12: ='[1]Ambos lados'!D21+'[2]Ambos lados'!D21+'[3]Ambos lados'!D21+'[4]Ambos lados'!D21+'[5]Ambos lados'!D21+'[6]Ambos lados'!D21+'[7]Ambos lados'!D21 -> 196 | E12: ='[1]Ambos lados'!E21+'[2]Ambos lados'!E21+'[3]Ambos lados'!E21+'[4]Ambos lados'!E21+'[5]Ambos lados'!E21+'[6]Ambos lados'!E21+'[7]Ambos lados'!E21 -> 2 | F12: ='[1]Ambos lados'!F21+'[2]Ambos lados'!F21+'[3]Ambos lados'!F21+'[4]Ambos lados'!F21+'[5]Ambos lados'!F21+'[6]Ambos lados'!F21+'[7]Ambos lados'!F21 -> 31 | G12: ='[1]Ambos lados'!G21+'[2]Ambos lados'!G21+'[3]Ambos lados'!G21+'[4]Ambos lados'!G21+'[5]Ambos lados'!G21+'[6]Ambos lados'!G21+'[7]Ambos lados'!G21 -> 153 | H12: ='[1]Ambos lados'!H21+'[2]Ambos lados'!H21+'[3]Ambos lados'!H21+'[4]Ambos lados'!H21+'[5]Ambos lados'!H21+'[6]Ambos lados'!H21+'[7]Ambos lados'!H21 -> 17 | I12: ='[1]Ambos lados'!I21+'[2]Ambos lados'!I21+'[3]Ambos lados'!I21+'[4]Ambos lados'!I21+'[5]Ambos lados'!I21+'[6]Ambos lados'!I21+'[7]Ambos lados'!I21 -> 79 | ... N12: ='[1]Ambos lados'!N21+'[2]Ambos lados'!N21+'[3]Ambos lados'!N21+'[4]Ambos lados'!N21+'[5]Ambos lados'!N21+'[6]Ambos lados'!N21+'[7]Ambos lados'!N21 -> 0 | O12: =('[1]Ambos lados'!O21+'[2]Ambos lados'!O21+'[3]Ambos lados'!O21+'[4]Ambos lados'!O21+'[5]Ambos lados'!O21+'[6]Ambos lados'!O21+'[7]Ambos lados'!O21)/7 -> 164.85714 | P12: =O12/$O$26 -> 0.044506151
A13: 11 - 12 | B13: ='[1]Ambos lados'!B22+'[2]Ambos lados'!B22+'[3]Ambos lados'!B22+'[4]Ambos lados'!B22+'[5]Ambos lados'!B22+'[6]Ambos lados'!B22+'[7]Ambos lados'!B22 -> 365 | C13: ='[1]Ambos lados'!C22+'[2]Ambos lados'!C22+'[3]Ambos lados'!C22+'[4]Ambos lados'!C22+'[5]Ambos lados'!C22+'[6]Ambos lados'!C22+'[7]Ambos lados'!C22 -> 66 | D13: ='[1]Ambos lados'!D22+'[2]Ambos lados'!D22+'[3]Ambos lados'!D22+'[4]Ambos lados'!D22+'[5]Ambos lados'!D22+'[6]Ambos lados'!D22+'[7]Ambos lados'!D22 -> 180 | E13: ='[1]Ambos lados'!E22+'[2]Ambos lados'!E22+'[3]Ambos lados'!E22+'[4]Ambos lados'!E22+'[5]Ambos lados'!E22+'[6]Ambos lados'!E22+'[7]Ambos lados'!E22 -> 3 | F13: ='[1]Ambos lados'!F22+'[2]Ambos lados'!F22+'[3]Ambos lados'!F22+'[4]Ambos lados'!F22+'[5]Ambos lados'!F22+'[6]Ambos lados'!F22+'[7]Ambos lados'!F22 -> 18 | G13: ='[1]Ambos lados'!G22+'[2]Ambos lados'!G22+'[3]Ambos lados'!G22+'[4]Ambos lados'!G22+'[5]Ambos lados'!G22+'[6]Ambos lados'!G22+'[7]Ambos lados'!G22 -> 154 | H13: ='[1]Ambos lados'!H22+'[2]Ambos lados'!H22+'[3]Ambos lados'!H22+'[4]Ambos lados'!H22+'[5]Ambos lados'!H22+'[6]Ambos lados'!H22+'[7]Ambos lados'!H22 -> 13 | I13: ='[1]Ambos lados'!I22+'[2]Ambos lados'!I22+'[3]Ambos lados'!I22+'[4]Ambos lados'!I22+'[5]Ambos lados'!I22+'[6]Ambos lados'!I22+'[7]Ambos lados'!I22 -> 35 | ... N13: ='[1]Ambos lados'!N22+'[2]Ambos lados'!N22+'[3]Ambos lados'!N22+'[4]Ambos lados'!N22+'[5]Ambos lados'!N22+'[6]Ambos lados'!N22+'[7]Ambos lados'!N22 -> 0 | O13: =('[1]Ambos lados'!O22+'[2]Ambos lados'!O22+'[3]Ambos lados'!O22+'[4]Ambos lados'!O22+'[5]Ambos lados'!O22+'[6]Ambos lados'!O22+'[7]Ambos lados'!O22)/7 -> 154 | P13: =O13/$O$26 -> 0.04157507
... A25: 23 - 24 | B25: ='[1]Ambos lados'!B34+'[2]Ambos lados'!B34+'[3]Ambos lados'!B34+'[4]Ambos lados'!B34+'[5]Ambos lados'!B34+'[6]Ambos lados'!B34+'[7]Ambos lados'!B34 -> 155 | C25: ='[1]Ambos lados'!C34+'[2]Ambos lados'!C34+'[3]Ambos lados'!C34+'[4]Ambos lados'!C34+'[5]Ambos lados'!C34+'[6]Ambos lados'!C34+'[7]Ambos lados'!C34 -> 35 | D25: ='[1]Ambos lados'!D34+'[2]Ambos lados'!D34+'[3]Ambos lados'!D34+'[4]Ambos lados'!D34+'[5]Ambos lados'!D34+'[6]Ambos lados'!D34+'[7]Ambos lados'!D34 -> 105 | E25: ='[1]Ambos lados'!E34+'[2]Ambos lados'!E34+'[3]Ambos lados'!E34+'[4]Ambos lados'!E34+'[5]Ambos lados'!E34+'[6]Ambos lados'!E34+'[7]Ambos lados'!E34 -> 1 | F25: ='[1]Ambos lados'!F34+'[2]Ambos lados'!F34+'[3]Ambos lados'!F34+'[4]Ambos lados'!F34+'[5]Ambos lados'!F34+'[6]Ambos lados'!F34+'[7]Ambos lados'!F34 -> 48 | G25: ='[1]Ambos lados'!G34+'[2]Ambos lados'!G34+'[3]Ambos lados'!G34+'[4]Ambos lados'!G34+'[5]Ambos lados'!G34+'[6]Ambos lados'!G34+'[7]Ambos lados'!G34 -> 189 | H25: ='[1]Ambos lados'!H34+'[2]Ambos lados'!H34+'[3]Ambos lados'!H34+'[4]Ambos lados'!H34+'[5]Ambos lados'!H34+'[6]Ambos lados'!H34+'[7]Ambos lados'!H34 -> 2 | I25: ='[1]Ambos lados'!I34+'[2]Ambos lados'!I34+'[3]Ambos lados'!I34+'[4]Ambos lados'!I34+'[5]Ambos lados'!I34+'[6]Ambos lados'!I34+'[7]Ambos lados'!I34 -> 78 | ... N25: ='[1]Ambos lados'!N34+'[2]Ambos lados'!N34+'[3]Ambos lados'!N34+'[4]Ambos lados'!N34+'[5]Ambos lados'!N34+'[6]Ambos lados'!N34+'[7]Ambos lados'!N34 -> 0 | O25: =('[1]Ambos lados'!O34+'[2]Ambos lados'!O34+'[3]Ambos lados'!O34+'[4]Ambos lados'!O34+'[5]Ambos lados'!O34+'[6]Ambos lados'!O34+'[7]Ambos lados'!O34)/7 -> 141.85714 | P25: =O25/$O$26 -> 0.038296888
A26: TOTAL | B26: =(SUM(B2:B25))/7 -> 956.57143 | C26: =(SUM(C2:C25))/7 -> 168.42857 | D26: =(SUM(D2:D25))/7 -> 531.28571 | E26: =(SUM(E2:E25))/7 -> 3.2857143 | F26: =(SUM(F2:F25))/7 -> 85 | G26: =(SUM(G2:G25))/7 -> 585.71429 | H26: =(SUM(H2:H25))/7 -> 55.714286 | I26: =(SUM(I2:I25))/7 -> 234.57143 | ... N26: =(SUM(N2:N25))/7 -> 0 | O26: =SUM(O2:O25) -> 3704.1429 | P26: =SUM(P2:P25) -> 1
A27: (%) | B27: =B26/$O$26 -> 0.25824367 | C27: =C26/$O$26 -> 0.045470323 | D27: =D26/$O$26 -> 0.14343014 | E27: =E26/$O$26 -> 0.00088703768 | F27: =F26/$O$26 -> 0.022947279 | G27: =G26/$O$26 -> 0.15812411 | H27: =H26/$O$26 -> 0.015041074 | I27: =I26/$O$26 -> 0.063326777 | ... O27: =O26/$O$26 -> 1
A29: hora pico ??

Sheet PROYECCION
B1: AÑO | C1: TPDA
B2: 2007 | C2: 220
B3: 2008 | C3: 350
B4: 2009 | C4: 388
B5: 2010 | C5: 390
B6: 2011 | C6: 400
B7: 2012 | C7: 410
B8: 2013 | C8: 450
B9: 2014 | C9: 468
B10: 2015 | C10: 480
B11: 2016 | C11: 570
C52: 15
C57: 20

Sheet TPDA (2)
C1: TIPO DE VEHÍCULO | O1: TPDA
A2: AÑO | B2: ETAPA | C2: T1 | D2: T2 | E2: T3 | F2: T4 | G2: T5 | H2: T6 | I2: T7 | J2: T8 | K2: T9 | L2: T10 | M2: T11 | N2: T12
B3: TPDS
B4: fe
B5: t
A6: 2020 | B6: EDTP | C6: =C3 -> 0 | D6: =D3 -> 0 | E6: =E3 -> 0 | F6: =F3 -> 0 | G6: =G3 -> 0 | H6: =H3 -> 0 | I6: =I3 -> 0 | J6: =J3 -> 0 | ... N6: =N3 -> 0 | O6: =SUM(C6:N6) -> 0
A7: =+A6+1 -> 2021 | B7: FINANC. | C7: =(C3*C4*C5)+C6 -> 0 | D7: =(D3*D4*D5)+D6 -> 0 | E7: =(E3*E4*E5)+E6 -> 0 | F7: =(F3*F4*F5)+F6 -> 0 | G7: =(G3*G4*G5)+G6 -> 0 | H7: =(H3*H4*H5)+H6 -> 0 | I7: =(I3*I4*I5)+I6 -> 0 | J7: =(J3*J4*J5)+J6 -> 0 | ... N7: =(N3*N4*N5)+N6 -> 0 | O7: =SUM(C7:N7) -> 0
A8: =+A7+1 -> 2022 | B8: LICT. | C8: =(C$3*C$4*C$5)+C7 -> 0 | D8: =(D$3*D$4*D$5)+D7 -> 0 | E8: =(E$3*E$4*E$5)+E7 -> 0 | F8: =(F$3*F$4*F$5)+F7 -> 0 | G8: =(G$3*G$4*G$5)+G7 -> 0 | H8: =(H$3*H$4*H$5)+H7 -> 0 | I8: =(I$3*I$4*I$5)+I7 -> 0 | J8: =(J$3*J$4*J$5)+J7 -> 0 | ... N8: =(N$3*N$4*N$5)+N7 -> 0 | O8: =SUM(C8:N8) -> 0
A9: =+A8+1 -> 2023 | B9: CONST. | C9: =(C$3*C$4*C$5)+C8 -> 0 | D9: =(D$3*D$4*D$5)+D8 -> 0 | E9: =(E$3*E$4*E$5)+E8 -> 0 | F9: =(F$3*F$4*F$5)+F8 -> 0 | G9: =(G$3*G$4*G$5)+G8 -> 0 | H9: =(H$3*H$4*H$5)+H8 -> 0 | I9: =(I$3*I$4*I$5)+I8 -> 0 | J9: =(J$3*J$4*J$5)+J8 -> 0 | ... N9: =(N$3*N$4*N$5)+N8 -> 0 | O9: =SUM(C9:N9) -> 0
A10: =+A9+1 -> 2024 | C10: =(C$3*C$4*C$5)+C9 -> 0 | D10: =(D$3*D$4*D$5)+D9 -> 0 | E10: =(E$3*E$4*E$5)+E9 -> 0 | F10: =(F$3*F$4*F$5)+F9 -> 0 | G10: =(G$3*G$4*G$5)+G9 -> 0 | H10: =(H$3*H$4*H$5)+H9 -> 0 | I10: =(I$3*I$4*I$5)+I9 -> 0 | J10: =(J$3*J$4*J$5)+J9 -> 0 | ... N10: =(N$3*N$4*N$5)+N9 -> 0 | O10: =SUM(C10:N10) -> 0
A11: =+A10+1 -> 2025 | C11: =(C$3*C$4*C$5)+C10 -> 0 | D11: =(D$3*D$4*D$5)+D10 -> 0 | E11: =(E$3*E$4*E$5)+E10 -> 0 | F11: =(F$3*F$4*F$5)+F10 -> 0 | G11: =(G$3*G$4*G$5)+G10 -> 0 | H11: =(H$3*H$4*H$5)+H10 -> 0 | I11: =(I$3*I$4*I$5)+I10 -> 0 | J11: =(J$3*J$4*J$5)+J10 -> 0 | ... N11: =(N$3*N$4*N$5)+N10 -> 0 | O11: =SUM(C11:N11) -> 0
A12: =+A11+1 -> 2026 | B12: O P E R A C I O N | C12: =(C$3*C$4*C$5)+C11 -> 0 | D12: =(D$3*D$4*D$5)+D11 -> 0 | E12: =(E$3*E$4*E$5)+E11 -> 0 | F12: =(F$3*F$4*F$5)+F11 -> 0 | G12: =(G$3*G$4*G$5)+G11 -> 0 | H12: =(H$3*H$4*H$5)+H11 -> 0 | I12: =(I$3*I$4*I$5)+I11 -> 0 | J12: =(J$3*J$4*J$5)+J11 -> 0 | ... N12: =(N$3*N$4*N$5)+N11 -> 0 | O12: =SUM(C12:N12) -> 0
A13: =+A12+1 -> 2027 | C13: =(C$3*C$4*C$5)+C12 -> 0 | D13: =(D$3*D$4*D$5)+D12 -> 0 | E13: =(E$3*E$4*E$5)+E12 -> 0 | F13: =(F$3*F$4*F$5)+F12 -> 0 | G13: =(G$3*G$4*G$5)+G12 -> 0 | H13: =(H$3*H$4*H$5)+H12 -> 0 | I13: =(I$3*I$4*I$5)+I12 -> 0 | J13: =(J$3*J$4*J$5)+J12 -> 0 | ... N13: =(N$3*N$4*N$5)+N12 -> 0 | O13: =SUM(C13:N13) -> 0
A14: =+A13+1 -> 2028 | C14: =(C$3*C$4*C$5)+C13 -> 0 | D14: =(D$3*D$4*D$5)+D13 -> 0 | E14: =(E$3*E$4*E$5)+E13 -> 0 | F14: =(F$3*F$4*F$5)+F13 -> 0 | G14: =(G$3*G$4*G$5)+G13 -> 0 | H14: =(H$3*H$4*H$5)+H13 -> 0 | I14: =(I$3*I$4*I$5)+I13 -> 0 | J14: =(J$3*J$4*J$5)+J13 -> 0 | ... N14: =(N$3*N$4*N$5)+N13 -> 0 | O14: =SUM(C14:N14) -> 0
A15: =+A14+1 -> 2029 | C15: =(C$3*C$4*C$5)+C14 -> 0 | D15: =(D$3*D$4*D$5)+D14 -> 0 | E15: =(E$3*E$4*E$5)+E14 -> 0 | F15: =(F$3*F$4*F$5)+F14 -> 0 | G15: =(G$3*G$4*G$5)+G14 -> 0 | H15: =(H$3*H$4*H$5)+H14 -> 0 | I15: =(I$3*I$4*I$5)+I14 -> 0 | J15: =(J$3*J$4*J$5)+J14 -> 0 | ... N15: =(N$3*N$4*N$5)+N14 -> 0 | O15: =SUM(C15:N15) -> 0
A16: =+A15+1 -> 2030 | C16: =(C$3*C$4*C$5)+C15 -> 0 | D16: =(D$3*D$4*D$5)+D15 -> 0 | E16: =(E$3*E$4*E$5)+E15 -> 0 | F16: =(F$3*F$4*F$5)+F15 -> 0 | G16: =(G$3*G$4*G$5)+G15 -> 0 | H16: =(H$3*H$4*H$5)+H15 -> 0 | I16: =(I$3*I$4*I$5)+I15 -> 0 | J16: =(J$3*J$4*J$5)+J15 -> 0 | ... N16: =(N$3*N$4*N$5)+N15 -> 0 | O16: =SUM(C16:N16) -> 0
A17: =+A16+1 -> 2031 | C17: =(C$3*C$4*C$5)+C16 -> 0 | D17: =(D$3*D$4*D$5)+D16 -> 0 | E17: =(E$3*E$4*E$5)+E16 -> 0 | F17: =(F$3*F$4*F$5)+F16 -> 0 | G17: =(G$3*G$4*G$5)+G16 -> 0 | H17: =(H$3*H$4*H$5)+H16 -> 0 | I17: =(I$3*I$4*I$5)+I16 -> 0 | J17: =(J$3*J$4*J$5)+J16 -> 0 | ... N17: =(N$3*N$4*N$5)+N16 -> 0 | O17: =SUM(C17:N17) -> 0
A18: =+A17+1 -> 2032 | C18: =(C$3*C$4*C$5)+C17 -> 0 | D18: =(D$3*D$4*D$5)+D17 -> 0 | E18: =(E$3*E$4*E$5)+E17 -> 0 | F18: =(F$3*F$4*F$5)+F17 -> 0 | G18: =(G$3*G$4*G$5)+G17 -> 0 | H18: =(H$3*H$4*H$5)+H17 -> 0 | I18: =(I$3*I$4*I$5)+I17 -> 0 | J18: =(J$3*J$4*J$5)+J17 -> 0 | ... N18: =(N$3*N$4*N$5)+N17 -> 0 | O18: =SUM(C18:N18) -> 0
A19: =+A18+1 -> 2033 | C19: =(C$3*C$4*C$5)+C18 -> 0 | D19: =(D$3*D$4*D$5)+D18 -> 0 | E19: =(E$3*E$4*E$5)+E18 -> 0 | F19: =(F$3*F$4*F$5)+F18 -> 0 | G19: =(G$3*G$4*G$5)+G18 -> 0 | H19: =(H$3*H$4*H$5)+H18 -> 0 | I19: =(I$3*I$4*I$5)+I18 -> 0 | J19: =(J$3*J$4*J$5)+J18 -> 0 | ... N19: =(N$3*N$4*N$5)+N18 -> 0 | O19: =SUM(C19:N19) -> 0
A20: =+A19+1 -> 2034 | C20: =(C$3*C$4*C$5)+C19 -> 0 | D20: =(D$3*D$4*D$5)+D19 -> 0 | E20: =(E$3*E$4*E$5)+E19 -> 0 | F20: =(F$3*F$4*F$5)+F19 -> 0 | G20: =(G$3*G$4*G$5)+G19 -> 0 | H20: =(H$3*H$4*H$5)+H19 -> 0 | I20: =(I$3*I$4*I$5)+I19 -> 0 | J20: =(J$3*J$4*J$5)+J19 -> 0 | ... N20: =(N$3*N$4*N$5)+N19 -> 0 | O20: =SUM(C20:N20) -> 0
A21: =+A20+1 -> 2035 | C21: =(C$3*C$4*C$5)+C20 -> 0 | D21: =(D$3*D$4*D$5)+D20 -> 0 | E21: =(E$3*E$4*E$5)+E20 -> 0 | F21: =(F$3*F$4*F$5)+F20 -> 0 | G21: =(G$3*G$4*G$5)+G20 -> 0 | H21: =(H$3*H$4*H$5)+H20 -> 0 | I21: =(I$3*I$4*I$5)+I20 -> 0 | J21: =(J$3*J$4*J$5)+J20 -> 0 | ... N21: =(N$3*N$4*N$5)+N20 -> 0 | O21: =SUM(C21:N21) -> 0
A22: =+A21+1 -> 2036 | C22: =(C$3*C$4*C$5)+C21 -> 0 | D22: =(D$3*D$4*D$5)+D21 -> 0 | E22: =(E$3*E$4*E$5)+E21 -> 0 | F22: =(F$3*F$4*F$5)+F21 -> 0 | G22: =(G$3*G$4*G$5)+G21 -> 0 | H22: =(H$3*H$4*H$5)+H21 -> 0 | I22: =(I$3*I$4*I$5)+I21 -> 0 | J22: =(J$3*J$4*J$5)+J21 -> 0 | ... N22: =(N$3*N$4*N$5)+N21 -> 0 | O22: =SUM(C22:N22) -> 0
A23: =+A22+1 -> 2037 | C23: =(C$3*C$4*C$5)+C22 -> 0 | D23: =(D$3*D$4*D$5)+D22 -> 0 | E23: =(E$3*E$4*E$5)+E22 -> 0 | F23: =(F$3*F$4*F$5)+F22 -> 0 | G23: =(G$3*G$4*G$5)+G22 -> 0 | H23: =(H$3*H$4*H$5)+H22 -> 0 | I23: =(I$3*I$4*I$5)+I22 -> 0 | J23: =(J$3*J$4*J$5)+J22 -> 0 | ... N23: =(N$3*N$4*N$5)+N22 -> 0 | O23: =SUM(C23:N23) -> 0
A24: =+A23+1 -> 2038 | C24: =(C$3*C$4*C$5)+C23 -> 0 | D24: =(D$3*D$4*D$5)+D23 -> 0 | E24: =(E$3*E$4*E$5)+E23 -> 0 | F24: =(F$3*F$4*F$5)+F23 -> 0 | G24: =(G$3*G$4*G$5)+G23 -> 0 | H24: =(H$3*H$4*H$5)+H23 -> 0 | I24: =(I$3*I$4*I$5)+I23 -> 0 | J24: =(J$3*J$4*J$5)+J23 -> 0 | ... N24: =(N$3*N$4*N$5)+N23 -> 0 | O24: =SUM(C24:N24) -> 0
... A32: =+A31+1 -> 2046 | C32: =(C$3*C$4*C$5)+C31 -> 0 | D32: =(D$3*D$4*D$5)+D31 -> 0 | E32: =(E$3*E$4*E$5)+E31 -> 0 | F32: =(F$3*F$4*F$5)+F31 -> 0 | G32: =(G$3*G$4*G$5)+G31 -> 0 | H32: =(H$3*H$4*H$5)+H31 -> 0 | I32: =(I$3*I$4*I$5)+I31 -> 0 | J32: =(J$3*J$4*J$5)+J31 -> 0 | ... N32: =(N$3*N$4*N$5)+N31 -> 0 | O32: =SUM(C32:N32) -> 0
A35: REFERENCIAS
A36: T1: Automóviles, Vagonetas y Jeep | E36: T5: Buses Medianos dos ejes (22 a 35 asientos) | J36: T9: Camiones Grandes tres ejes (hasta 10 Ton)
A37: T2: Camionetas (Hasta 2 Ton) | E37: T6: Buses Grandes tres ejes (36 asientos o mas) | J37: T10: Camiones Semiremolque
A38: T3: Minibuses (7 a 15 asientos) | E38: T7: Camiones Medianos dos ejes (hasta 10 Ton) | J38: T11: Camiones Remolque
A39: T4: Microbuses dos ejes (16 a 21 asientos) | E39: T8: Camiones Grandes dos ejes | J39: T12: Otros Vehículos

Sheet EE
C1: TIPO DE VEHÍCULO | O1: TPDA
A2: AÑO | B2: ETAPA | C2: T1 | D2: T2 | E2: T3 | F2: T4 | G2: T5 | H2: T6 | I2: T7 | J2: T8 | K2: T9 | L2: T10 | M2: T11 | N2: T12
B3: TPDS
B4: fe | AA4: =(7/7.77)^4.32 -> 0.63709578
B5: %
A6: 2016 | C6: =('TPDA (2)'!C6)*$AA$4*$C$5 -> 0 | D6: =('TPDA (2)'!D6)*$AA$4*$D$5 -> 0 | E6: =('TPDA (2)'!E6)*$AA$4*$E$5 -> 0 | F6: =('TPDA (2)'!F6)*$AA$9*$F$5 -> 0 | G6: =('TPDA (2)'!G6)*$AA$9*$G$5 -> 0 | H6: =('TPDA (2)'!H6)*$AA$9*$H$5 -> 0 | I6: =('TPDA (2)'!I6)*$AA$9*$I$5 -> 0 | J6: =('TPDA (2)'!J6)*$AA$14*$J$5 -> 0 | K6: =('TPDA (2)'!K6)*$AA$14*$K$5 -> 0 | L6: =('TPDA (2)'!L6)*$AA$18*$L$5 -> 0 | M6: =('TPDA (2)'!M6)*$AA$18*$M$5 -> 0 | N6: =('TPDA (2)'!N6)*$AA$4*$N$5 -> 0 | O6: =SUM(C6:N6) -> 0
A7: =+A6+1 -> 2017 | B7: TESA | C7: =('TPDA (2)'!C7)*$AA$4*$C$5 -> 0 | D7: =('TPDA (2)'!D7)*$AA$4*$D$5 -> 0 | E7: =('TPDA (2)'!E7)*$AA$4*$E$5 -> 0 | F7: =('TPDA (2)'!F7)*$AA$9*$F$5 -> 0 | G7: =('TPDA (2)'!G7)*$AA$9*$G$5 -> 0 | H7: =('TPDA (2)'!H7)*$AA$9*$H$5 -> 0 | I7: =('TPDA (2)'!I7)*$AA$9*$I$5 -> 0 | J7: =('TPDA (2)'!J7)*$AA$14*$J$5 -> 0 | K7: =('TPDA (2)'!K7)*$AA$14*$K$5 -> 0 | L7: =('TPDA (2)'!L7)*$AA$18*$L$5 -> 0 | M7: =('TPDA (2)'!M7)*$AA$18*$M$5 -> 0 | N7: =('TPDA (2)'!N7)*$AA$4*$N$5 -> 0 | O7: =SUM(C7:N7) -> 0
A8: =+A7+1 -> 2018 | B8: LICT. | C8: =('TPDA (2)'!C8)*$AA$4*$C$5 -> 0 | D8: =('TPDA (2)'!D8)*$AA$4*$D$5 -> 0 | E8: =('TPDA (2)'!E8)*$AA$4*$E$5 -> 0 | F8: =('TPDA (2)'!F8)*$AA$9*$F$5 -> 0 | G8: =('TPDA (2)'!G8)*$AA$9*$G$5 -> 0 | H8: =('TPDA (2)'!H8)*$AA$9*$H$5 -> 0 | I8: =('TPDA (2)'!I8)*$AA$9*$I$5 -> 0 | J8: =('TPDA (2)'!J8)*$AA$14*$J$5 -> 0 | K8: =('TPDA (2)'!K8)*$AA$14*$K$5 -> 0 | L8: =('TPDA (2)'!L8)*$AA$18*$L$5 -> 0 | M8: =('TPDA (2)'!M8)*$AA$18*$M$5 -> 0 | N8: =('TPDA (2)'!N8)*$AA$4*$N$5 -> 0 | O8: =SUM(C8:N8) -> 0
A9: =+A8+1 -> 2019 | B9: CONST. | C9: =('TPDA (2)'!C9)*$AA$4*$C$5 -> 0 | D9: =('TPDA (2)'!D9)*$AA$4*$D$5 -> 0 | E9: =('TPDA (2)'!E9)*$AA$4*$E$5 -> 0 | F9: =('TPDA (2)'!F9)*$AA$9*$F$5 -> 0 | G9: =('TPDA (2)'!G9)*$AA$9*$G$5 -> 0 | H9: =('TPDA (2)'!H9)*$AA$9*$H$5 -> 0 | I9: =('TPDA (2)'!I9)*$AA$9*$I$5 -> 0 | J9: =('TPDA (2)'!J9)*$AA$14*$J$5 -> 0 | K9: =('TPDA (2)'!K9)*$AA$14*$K$5 -> 0 | L9: =('TPDA (2)'!L9)*$AA$18*$L$5 -> 0 | M9: =('TPDA (2)'!M9)*$AA$18*$M$5 -> 0 | N9: =('TPDA (2)'!N9)*$AA$4*$N$5 -> 0 | O9: =SUM(C9:N9) -> 0 | AA9: =(11/8.17)^4.32 -> 3.6142411
A10: =+A9+1 -> 2020 | C10: =('TPDA (2)'!C10)*$AA$4*$C$5 -> 0 | D10: =('TPDA (2)'!D10)*$AA$4*$D$5 -> 0 | E10: =('TPDA (2)'!E10)*$AA$4*$E$5 -> 0 | F10: =('TPDA (2)'!F10)*$AA$9*$F$5 -> 0 | G10: =('TPDA (2)'!G10)*$AA$9*$G$5 -> 0 | H10: =('TPDA (2)'!H10)*$AA$9*$H$5 -> 0 | I10: =('TPDA (2)'!I10)*$AA$9*$I$5 -> 0 | J10: =('TPDA (2)'!J10)*$AA$14*$J$5 -> 0 | K10: =('TPDA (2)'!K10)*$AA$14*$K$5 -> 0 | L10: =('TPDA (2)'!L10)*$AA$18*$L$5 -> 0 | M10: =('TPDA (2)'!M10)*$AA$18*$M$5 -> 0 | N10: =('TPDA (2)'!N10)*$AA$4*$N$5 -> 0 | O10: =SUM(C10:N10) -> 0
A11: =+A10+1 -> 2021 | C11: =('TPDA (2)'!C11)*$AA$4*$C$5 -> 0 | D11: =('TPDA (2)'!D11)*$AA$4*$D$5 -> 0 | E11: =('TPDA (2)'!E11)*$AA$4*$E$5 -> 0 | F11: =('TPDA (2)'!F11)*$AA$9*$F$5 -> 0 | G11: =('TPDA (2)'!G11)*$AA$9*$G$5 -> 0 | H11: =('TPDA (2)'!H11)*$AA$9*$H$5 -> 0 | I11: =('TPDA (2)'!I11)*$AA$9*$I$5 -> 0 | J11: =('TPDA (2)'!J11)*$AA$14*$J$5 -> 0 | K11: =('TPDA (2)'!K11)*$AA$14*$K$5 -> 0 | L11: =('TPDA (2)'!L11)*$AA$18*$L$5 -> 0 | M11: =('TPDA (2)'!M11)*$AA$18*$M$5 -> 0 | N11: =('TPDA (2)'!N11)*$AA$4*$N$5 -> 0 | O11: =SUM(C11:N11) -> 0
A12: =+A11+1 -> 2022 | B12: O P E R A C I O N | C12: =('TPDA (2)'!C12)*$AA$4*$C$5 -> 0 | D12: =('TPDA (2)'!D12)*$AA$4*$D$5 -> 0 | E12: =('TPDA (2)'!E12)*$AA$4*$E$5 -> 0 | F12: =('TPDA (2)'!F12)*$AA$9*$F$5 -> 0 | G12: =('TPDA (2)'!G12)*$AA$9*$G$5 -> 0 | H12: =('TPDA (2)'!H12)*$AA$9*$H$5 -> 0 | I12: =('TPDA (2)'!I12)*$AA$9*$I$5 -> 0 | J12: =('TPDA (2)'!J12)*$AA$14*$J$5 -> 0 | K12: =('TPDA (2)'!K12)*$AA$14*$K$5 -> 0 | L12: =('TPDA (2)'!L12)*$AA$18*$L$5 -> 0 | M12: =('TPDA (2)'!M12)*$AA$18*$M$5 -> 0 | N12: =('TPDA (2)'!N12)*$AA$4*$N$5 -> 0 | O12: =SUM(C12:N12) -> 0
A13: =+A12+1 -> 2023 | C13: =('TPDA (2)'!C13)*$AA$4*$C$5 -> 0 | D13: =('TPDA (2)'!D13)*$AA$4*$D$5 -> 0 | E13: =('TPDA (2)'!E13)*$AA$4*$E$5 -> 0 | F13: =('TPDA (2)'!F13)*$AA$9*$F$5 -> 0 | G13: =('TPDA (2)'!G13)*$AA$9*$G$5 -> 0 | H13: =('TPDA (2)'!H13)*$AA$9*$H$5 -> 0 | I13: =('TPDA (2)'!I13)*$AA$9*$I$5 -> 0 | J13: =('TPDA (2)'!J13)*$AA$14*$J$5 -> 0 | K13: =('TPDA (2)'!K13)*$AA$14*$K$5 -> 0 | L13: =('TPDA (2)'!L13)*$AA$18*$L$5 -> 0 | M13: =('TPDA (2)'!M13)*$AA$18*$M$5 -> 0 | N13: =('TPDA (2)'!N13)*$AA$4*$N$5 -> 0 | O13: =SUM(C13:N13) -> 0
A14: =+A13+1 -> 2024 | C14: =('TPDA (2)'!C14)*$AA$4*$C$5 -> 0 | D14: =('TPDA (2)'!D14)*$AA$4*$D$5 -> 0 | E14: =('TPDA (2)'!E14)*$AA$4*$E$5 -> 0 | F14: =('TPDA (2)'!F14)*$AA$9*$F$5 -> 0 | G14: =('TPDA (2)'!G14)*$AA$9*$G$5 -> 0 | H14: =('TPDA (2)'!H14)*$AA$9*$H$5 -> 0 | I14: =('TPDA (2)'!I14)*$AA$9*$I$5 -> 0 | J14: =('TPDA (2)'!J14)*$AA$14*$J$5 -> 0 | K14: =('TPDA (2)'!K14)*$AA$14*$K$5 -> 0 | L14: =('TPDA (2)'!L14)*$AA$18*$L$5 -> 0 | M14: =('TPDA (2)'!M14)*$AA$18*$M$5 -> 0 | N14: =('TPDA (2)'!N14)*$AA$4*$N$5 -> 0 | O14: =SUM(C14:N14) -> 0 | AA14: =(17/15.08)^4.14 -> 1.6423926
A15: =+A14+1 -> 2025 | C15: =('TPDA (2)'!C15)*$AA$4*$C$5 -> 0 | D15: =('TPDA (2)'!D15)*$AA$4*$D$5 -> 0 | E15: =('TPDA (2)'!E15)*$AA$4*$E$5 -> 0 | F15: =('TPDA (2)'!F15)*$AA$9*$F$5 -> 0 | G15: =('TPDA (2)'!G15)*$AA$9*$G$5 -> 0 | H15: =('TPDA (2)'!H15)*$AA$9*$H$5 -> 0 | I15: =('TPDA (2)'!I15)*$AA$9*$I$5 -> 0 | J15: =('TPDA (2)'!J15)*$AA$14*$J$5 -> 0 | K15: =('TPDA (2)'!K15)*$AA$14*$K$5 -> 0 | L15: =('TPDA (2)'!L15)*$AA$18*$L$5 -> 0 | M15: =('TPDA (2)'!M15)*$AA$18*$M$5 -> 0 | N15: =('TPDA (2)'!N15)*$AA$4*$N$5 -> 0 | O15: =SUM(C15:N15) -> 0
A16: =+A15+1 -> 2026 | C16: =('TPDA (2)'!C16)*$AA$4*$C$5 -> 0 | D16: =('TPDA (2)'!D16)*$AA$4*$D$5 -> 0 | E16: =('TPDA (2)'!E16)*$AA$4*$E$5 -> 0 | F16: =('TPDA (2)'!F16)*$AA$9*$F$5 -> 0 | G16: =('TPDA (2)'!G16)*$AA$9*$G$5 -> 0 | H16: =('TPDA (2)'!H16)*$AA$9*$H$5 -> 0 | I16: =('TPDA (2)'!I16)*$AA$9*$I$5 -> 0 | J16: =('TPDA (2)'!J16)*$AA$14*$J$5 -> 0 | K16: =('TPDA (2)'!K16)*$AA$14*$K$5 -> 0 | L16: =('TPDA (2)'!L16)*$AA$18*$L$5 -> 0 | M16: =('TPDA (2)'!M16)*$AA$18*$M$5 -> 0 | N16: =('TPDA (2)'!N16)*$AA$4*$N$5 -> 0 | O16: =SUM(C16:N16) -> 0
A17: =+A16+1 -> 2027 | C17: =('TPDA (2)'!C17)*$AA$4*$C$5 -> 0 | D17: =('TPDA (2)'!D17)*$AA$4*$D$5 -> 0 | E17: =('TPDA (2)'!E17)*$AA$4*$E$5 -> 0 | F17: =('TPDA (2)'!F17)*$AA$9*$F$5 -> 0 | G17: =('TPDA (2)'!G17)*$AA$9*$G$5 -> 0 | H17: =('TPDA (2)'!H17)*$AA$9*$H$5 -> 0 | I17: =('TPDA (2)'!I17)*$AA$9*$I$5 -> 0 | J17: =('TPDA (2)'!J17)*$AA$14*$J$5 -> 0 | K17: =('TPDA (2)'!K17)*$AA$14*$K$5 -> 0 | L17: =('TPDA (2)'!L17)*$AA$18*$L$5 -> 0 | M17: =('TPDA (2)'!M17)*$AA$18*$M$5 -> 0 | N17: =('TPDA (2)'!N17)*$AA$4*$N$5 -> 0 | O17: =SUM(C17:N17) -> 0
A18: =+A17+1 -> 2028 | C18: =('TPDA (2)'!C18)*$AA$4*$C$5 -> 0 | D18: =('TPDA (2)'!D18)*$AA$4*$D$5 -> 0 | E18: =('TPDA (2)'!E18)*$AA$4*$E$5 -> 0 | F18: =('TPDA (2)'!F18)*$AA$9*$F$5 -> 0 | G18: =('TPDA (2)'!G18)*$AA$9*$G$5 -> 0 | H18: =('TPDA (2)'!H18)*$AA$9*$H$5 -> 0 | I18: =('TPDA (2)'!I18)*$AA$9*$I$5 -> 0 | J18: =('TPDA (2)'!J18)*$AA$14*$J$5 -> 0 | K18: =('TPDA (2)'!K18)*$AA$14*$K$5 -> 0 | L18: =('TPDA (2)'!L18)*$AA$18*$L$5 -> 0 | M18: =('TPDA (2)'!M18)*$AA$18*$M$5 -> 0 | N18: =('TPDA (2)'!N18)*$AA$4*$N$5 -> 0 | O18: =SUM(C18:N18) -> 0 | AA18: =(22/22.98)^4.22 -> 0.83200629
A19: =+A18+1 -> 2029 | C19: =('TPDA (2)'!C19)*$AA$4*$C$5 -> 0 | D19: =('TPDA (2)'!D19)*$AA$4*$D$5 -> 0 | E19: =('TPDA (2)'!E19)*$AA$4*$E$5 -> 0 | F19: =('TPDA (2)'!F19)*$AA$9*$F$5 -> 0 | G19: =('TPDA (2)'!G19)*$AA$9*$G$5 -> 0 | H19: =('TPDA (2)'!H19)*$AA$9*$H$5 -> 0 | I19: =('TPDA (2)'!I19)*$AA$9*$I$5 -> 0 | J19: =('TPDA (2)'!J19)*$AA$14*$J$5 -> 0 | K19: =('TPDA (2)'!K19)*$AA$14*$K$5 -> 0 | L19: =('TPDA (2)'!L19)*$AA$18*$L$5 -> 0 | M19: =('TPDA (2)'!M19)*$AA$18*$M$5 -> 0 | N19: =('TPDA (2)'!N19)*$AA$4*$N$5 -> 0 | O19: =SUM(C19:N19) -> 0
A20: =+A19+1 -> 2030 | C20: =('TPDA (2)'!C20)*$AA$4*$C$5 -> 0 | D20: =('TPDA (2)'!D20)*$AA$4*$D$5 -> 0 | E20: =('TPDA (2)'!E20)*$AA$4*$E$5 -> 0 | F20: =('TPDA (2)'!F20)*$AA$9*$F$5 -> 0 | G20: =('TPDA (2)'!G20)*$AA$9*$G$5 -> 0 | H20: =('TPDA (2)'!H20)*$AA$9*$H$5 -> 0 | I20: =('TPDA (2)'!I20)*$AA$9*$I$5 -> 0 | J20: =('TPDA (2)'!J20)*$AA$14*$J$5 -> 0 | K20: =('TPDA (2)'!K20)*$AA$14*$K$5 -> 0 | L20: =('TPDA (2)'!L20)*$AA$18*$L$5 -> 0 | M20: =('TPDA (2)'!M20)*$AA$18*$M$5 -> 0 | N20: =('TPDA (2)'!N20)*$AA$4*$N$5 -> 0 | O20: =SUM(C20:N20) -> 0
A21: =+A20+1 -> 2031 | C21: =('TPDA (2)'!C21)*$AA$4*$C$5 -> 0 | D21: =('TPDA (2)'!D21)*$AA$4*$D$5 -> 0 | E21: =('TPDA (2)'!E21)*$AA$4*$E$5 -> 0 | F21: =('TPDA (2)'!F21)*$AA$9*$F$5 -> 0 | G21: =('TPDA (2)'!G21)*$AA$9*$G$5 -> 0 | H21: =('TPDA (2)'!H21)*$AA$9*$H$5 -> 0 | I21: =('TPDA (2)'!I21)*$AA$9*$I$5 -> 0 | J21: =('TPDA (2)'!J21)*$AA$14*$J$5 -> 0 | K21: =('TPDA (2)'!K21)*$AA$14*$K$5 -> 0 | L21: =('TPDA (2)'!L21)*$AA$18*$L$5 -> 0 | M21: =('TPDA (2)'!M21)*$AA$18*$M$5 -> 0 | N21: =('TPDA (2)'!N21)*$AA$4*$N$5 -> 0 | O21: =SUM(C21:N21) -> 0
A22: =+A21+1 -> 2032 | C22: =('TPDA (2)'!C22)*$AA$4*$C$5 -> 0 | D22: =('TPDA (2)'!D22)*$AA$4*$D$5 -> 0 | E22: =('TPDA (2)'!E22)*$AA$4*$E$5 -> 0 | F22: =('TPDA (2)'!F22)*$AA$9*$F$5 -> 0 | G22: =('TPDA (2)'!G22)*$AA$9*$G$5 -> 0 | H22: =('TPDA (2)'!H22)*$AA$9*$H$5 -> 0 | I22: =('TPDA (2)'!I22)*$AA$9*$I$5 -> 0 | J22: =('TPDA (2)'!J22)*$AA$14*$J$5 -> 0 | K22: =('TPDA (2)'!K22)*$AA$14*$K$5 -> 0 | L22: =('TPDA (2)'!L22)*$AA$18*$L$5 -> 0 | M22: =('TPDA (2)'!M22)*$AA$18*$M$5 -> 0 | N22: =('TPDA (2)'!N22)*$AA$4*$N$5 -> 0 | O22: =SUM(C22:N22) -> 0
A23: =+A22+1 -> 2033 | C23: =('TPDA (2)'!C23)*$AA$4*$C$5 -> 0 | D23: =('TPDA (2)'!D23)*$AA$4*$D$5 -> 0 | E23: =('TPDA (2)'!E23)*$AA$4*$E$5 -> 0 | F23: =('TPDA (2)'!F23)*$AA$9*$F$5 -> 0 | G23: =('TPDA (2)'!G23)*$AA$9*$G$5 -> 0 | H23: =('TPDA (2)'!H23)*$AA$9*$H$5 -> 0 | I23: =('TPDA (2)'!I23)*$AA$9*$I$5 -> 0 | J23: =('TPDA (2)'!J23)*$AA$14*$J$5 -> 0 | K23: =('TPDA (2)'!K23)*$AA$14*$K$5 -> 0 | L23: =('TPDA (2)'!L23)*$AA$18*$L$5 -> 0 | M23: =('TPDA (2)'!M23)*$AA$18*$M$5 -> 0 | N23: =('TPDA (2)'!N23)*$AA$4*$N$5 -> 0 | O23: =SUM(C23:N23) -> 0
A24: =+A23+1 -> 2034 | C24: =('TPDA (2)'!C24)*$AA$4*$C$5 -> 0 | D24: =('TPDA (2)'!D24)*$AA$4*$D$5 -> 0 | E24: =('TPDA (2)'!E24)*$AA$4*$E$5 -> 0 | F24: =('TPDA (2)'!F24)*$AA$9*$F$5 -> 0 | G24: =('TPDA (2)'!G24)*$AA$9*$G$5 -> 0 | H24: =('TPDA (2)'!H24)*$AA$9*$H$5 -> 0 | I24: =('TPDA (2)'!I24)*$AA$9*$I$5 -> 0 | J24: =('TPDA (2)'!J24)*$AA$14*$J$5 -> 0 | K24: =('TPDA (2)'!K24)*$AA$14*$K$5 -> 0 | L24: =('TPDA (2)'!L24)*$AA$18*$L$5 -> 0 | M24: =('TPDA (2)'!M24)*$AA$18*$M$5 -> 0 | N24: =('TPDA (2)'!N24)*$AA$4*$N$5 -> 0 | O24: =SUM(C24:N24) -> 0
A25: =+A24+1 -> 2035 | C25: =('TPDA (2)'!C25)*$AA$4*$C$5 -> 0 | D25: =('TPDA (2)'!D25)*$AA$4*$D$5 -> 0 | E25: =('TPDA (2)'!E25)*$AA$4*$E$5 -> 0 | F25: =('TPDA (2)'!F25)*$AA$9*$F$5 -> 0 | G25: =('TPDA (2)'!G25)*$AA$9*$G$5 -> 0 | H25: =('TPDA (2)'!H25)*$AA$9*$H$5 -> 0 | I25: =('TPDA (2)'!I25)*$AA$9*$I$5 -> 0 | J25: =('TPDA (2)'!J25)*$AA$14*$J$5 -> 0 | K25: =('TPDA (2)'!K25)*$AA$14*$K$5 -> 0 | L25: =('TPDA (2)'!L25)*$AA$18*$L$5 -> 0 | M25: =('TPDA (2)'!M25)*$AA$18*$M$5 -> 0 | N25: =('TPDA (2)'!N25)*$AA$4*$N$5 -> 0 | O25: =SUM(C25:N25) -> 0
A26: =+A25+1 -> 2036 | C26: =('TPDA (2)'!C26)*$AA$4*$C$5 -> 0 | D26: =('TPDA (2)'!D26)*$AA$4*$D$5 -> 0 | E26: =('TPDA (2)'!E26)*$AA$4*$E$5 -> 0 | F26: =('TPDA (2)'!F26)*$AA$9*$F$5 -> 0 | G26: =('TPDA (2)'!G26)*$AA$9*$G$5 -> 0 | H26: =('TPDA (2)'!H26)*$AA$9*$H$5 -> 0 | I26: =('TPDA (2)'!I26)*$AA$9*$I$5 -> 0 | J26: =('TPDA (2)'!J26)*$AA$14*$J$5 -> 0 | K26: =('TPDA (2)'!K26)*$AA$14*$K$5 -> 0 | L26: =('TPDA (2)'!L26)*$AA$18*$L$5 -> 0 | M26: =('TPDA (2)'!M26)*$AA$18*$M$5 -> 0 | N26: =('TPDA (2)'!N26)*$AA$4*$N$5 -> 0 | O26: =SUM(C26:N26) -> 0
A27: =+A26+1 -> 2037 | C27: =('TPDA (2)'!C27)*$AA$4*$C$5 -> 0 | D27: =('TPDA (2)'!D27)*$AA$4*$D$5 -> 0 | E27: =('TPDA (2)'!E27)*$AA$4*$E$5 -> 0 | F27: =('TPDA (2)'!F27)*$AA$9*$F$5 -> 0 | G27: =('TPDA (2)'!G27)*$AA$9*$G$5 -> 0 | H27: =('TPDA (2)'!H27)*$AA$9*$H$5 -> 0 | I27: =('TPDA (2)'!I27)*$AA$9*$I$5 -> 0 | J27: =('TPDA (2)'!J27)*$AA$14*$J$5 -> 0 | K27: =('TPDA (2)'!K27)*$AA$14*$K$5 -> 0 | L27: =('TPDA (2)'!L27)*$AA$18*$L$5 -> 0 | M27: =('TPDA (2)'!M27)*$AA$18*$M$5 -> 0 | N27: =('TPDA (2)'!N27)*$AA$4*$N$5 -> 0 | O27: =SUM(C27:N27) -> 0
A28: =+A27+1 -> 2038 | C28: =('TPDA (2)'!C28)*$AA$4*$C$5 -> 0 | D28: =('TPDA (2)'!D28)*$AA$4*$D$5 -> 0 | E28: =('TPDA (2)'!E28)*$AA$4*$E$5 -> 0 | F28: =('TPDA (2)'!F28)*$AA$9*$F$5 -> 0 | G28: =('TPDA (2)'!G28)*$AA$9*$G$5 -> 0 | H28: =('TPDA (2)'!H28)*$AA$9*$H$5 -> 0 | I28: =('TPDA (2)'!I28)*$AA$9*$I$5 -> 0 | J28: =('TPDA (2)'!J28)*$AA$14*$J$5 -> 0 | K28: =('TPDA (2)'!K28)*$AA$14*$K$5 -> 0 | L28: =('TPDA (2)'!L28)*$AA$18*$L$5 -> 0 | M28: =('TPDA (2)'!M28)*$AA$18*$M$5 -> 0 | N28: =('TPDA (2)'!N28)*$AA$4*$N$5 -> 0 | O28: =SUM(C28:N28) -> 0
A29: =+A28+1 -> 2039 | C29: =('TPDA (2)'!C29)*$AA$4*$C$5 -> 0 | D29: =('TPDA (2)'!D29)*$AA$4*$D$5 -> 0 | E29: =('TPDA (2)'!E29)*$AA$4*$E$5 -> 0 | F29: =('TPDA (2)'!F29)*$AA$9*$F$5 -> 0 | G29: =('TPDA (2)'!G29)*$AA$9*$G$5 -> 0 | H29: =('TPDA (2)'!H29)*$AA$9*$H$5 -> 0 | I29: =('TPDA (2)'!I29)*$AA$9*$I$5 -> 0 | J29: =('TPDA (2)'!J29)*$AA$14*$J$5 -> 0 | K29: =('TPDA (2)'!K29)*$AA$14*$K$5 -> 0 | L29: =('TPDA (2)'!L29)*$AA$18*$L$5 -> 0 | M29: =('TPDA (2)'!M29)*$AA$18*$M$5 -> 0 | N29: =('TPDA (2)'!N29)*$AA$4*$N$5 -> 0 | O29: =SUM(C29:N29) -> 0
A30: =+A29+1 -> 2040 | C30: =('TPDA (2)'!C30)*$AA$4*$C$5 -> 0 | D30: =('TPDA (2)'!D30)*$AA$4*$D$5 -> 0 | E30: =('TPDA (2)'!E30)*$AA$4*$E$5 -> 0 | F30: =('TPDA (2)'!F30)*$AA$9*$F$5 -> 0 | G30: =('TPDA (2)'!G30)*$AA$9*$G$5 -> 0 | H30: =('TPDA (2)'!H30)*$AA$9*$H$5 -> 0 | I30: =('TPDA (2)'!I30)*$AA$9*$I$5 -> 0 | J30: =('TPDA (2)'!J30)*$AA$14*$J$5 -> 0 | K30: =('TPDA (2)'!K30)*$AA$14*$K$5 -> 0 | L30: =('TPDA (2)'!L30)*$AA$18*$L$5 -> 0 | M30: =('TPDA (2)'!M30)*$AA$18*$M$5 -> 0 | N30: =('TPDA (2)'!N30)*$AA$4*$N$5 -> 0 | O30: =SUM(C30:N30) -> 0
O31: 0.2X10E6
C32: =(C7*C5)+C6 -> 0
A33: REFERENCIAS
A34: T1: Automóviles, Vagonetas y Jeep | E34: T5: Buses Medianos dos ejes (22 a 35 asientos) | J34: T9: Camiones Grandes tres ejes (hasta 10 Ton)
A35: T2: Camionetas (Hasta 2 Ton) | E35: T6: Buses Grandes tres ejes (36 asientos o mas) | J35: T10: Camiones Semiremolque
A36: T3: Minibuses (7 a 15 asientos) | E36: T7: Camiones Medianos dos ejes (hasta 10 Ton) | J36: T10: Camiones Remolque
A37: T4: Microbuses dos ejes (16 a 21 asientos) | E37: T8: Camiones Grandes dos ejes | J37: T12: Otros Vehículos

Sheet TPDA
C1: TIPO DE VEHÍCULO | O1: TPDA
A2: AÑO | B2: ETAPA | C2: T1 | D2: T2 | E2: T3 | F2: T4 | G2: T5 | H2: T6 | I2: T7 | J2: T8 | K2: T9 | L2: T10 | M2: T11 | N2: T12
B3: TPDS | C3: =CONSOLIDADO!B36/2 -> 0 | D3: =CONSOLIDADO!C36/2 -> 0 | E3: =CONSOLIDADO!D36/2 -> 0 | F3: =CONSOLIDADO!E36/2 -> 0 | G3: =CONSOLIDADO!F36/2 -> 0 | H3: =CONSOLIDADO!G36/2 -> 0 | I3: =CONSOLIDADO!H36/2 -> 0 | J3: =CONSOLIDADO!I36/2 -> 0 | ... N3: =CONSOLIDADO!M36/2 -> 0
B4: fe | C4: 1.151 | D4: 1.151 | E4: 1.151 | F4: 1.151 | G4: 1.151 | H4: 1.151 | I4: 1.151 | J4: 1.151 | K4: 1.151 | L4: 1.151 | M4: 1.151 | N4: 1.151
B5: t | C5: 0.1044 | D5: 0.1044 | E5: 0.1044 | F5: 0.1044 | G5: 0.1044 | H5: 0.1044 | I5: 0.1044 | J5: 0.1044 | K5: 0.1044 | L5: 0.1044 | M5: 0.1044 | N5: 0.1044
A6: 2020 | B6: EDTP | C6: =C3 -> 0 | D6: =D3 -> 0 | E6: =E3 -> 0 | F6: =F3 -> 0 | G6: =G3 -> 0 | H6: =H3 -> 0 | I6: =I3 -> 0 | J6: =J3 -> 0 | ... N6: =N3 -> 0 | O6: =SUM(C6:N6) -> 0 | P6: =O6*365 -> 0
A7: =+A6+1 -> 2021 | B7: LICIT | C7: =($C$3*$C$4*$C$5)+C6 -> 0 | D7: =($D$3*$D$4*$D$5)+D6 -> 0 | E7: =($E$3*$E$4*$E$5)+E6 -> 0 | F7: =($F$3*$F$4*$F$5)+F6 -> 0 | G7: =($G$3*$G$4*$G$5)+G6 -> 0 | H7: =($H$3*$H$4*$H$5)+H6 -> 0 | I7: =($I$3*$I$4*$I$5)+I6 -> 0 | J7: =($J$3*$J$4*$J$5)+J6 -> 0 | K7: =($K$3*$K$4*$K$5)+K6 -> 0 | L7: =($L$3*$L$4*$L$5)+L6 -> 0 | M7: =($M$3*$M$4*$M$5)+M6 -> 0 | N7: =($N$3*$N$4*$N$5)+N6 -> 0 | O7: =SUM(C7:N7) -> 0 | P7: =O7*365 -> 0
A8: =+A7+1 -> 2022 | B8: CONST. | C8: =($C$3*$C$4*$C$5)+C7 -> 0 | D8: =($D$3*$D$4*$D$5)+D7 -> 0 | E8: =($E$3*$E$4*$E$5)+E7 -> 0 | F8: =($F$3*$F$4*$F$5)+F7 -> 0 | G8: =($G$3*$G$4*$G$5)+G7 -> 0 | H8: =($H$3*$H$4*$H$5)+H7 -> 0 | I8: =($I$3*$I$4*$I$5)+I7 -> 0 | J8: =($J$3*$J$4*$J$5)+J7 -> 0 | K8: =($K$3*$K$4*$K$5)+K7 -> 0 | L8: =($L$3*$L$4*$L$5)+L7 -> 0 | M8: =($M$3*$M$4*$M$5)+M7 -> 0 | N8: =($N$3*$N$4*$N$5)+N7 -> 0 | O8: =SUM(C8:N8) -> 0 | P8: =O8*365 -> 0
A9: =+A8+1 -> 2023 | C9: =($C$3*$C$4*$C$5)+C8 -> 0 | D9: =($D$3*$D$4*$D$5)+D8 -> 0 | E9: =($E$3*$E$4*$E$5)+E8 -> 0 | F9: =($F$3*$F$4*$F$5)+F8 -> 0 | G9: =($G$3*$G$4*$G$5)+G8 -> 0 | H9: =($H$3*$H$4*$H$5)+H8 -> 0 | I9: =($I$3*$I$4*$I$5)+I8 -> 0 | J9: =($J$3*$J$4*$J$5)+J8 -> 0 | K9: =($K$3*$K$4*$K$5)+K8 -> 0 | L9: =($L$3*$L$4*$L$5)+L8 -> 0 | M9: =($M$3*$M$4*$M$5)+M8 -> 0 | N9: =($N$3*$N$4*$N$5)+N8 -> 0 | O9: =SUM(C9:N9) -> 0 | P9: =O9*365 -> 0
A10: =+A9+1 -> 2024 | C10: =($C$3*$C$4*$C$5)+C9 -> 0 | D10: =($D$3*$D$4*$D$5)+D9 -> 0 | E10: =($E$3*$E$4*$E$5)+E9 -> 0 | F10: =($F$3*$F$4*$F$5)+F9 -> 0 | G10: =($G$3*$G$4*$G$5)+G9 -> 0 | H10: =($H$3*$H$4*$H$5)+H9 -> 0 | I10: =($I$3*$I$4*$I$5)+I9 -> 0 | J10: =($J$3*$J$4*$J$5)+J9 -> 0 | K10: =($K$3*$K$4*$K$5)+K9 -> 0 | L10: =($L$3*$L$4*$L$5)+L9 -> 0 | M10: =($M$3*$M$4*$M$5)+M9 -> 0 | N10: =($N$3*$N$4*$N$5)+N9 -> 0 | O10: =SUM(C10:N10) -> 0 | P10: =O10*365 -> 0
A11: =+A10+1 -> 2025 | B11: O P E R A C I O N | C11: =($C$3*$C$4*$C$5)+C10 -> 0 | D11: =($D$3*$D$4*$D$5)+D10 -> 0 | E11: =($E$3*$E$4*$E$5)+E10 -> 0 | F11: =($F$3*$F$4*$F$5)+F10 -> 0 | G11: =($G$3*$G$4*$G$5)+G10 -> 0 | H11: =($H$3*$H$4*$H$5)+H10 -> 0 | I11: =($I$3*$I$4*$I$5)+I10 -> 0 | J11: =($J$3*$J$4*$J$5)+J10 -> 0 | K11: =($K$3*$K$4*$K$5)+K10 -> 0 | L11: =($L$3*$L$4*$L$5)+L10 -> 0 | M11: =($M$3*$M$4*$M$5)+M10 -> 0 | N11: =($N$3*$N$4*$N$5)+N10 -> 0 | O11: =SUM(C11:N11) -> 0 | P11: =O11*365 -> 0
A12: =+A11+1 -> 2026 | C12: =($C$3*$C$4*$C$5)+C11 -> 0 | D12: =($D$3*$D$4*$D$5)+D11 -> 0 | E12: =($E$3*$E$4*$E$5)+E11 -> 0 | F12: =($F$3*$F$4*$F$5)+F11 -> 0 | G12: =($G$3*$G$4*$G$5)+G11 -> 0 | H12: =($H$3*$H$4*$H$5)+H11 -> 0 | I12: =($I$3*$I$4*$I$5)+I11 -> 0 | J12: =($J$3*$J$4*$J$5)+J11 -> 0 | K12: =($K$3*$K$4*$K$5)+K11 -> 0 | L12: =($L$3*$L$4*$L$5)+L11 -> 0 | M12: =($M$3*$M$4*$M$5)+M11 -> 0 | N12: =($N$3*$N$4*$N$5)+N11 -> 0 | O12: =SUM(C12:N12) -> 0 | P12: =O12*365 -> 0
A13: =+A12+1 -> 2027 | C13: =($C$3*$C$4*$C$5)+C12 -> 0 | D13: =($D$3*$D$4*$D$5)+D12 -> 0 | E13: =($E$3*$E$4*$E$5)+E12 -> 0 | F13: =($F$3*$F$4*$F$5)+F12 -> 0 | G13: =($G$3*$G$4*$G$5)+G12 -> 0 | H13: =($H$3*$H$4*$H$5)+H12 -> 0 | I13: =($I$3*$I$4*$I$5)+I12 -> 0 | J13: =($J$3*$J$4*$J$5)+J12 -> 0 | K13: =($K$3*$K$4*$K$5)+K12 -> 0 | L13: =($L$3*$L$4*$L$5)+L12 -> 0 | M13: =($M$3*$M$4*$M$5)+M12 -> 0 | N13: =($N$3*$N$4*$N$5)+N12 -> 0 | O13: =SUM(C13:N13) -> 0 | P13: =O13*365 -> 0
A14: =+A13+1 -> 2028 | C14: =($C$3*$C$4*$C$5)+C13 -> 0 | D14: =($D$3*$D$4*$D$5)+D13 -> 0 | E14: =($E$3*$E$4*$E$5)+E13 -> 0 | F14: =($F$3*$F$4*$F$5)+F13 -> 0 | G14: =($G$3*$G$4*$G$5)+G13 -> 0 | H14: =($H$3*$H$4*$H$5)+H13 -> 0 | I14: =($I$3*$I$4*$I$5)+I13 -> 0 | J14: =($J$3*$J$4*$J$5)+J13 -> 0 | K14: =($K$3*$K$4*$K$5)+K13 -> 0 | L14: =($L$3*$L$4*$L$5)+L13 -> 0 | M14: =($M$3*$M$4*$M$5)+M13 -> 0 | N14: =($N$3*$N$4*$N$5)+N13 -> 0 | O14: =SUM(C14:N14) -> 0 | P14: =O14*365 -> 0
A15: =+A14+1 -> 2029 | C15: =($C$3*$C$4*$C$5)+C14 -> 0 | D15: =($D$3*$D$4*$D$5)+D14 -> 0 | E15: =($E$3*$E$4*$E$5)+E14 -> 0 | F15: =($F$3*$F$4*$F$5)+F14 -> 0 | G15: =($G$3*$G$4*$G$5)+G14 -> 0 | H15: =($H$3*$H$4*$H$5)+H14 -> 0 | I15: =($I$3*$I$4*$I$5)+I14 -> 0 | J15: =($J$3*$J$4*$J$5)+J14 -> 0 | K15: =($K$3*$K$4*$K$5)+K14 -> 0 | L15: =($L$3*$L$4*$L$5)+L14 -> 0 | M15: =($M$3*$M$4*$M$5)+M14 -> 0 | N15: =($N$3*$N$4*$N$5)+N14 -> 0 | O15: =SUM(C15:N15) -> 0 | P15: =O15*365 -> 0
A16: =+A15+1 -> 2030 | C16: =($C$3*$C$4*$C$5)+C15 -> 0 | D16: =($D$3*$D$4*$D$5)+D15 -> 0 | E16: =($E$3*$E$4*$E$5)+E15 -> 0 | F16: =($F$3*$F$4*$F$5)+F15 -> 0 | G16: =($G$3*$G$4*$G$5)+G15 -> 0 | H16: =($H$3*$H$4*$H$5)+H15 -> 0 | I16: =($I$3*$I$4*$I$5)+I15 -> 0 | J16: =($J$3*$J$4*$J$5)+J15 -> 0 | K16: =($K$3*$K$4*$K$5)+K15 -> 0 | L16: =($L$3*$L$4*$L$5)+L15 -> 0 | M16: =($M$3*$M$4*$M$5)+M15 -> 0 | N16: =($N$3*$N$4*$N$5)+N15 -> 0 | O16: =SUM(C16:N16) -> 0 | P16: =O16*365 -> 0
A17: =+A16+1 -> 2031 | C17: =($C$3*$C$4*$C$5)+C16 -> 0 | D17: =($D$3*$D$4*$D$5)+D16 -> 0 | E17: =($E$3*$E$4*$E$5)+E16 -> 0 | F17: =($F$3*$F$4*$F$5)+F16 -> 0 | G17: =($G$3*$G$4*$G$5)+G16 -> 0 | H17: =($H$3*$H$4*$H$5)+H16 -> 0 | I17: =($I$3*$I$4*$I$5)+I16 -> 0 | J17: =($J$3*$J$4*$J$5)+J16 -> 0 | K17: =($K$3*$K$4*$K$5)+K16 -> 0 | L17: =($L$3*$L$4*$L$5)+L16 -> 0 | M17: =($M$3*$M$4*$M$5)+M16 -> 0 | N17: =($N$3*$N$4*$N$5)+N16 -> 0 | O17: =SUM(C17:N17) -> 0 | P17: =O17*365 -> 0
