Workbook

Sheet CONSOLIDADO
B1: AUTOMÓVILES VAGONETAS Y JEEP | C1: CAMIONETAS | D1: MINIBUSES | E1: MICROBUSES (DOS EJES) | F1: BÚS MEDIANO (DOS EJES) | G1: BÚS GRANDE (DOS O MAS EJES) | H1: CAMIÓN MEDIANO (DOS EJES) | I1: CAMIÓN GRANDE ( DOS EJES) | J1: CAMION GRANDE (TRES EJES) | K1: CAMIÓN CON SEMIRREMOLQUE | L1: CAMION CON REMOLQUE | M1: MOTOCICLETAS | N1: OTROS VEHICULOS | O1: TOTAL
A2: Sabado | O2: =SUM(B2:N2) -> 0
A3: Domingo | O3: =SUM(B3:N3) -> 0
A4: Lunes | O4: =SUM(B4:N4) -> 0
A5: Martes | O5: =SUM(B5:N5) -> 0
A6: Miércoles | O6: =SUM(B6:N6) -> 0
A7: Jueves | O7: =SUM(B7:N7) -> 0
A8: Viernes | O8: =SUM(B8:N8) -> 0
A9: TOTAL | O9: =SUM(O2:O8) -> 0
A10: PROMEDIO | B10: =SUM(B2:B8)/7 -> 0 | C10: =SUM(C2:C8)/7 -> 0 | D10: =SUM(D2:D8)/7 -> 0 | E10: =SUM(E2:E8)/7 -> 0 | F10: =SUM(F2:F8)/7 -> 0 | G10: =SUM(G2:G8)/7 -> 0 | H10: =SUM(H2:H8)/7 -> 0 | I10: =SUM(I2:I8)/7 -> 0 | ... N10: =SUM(N2:N8)/7 -> 0 | O10: =O9/7 -> 0
B14: AUTOMÓVILES VAGONETAS Y JEEP | C14: CAMIONETAS | D14: MINIBUSES | E14: MICROBUSES (DOS EJES) | F14: BÚS MEDIANO (DOS EJES) | G14: BÚS GRANDE (DOS O MAS EJES) | H14: CAMIÓN MEDIANO (DOS EJES) | I14: CAMIÓN GRANDE ( DOS EJES) | J14: CAMION GRANDE (TRES EJES) | K14: CAMIÓN CON SEMIRREMOLQUE | L14: CAMION CON REMOLQUE | M14: MOTOCICLETAS | N14: OTROS VEHICULOS | O14: TOTAL
A15: Sabado | O15: =SUM(B15:N15) -> 0
A16: Domingo | O16: =SUM(B16:N16) -> 0
A17: Lunes | O17: =SUM(B17:N17) -> 0
A18: Martes | O18: =SUM(B18:N18) -> 0
A19: Miércoles | O19: =SUM(B19:N19) -> 0
A20: Jueves | O20: =SUM(B20:N20) -> 0
A21: Viernes | O21: =SUM(B21:N21) -> 0
A22: TOTAL | O22: =SUM(O15:O21) -> 0
A23: PROMEDIO | B23: =SUM(B15:B21)/7 -> 0 | C23: =SUM(C15:C21)/7 -> 0 | D23: =SUM(D15:D21)/7 -> 0 | E23: =SUM(E15:E21)/7 -> 0 | F23: =SUM(F15:F21)/7 -> 0 | G23: =SUM(G15:G21)/7 -> 0 | H23: =SUM(H15:H21)/7 -> 0 | I23: =SUM(I15:I21)/7 -> 0 | ... N23: =SUM(N15:N21)/7 -> 0 | O23: =O22/7 -> 0
B27: AUTOMÓVILES VAGONETAS Y JEEP | C27: CAMIONETAS | D27: MINIBUSES | E27: MICROBUSES (DOS EJES) | F27: BÚS MEDIANO (DOS EJES) | G27: BÚS GRANDE (DOS O MAS EJES) | H27: CAMIÓN MEDIANO (DOS EJES) | I27: CAMIÓN GRANDE ( DOS EJES) | J27: CAMION GRANDE (TRES EJES) | K27: CAMIÓN CON SEMIRREMOLQUE | L27: CAMION CON REMOLQUE | M27: MOTOCICLETAS | N27: OTROS VEHICULOS | O27: TOTAL
A28: Sabado | B28: =B2+B15 -> 0 | C28: =C2+C15 -> 0 | D28: =D2+D15 -> 0 | E28: =E2+E15 -> 0 | F28: =F2+F15 -> 0 | G28: =G2+G15 -> 0 | H28: =H2+H15 -> 0 | I28: =I2+I15 -> 0 | ... N28: =N2+N15 -> 0 | O28: =SUM(B28:N28) -> 0
A29: Domingo | B29: =B3+B16 -> 0 | C29: =C3+C16 -> 0 | D29: =D3+D16 -> 0 | E29: =E3+E16 -> 0 | F29: =F3+F16 -> 0 | G29: =G3+G16 -> 0 | H29: =H3+H16 -> 0 | I29: =I3+I16 -> 0 | ... N29: =N3+N16 -> 0 | O29: =SUM(B29:N29) -> 0
A30: Lunes | B30: =B4+B17 -> 0 | C30: =C4+C17 -> 0 | D30: =D4+D17 -> 0 | E30: =E4+E17 -> 0 | F30: =F4+F17 -> 0 | G30: =G4+G17 -> 0 | H30: =H4+H17 -> 0 | I30: =I4+I17 -> 0 | ... N30: =N4+N17 -> 0 | O30: =SUM(B30:N30) -> 0
A31: Martes | B31: =B5+B18 -> 0 | C31: =C5+C18 -> 0 | D31: =D5+D18 -> 0 | E31: =E5+E18 -> 0 | F31: =F5+F18 -> 0 | G31: =G5+G18 -> 0 | H31: =H5+H18 -> 0 | I31: =I5+I18 -> 0 | ... N31: =N5+N18 -> 0 | O31: =SUM(B31:N31) -> 0
A32: Miércoles | B32: =B6+B19 -> 0 | C32: =C6+C19 -> 0 | D32: =D6+D19 -> 0 | E32: =E6+E19 -> 0 | F32: =F6+F19 -> 0 | G32: =G6+G19 -> 0 | H32: =H6+H19 -> 0 | I32: =I6+I19 -> 0 | ... N32: =N6+N19 -> 0 | O32: =SUM(B32:N32) -> 0
A33: Jueves | B33: =B7+B20 -> 0 | C33: =C7+C20 -> 0 | D33: =D7+D20 -> 0 | E33: =E7+E20 -> 0 | F33: =F7+F20 -> 0 | G33: =G7+G20 -> 0 | H33: =H7+H20 -> 0 | I33: =I7+I20 -> 0 | ... N33: =N7+N20 -> 0 | O33: =SUM(B33:N33) -> 0
A34: Viernes | B34: =B8+B21 -> 0 | C34: =C8+C21 -> 0 | D34: =D8+D21 -> 0 | E34: =E8+E21 -> 0 | F34: =F8+F21 -> 0 | G34: =G8+G21 -> 0 | H34: =H8+H21 -> 0 | I34: =I8+I21 -> 0 | ... N34: =N8+N21 -> 0 | O34: =SUM(B34:N34) -> 0
A35: TOTAL | B35: =SUM(B28:B34) -> 0 | C35: =SUM(C28:C34) -> 0 | D35: =SUM(D28:D34) -> 0 | E35: =SUM(E28:E34) -> 0 | F35: =SUM(F28:F34) -> 0 | G35: =SUM(G28:G34) -> 0 | H35: =SUM(H28:H34) -> 0 | I35: =SUM(I28:I34) -> 0 | ... O35: =SUM(O28:O34) -> 0
A36: PROMEDIO | B36: =SUM(B28:B34)/7 -> 0 | C36: =SUM(C28:C34)/7 -> 0 | D36: =SUM(D28:D34)/7 -> 0 | E36: =SUM(E28:E34)/7 -> 0 | F36: =SUM(F28:F34)/7 -> 0 | G36: =SUM(G28:G34)/7 -> 0 | H36: =SUM(H28:H34)/7 -> 0 | I36: =SUM(I28:I34)/7 -> 0 | ... N36: =SUM(N28:N34)/7 -> 0 | O36: =O35/7 -> 0
B38: =B36/O36 -> #DIV/0!

Sheet dia 1
A3: RESUMEN DE CONTEO
A4: CLASIFICACIÓN DE VEHÍCULOS
A6: CAMINO:DOBLE VIA ORURO - COCHABAMBA | J6: DEPARTAMENTO:
A7: ESTACIÓN: CAIHUASI | F7: Nº. | G7: S/N
A8: TRAMO: 1 | J8: FECHA:
A10: HORA DE - A | B10: AUTOMÓVILES VAGONETAS Y JEEP | C10: CAMIONETAS | D10: MINIBUSES | E10: MICROBUSES (DOS EJES) | F10: BÚS MEDIANO (DOS EJES) | G10: BÚS GRANDE (DOS O MAS EJES) | H10: CAMIÓN MEDIANO (DOS EJES) | I10: CAMIÓN GRANDE ( DOS EJES) | J10: CAMION GRANDE (TRES EJES) | K10: CAMIÓN CON SEMIRREMOLQUE | L10: CAMION CON REMOLQUE | M10: MOTOCICLETAS | N10: OTROS VEHICULOS | O10: TOTAL | P10: PORCENTAJE
A11: 0 - 1 | B11: ='[1]DP8 CAIHUASI S1'!B11+'[1]DP6 CAIHUASI S2'!B11 -> 11 | C11: ='[1]DP8 CAIHUASI S1'!C11+'[1]DP6 CAIHUASI S2'!C11 -> 2 | D11: ='[1]DP8 CAIHUASI S1'!D11+'[1]DP6 CAIHUASI S2'!D11 -> 9 | E11: ='[1]DP8 CAIHUASI S1'!E11+'[1]DP6 CAIHUASI S2'!E11 -> 0 | F11: ='[1]DP8 CAIHUASI S1'!F11+'[1]DP6 CAIHUASI S2'!F11 -> 0 | G11: ='[1]DP8 CAIHUASI S1'!G11+'[1]DP6 CAIHUASI S2'!G11 -> 23 | H11: ='[1]DP8 CAIHUASI S1'!H11+'[1]DP6 CAIHUASI S2'!H11 -> 0 | I11: ='[1]DP8 CAIHUASI S1'!I11+'[1]DP6 CAIHUASI S2'!I11 -> 0 | ... N11: ='[1]DP8 CAIHUASI S1'!N11+'[1]DP6 CAIHUASI S2'!N11 -> 0 | O11: =SUM(B11:N11) -> 93 | P11: =O11/$O$35 -> 0.024720893
A12: 1 - 2 | B12: ='[1]DP8 CAIHUASI S1'!B12+'[1]DP6 CAIHUASI S2'!B12 -> 7 | C12: ='[1]DP8 CAIHUASI S1'!C12+'[1]DP6 CAIHUASI S2'!C12 -> 0 | D12: ='[1]DP8 CAIHUASI S1'!D12+'[1]DP6 CAIHUASI S2'!D12 -> 18 | E12: ='[1]DP8 CAIHUASI S1'!E12+'[1]DP6 CAIHUASI S2'!E12 -> 0 | F12: ='[1]DP8 CAIHUASI S1'!F12+'[1]DP6 CAIHUASI S2'!F12 -> 0 | G12: ='[1]DP8 CAIHUASI S1'!G12+'[1]DP6 CAIHUASI S2'!G12 -> 22 | H12: ='[1]DP8 CAIHUASI S1'!H12+'[1]DP6 CAIHUASI S2'!H12 -> 0 | I12: ='[1]DP8 CAIHUASI S1'!I12+'[1]DP6 CAIHUASI S2'!I12 -> 0 | ... N12: ='[1]DP8 CAIHUASI S1'!N12+'[1]DP6 CAIHUASI S2'!N12 -> 0 | O12: =SUM(B12:N12) -> 90 | P12: =O12/$O$35 -> 0.023923445
A13: 2 - 3 | B13: ='[1]DP8 CAIHUASI S1'!B13+'[1]DP6 CAIHUASI S2'!B13 -> 13 | C13: ='[1]DP8 CAIHUASI S1'!C13+'[1]DP6 CAIHUASI S2'!C13 -> 0 | D13: ='[1]DP8 CAIHUASI S1'!D13+'[1]DP6 CAIHUASI S2'!D13 -> 12 | E13: ='[1]DP8 CAIHUASI S1'!E13+'[1]DP6 CAIHUASI S2'!E13 -> 0 | F13: ='[1]DP8 CAIHUASI S1'!F13+'[1]DP6 CAIHUASI S2'!F13 -> 0 | G13: ='[1]DP8 CAIHUASI S1'!G13+'[1]DP6 CAIHUASI S2'!G13 -> 19 | H13: ='[1]DP8 CAIHUASI S1'!H13+'[1]DP6 CAIHUASI S2'!H13 -> 0 | I13: ='[1]DP8 CAIHUASI S1'!I13+'[1]DP6 CAIHUASI S2'!I13 -> 2 | ... N13: ='[1]DP8 CAIHUASI S1'!N13+'[1]DP6 CAIHUASI S2'!N13 -> 0 | O13: =SUM(B13:N13) -> 93 | P13: =O13/$O$35 -> 0.024720893
A14: 3 - 4 | B14: ='[1]DP8 CAIHUASI S1'!B14+'[1]DP6 CAIHUASI S2'!B14 -> 15 | C14: ='[1]DP8 CAIHUASI S1'!C14+'[1]DP6 CAIHUASI S2'!C14 -> 3 | D14: ='[1]DP8 CAIHUASI S1'!D14+'[1]DP6 CAIHUASI S2'!D14 -> 7 | E14: ='[1]DP8 CAIHUASI S1'!E14+'[1]DP6 CAIHUASI S2'!E14 -> 0 | F14: ='[1]DP8 CAIHUASI S1'!F14+'[1]DP6 CAIHUASI S2'!F14 -> 7 | G14: ='[1]DP8 CAIHUASI S1'!G14+'[1]DP6 CAIHUASI S2'!G14 -> 29 | H14: ='[1]DP8 CAIHUASI S1'!H14+'[1]DP6 CAIHUASI S2'!H14 -> 4 | I14: ='[1]DP8 CAIHUASI S1'!I14+'[1]DP6 CAIHUASI S2'!I14 -> 6 | ... N14: ='[1]DP8 CAIHUASI S1'!N14+'[1]DP6 CAIHUASI S2'!N14 -> 0 | O14: =SUM(B14:N14) -> 103 | P14: =O14/$O$35 -> 0.027379054
A15: 4 - 5 | B15: ='[1]DP8 CAIHUASI S1'!B15+'[1]DP6 CAIHUASI S2'!B15 -> 15 | C15: ='[1]DP8 CAIHUASI S1'!C15+'[1]DP6 CAIHUASI S2'!C15 -> 4 | D15: ='[1]DP8 CAIHUASI S1'!D15+'[1]DP6 CAIHUASI S2'!D15 -> 5 | E15: ='[1]DP8 CAIHUASI S1'!E15+'[1]DP6 CAIHUASI S2'!E15 -> 0 | F15: ='[1]DP8 CAIHUASI S1'!F15+'[1]DP6 CAIHUASI S2'!F15 -> 3 | G15: ='[1]DP8 CAIHUASI S1'!G15+'[1]DP6 CAIHUASI S2'!G15 -> 20 | H15: ='[1]DP8 CAIHUASI S1'!H15+'[1]DP6 CAIHUASI S2'!H15 -> 3 | I15: ='[1]DP8 CAIHUASI S1'!I15+'[1]DP6 CAIHUASI S2'!I15 -> 8 | ... N15: ='[1]DP8 CAIHUASI S1'!N15+'[1]DP6 CAIHUASI S2'!N15 -> 0 | O15: =SUM(B15:N15) -> 96 | P15: =O15/$O$35 -> 0.025518341
A16: 5 - 6 | B16: ='[1]DP8 CAIHUASI S1'!B16+'[1]DP6 CAIHUASI S2'!B16 -> 31 | C16: ='[1]DP8 CAIHUASI S1'!C16+'[1]DP6 CAIHUASI S2'!C16 -> 9 | D16: ='[1]DP8 CAIHUASI S1'!D16+'[1]DP6 CAIHUASI S2'!D16 -> 21 | E16: ='[1]DP8 CAIHUASI S1'!E16+'[1]DP6 CAIHUASI S2'!E16 -> 0 | F16: ='[1]DP8 CAIHUASI S1'!F16+'[1]DP6 CAIHUASI S2'!F16 -> 3 | G16: ='[1]DP8 CAIHUASI S1'!G16+'[1]DP6 CAIHUASI S2'!G16 -> 16 | H16: ='[1]DP8 CAIHUASI S1'!H16+'[1]DP6 CAIHUASI S2'!H16 -> 11 | I16: ='[1]DP8 CAIHUASI S1'!I16+'[1]DP6 CAIHUASI S2'!I16 -> 10 | ... N16: ='[1]DP8 CAIHUASI S1'!N16+'[1]DP6 CAIHUASI S2'!N16 -> 0 | O16: =SUM(B16:N16) -> 161 | P16: =O16/$O$35 -> 0.042796385
A17: 6 - 7 | B17: ='[1]DP8 CAIHUASI S1'!B17+'[1]DP6 CAIHUASI S2'!B17 -> 40 | C17: ='[1]DP8 CAIHUASI S1'!C17+'[1]DP6 CAIHUASI S2'!C17 -> 5 | D17: ='[1]DP8 CAIHUASI S1'!D17+'[1]DP6 CAIHUASI S2'!D17 -> 40 | E17: ='[1]DP8 CAIHUASI S1'!E17+'[1]DP6 CAIHUASI S2'!E17 -> 1 | F17: ='[1]DP8 CAIHUASI S1'!F17+'[1]DP6 CAIHUASI S2'!F17 -> 6 | G17: ='[1]DP8 CAIHUASI S1'!G17+'[1]DP6 CAIHUASI S2'!G17 -> 26 | H17: ='[1]DP8 CAIHUASI S1'!H17+'[1]DP6 CAIHUASI S2'!H17 -> 2 | I17: ='[1]DP8 CAIHUASI S1'!I17+'[1]DP6 CAIHUASI S2'!I17 -> 12 | ... N17: ='[1]DP8 CAIHUASI S1'!N17+'[1]DP6 CAIHUASI S2'!N17 -> 0 | O17: =SUM(B17:N17) -> 185 | P17: =O17/$O$35 -> 0.04917597
A18: 7 - 8 | B18: ='[1]DP8 CAIHUASI S1'!B18+'[1]DP6 CAIHUASI S2'!B18 -> 43 | C18: ='[1]DP8 CAIHUASI S1'!C18+'[1]DP6 CAIHUASI S2'!C18 -> 11 | D18: ='[1]DP8 CAIHUASI S1'!D18+'[1]DP6 CAIHUASI S2'!D18 -> 14 | E18: ='[1]DP8 CAIHUASI S1'!E18+'[1]DP6 CAIHUASI S2'!E18 -> 1 | F18: ='[1]DP8 CAIHUASI S1'!F18+'[1]DP6 CAIHUASI S2'!F18 -> 2 | G18: ='[1]DP8 CAIHUASI S1'!G18+'[1]DP6 CAIHUASI S2'!G18 -> 18 | H18: ='[1]DP8 CAIHUASI S1'!H18+'[1]DP6 CAIHUASI S2'!H18 -> 3 | I18: ='[1]DP8 CAIHUASI S1'!I18+'[1]DP6 CAIHUASI S2'!I18 -> 1 | ... N18: ='[1]DP8 CAIHUASI S1'!N18+'[1]DP6 CAIHUASI S2'!N18 -> 0 | O18: =SUM(B18:N18) -> 138 | P18: =O18/$O$35 -> 0.036682616
A19: 8 - 9 | B19: ='[1]DP8 CAIHUASI S1'!B19+'[1]DP6 CAIHUASI S2'!B19 -> 49 | C19: ='[1]DP8 CAIHUASI S1'!C19+'[1]DP6 CAIHUASI S2'!C19 -> 13 | D19: ='[1]DP8 CAIHUASI S1'!D19+'[1]DP6 CAIHUASI S2'!D19 -> 18 | E19: ='[1]DP8 CAIHUASI S1'!E19+'[1]DP6 CAIHUASI S2'!E19 -> 0 | F19: ='[1]DP8 CAIHUASI S1'!F19+'[1]DP6 CAIHUASI S2'!F19 -> 4 | G19: ='[1]DP8 CAIHUASI S1'!G19+'[1]DP6 CAIHUASI S2'!G19 -> 9 | H19: ='[1]DP8 CAIHUASI S1'!H19+'[1]DP6 CAIHUASI S2'!H19 -> 1 | I19: ='[1]DP8 CAIHUASI S1'!I19+'[1]DP6 CAIHUASI S2'!I19 -> 4 | ... N19: ='[1]DP8 CAIHUASI S1'!N19+'[1]DP6 CAIHUASI S2'!N19 -> 0 | O19: =SUM(B19:N19) -> 116 | P19: =O19/$O$35 -> 0.030834662
A20: 9 - 10 | B20: ='[1]DP8 CAIHUASI S1'!B20+'[1]DP6 CAIHUASI S2'!B20 -> 28 | C20: ='[1]DP8 CAIHUASI S1'!C20+'[1]DP6 CAIHUASI S2'!C20 -> 9 | D20: ='[1]DP8 CAIHUASI S1'!D20+'[1]DP6 CAIHUASI S2'!D20 -> 22 | E20: ='[1]DP8 CAIHUASI S1'!E20+'[1]DP6 CAIHUASI S2'!E20 -> 0 | F20: ='[1]DP8 CAIHUASI S1'!F20+'[1]DP6 CAIHUASI S2'!F20 -> 7 | G20: ='[1]DP8 CAIHUASI S1'!G20+'[1]DP6 CAIHUASI S2'!G20 -> 28 | H20: ='[1]DP8 CAIHUASI S1'!H20+'[1]DP6 CAIHUASI S2'!H20 -> 1 | I20: ='[1]DP8 CAIHUASI S1'!I20+'[1]DP6 CAIHUASI S2'!I20 -> 11 | ... N20: ='[1]DP8 CAIHUASI S1'!N20+'[1]DP6 CAIHUASI S2'!N20 -> 0 | O20: =SUM(B20:N20) -> 161 | P20: =O20/$O$35 -> 0.042796385
A21: 10 - 11 | B21: ='[1]DP8 CAIHUASI S1'!B21+'[1]DP6 CAIHUASI S2'!B21 -> 29 | C21: ='[1]DP8 CAIHUASI S1'!C21+'[1]DP6 CAIHUASI S2'!C21 -> 7 | D21: ='[1]DP8 CAIHUASI S1'!D21+'[1]DP6 CAIHUASI S2'!D21 -> 36 | E21: ='[1]DP8 CAIHUASI S1'!E21+'[1]DP6 CAIHUASI S2'!E21 -> 0 | F21: ='[1]DP8 CAIHUASI S1'!F21+'[1]DP6 CAIHUASI S2'!F21 -> 8 | G21: ='[1]DP8 CAIHUASI S1'!G21+'[1]DP6 CAIHUASI S2'!G21 -> 26 | H21: ='[1]DP8 CAIHUASI S1'!H21+'[1]DP6 CAIHUASI S2'!H21 -> 2 | I21: ='[1]DP8 CAIHUASI S1'!I21+'[1]DP6 CAIHUASI S2'!I21 -> 15 | ... N21: ='[1]DP8 CAIHUASI S1'!N21+'[1]DP6 CAIHUASI S2'!N21 -> 0 | O21: =SUM(B21:N21) -> 181 | P21: =O21/$O$35 -> 0.048112706
A22: 11 - 12 | B22: ='[1]DP8 CAIHUASI S1'!B22+'[1]DP6 CAIHUASI S2'!B22 -> 30 | C22: ='[1]DP8 CAIHUASI S1'!C22+'[1]DP6 CAIHUASI S2'!C22 -> 10 | D22: ='[1]DP8 CAIHUASI S1'!D22+'[1]DP6 CAIHUASI S2'!D22 -> 19 | E22: ='[1]DP8 CAIHUASI S1'!E22+'[1]DP6 CAIHUASI S2'!E22 -> 0 | F22: ='[1]DP8 CAIHUASI S1'!F22+'[1]DP6 CAIHUASI S2'!F22 -> 0 | G22: ='[1]DP8 CAIHUASI S1'!G22+'[1]DP6 CAIHUASI S2'!G22 -> 27 | H22: ='[1]DP8 CAIHUASI S1'!H22+'[1]DP6 CAIHUASI S2'!H22 -> 1 | I22: ='[1]DP8 CAIHUASI S1'!I22+'[1]DP6 CAIHUASI S2'!I22 -> 1 | ... N22: ='[1]DP8 CAIHUASI S1'!N22+'[1]DP6 CAIHUASI S2'!N22 -> 0 | O22: =SUM(B22:N22) -> 123 | P22: =O22/$O$35 -> 0.032695375
... A34: 23 - 24 | B34: ='[1]DP8 CAIHUASI S1'!B34+'[1]DP6 CAIHUASI S2'!B34 -> 20 | C34: ='[1]DP8 CAIHUASI S1'!C34+'[1]DP6 CAIHUASI S2'!C34 -> 2 | D34: ='[1]DP8 CAIHUASI S1'!D34+'[1]DP6 CAIHUASI S2'!D34 -> 14 | E34: ='[1]DP8 CAIHUASI S1'!E34+'[1]DP6 CAIHUASI S2'!E34 -> 0 | F34: ='[1]DP8 CAIHUASI S1'!F34+'[1]DP6 CAIHUASI S2'!F34 -> 6 | G34: ='[1]DP8 CAIHUASI S1'!G34+'[1]DP6 CAIHUASI S2'!G34 -> 18 | H34: ='[1]DP8 CAIHUASI S1'!H34+'[1]DP6 CAIHUASI S2'!H34 -> 0 | I34: ='[1]DP8 CAIHUASI S1'!I34+'[1]DP6 CAIHUASI S2'!I34 -> 7 | ... N34: ='[1]DP8 CAIHUASI S1'!N34+'[1]DP6 CAIHUASI S2'!N34 -> 0 | O34: =SUM(B34:N34) -> 122 | P34: =O34/$O$35 -> 0.032429559
A35: TOTAL | B35: =SUM(B11:B34) -> 1080 | C35: =SUM(C11:C34) -> 181 | D35: =SUM(D11:D34) -> 570 | E35: =SUM(E11:E34) -> 3 | F35: =SUM(F11:F34) -> 66 | G35: =SUM(G11:G34) -> 476 | H35: =SUM(H11:H34) -> 66 | I35: =SUM(I11:I34) -> 178 | ... P35: =SUM(P11:P34) -> 1
A36: (%) | B36: =B35/$O$35 -> 0.28708134 | C36: =C35/$O$35 -> 0.048112706 | D36: =D35/$O$35 -> 0.15151515 | E36: =E35/$O$35 -> 0.00079744817 | F36: =F35/$O$35 -> 0.01754386 | G36: =G35/$O$35 -> 0.12652844 | H36: =H35/$O$35 -> 0.01754386 | I36: =I35/$O$35 -> 0.047315258 | ... N36: =N35/$O$35 -> 0 | O36: =SUM(B36:N36) -> 1

Sheet dia 2
A3: RESUMEN DE CONTEO
A4: CLASIFICACIÓN DE VEHÍCULOS
A6: CAMINO:DOBLE VIA ORURO - COCHABAMBA | J6: DEPARTAMENTO:
A7: ESTACIÓN> CAIHUASI | F7: Nº. | G7: S/N
A8: TRAMO: 1 | J8: FECHA:
A10: HORA DE - A | B10: AUTOMÓVILES VAGONETAS Y JEEP | C10: CAMIONETAS | D10: MINIBUSES | E10: MICROBUSES (DOS EJES) | F10: BÚS MEDIANO (DOS EJES) | G10: BÚS GRANDE (DOS O MAS EJES) | H10: CAMIÓN MEDIANO (DOS EJES) | I10: CAMIÓN GRANDE ( DOS EJES) | J10: CAMION GRANDE (TRES EJES) | K10: CAMIÓN CON SEMIRREMOLQUE | L10: CAMION CON REMOLQUE | M10: MOTOCICLETAS | N10: OTROS VEHICULOS | O10: TOTAL | P10: PORCENTAJE
A11: 0 - 1 | B11: ='[2]DP8 CAIHUASI S1'!B11+'[2]DP6 CAIHUASI S2'!B11 -> 19 | C11: ='[2]DP8 CAIHUASI S1'!C11+'[2]DP6 CAIHUASI S2'!C11 -> 7 | D11: ='[2]DP8 CAIHUASI S1'!D11+'[2]DP6 CAIHUASI S2'!D11 -> 7 | E11: ='[2]DP8 CAIHUASI S1'!E11+'[2]DP6 CAIHUASI S2'!E11 -> 0 | F11: ='[2]DP8 CAIHUASI S1'!F11+'[2]DP6 CAIHUASI S2'!F11 -> 6 | G11: ='[2]DP8 CAIHUASI S1'!G11+'[2]DP6 CAIHUASI S2'!G11 -> 15 | H11: ='[2]DP8 CAIHUASI S1'!H11+'[2]DP6 CAIHUASI S2'!H11 -> 2 | I11: ='[2]DP8 CAIHUASI S1'!I11+'[2]DP6 CAIHUASI S2'!I11 -> 7 | ... N11: ='[2]DP8 CAIHUASI S1'!N11+'[2]DP6 CAIHUASI S2'!N11 -> 0 | O11: =SUM(B11:N11) -> 111 | P11: =O11/$O$35 -> 0.027896456
A12: 1 - 2 | B12: ='[2]DP8 CAIHUASI S1'!B12+'[2]DP6 CAIHUASI S2'!B12 -> 19 | C12: ='[2]DP8 CAIHUASI S1'!C12+'[2]DP6 CAIHUASI S2'!C12 -> 2 | D12: ='[2]DP8 CAIHUASI S1'!D12+'[2]DP6 CAIHUASI S2'!D12 -> 6 | E12: ='[2]DP8 CAIHUASI S1'!E12+'[2]DP6 CAIHUASI S2'!E12 -> 0 | F12: ='[2]DP8 CAIHUASI S1'!F12+'[2]DP6 CAIHUASI S2'!F12 -> 6 | G12: ='[2]DP8 CAIHUASI S1'!G12+'[2]DP6 CAIHUASI S2'!G12 -> 39 | H12: ='[2]DP8 CAIHUASI S1'!H12+'[2]DP6 CAIHUASI S2'!H12 -> 1 | I12: ='[2]DP8 CAIHUASI S1'!I12+'[2]DP6 CAIHUASI S2'!I12 -> 9 | ... N12: ='[2]DP8 CAIHUASI S1'!N12+'[2]DP6 CAIHUASI S2'!N12 -> 0 | O12: =SUM(B12:N12) -> 110 | P12: =O12/$O$35 -> 0.027645137
A13: 2 - 3 | B13: ='[2]DP8 CAIHUASI S1'!B13+'[2]DP6 CAIHUASI S2'!B13 -> 13 | C13: ='[2]DP8 CAIHUASI S1'!C13+'[2]DP6 CAIHUASI S2'!C13 -> 3 | D13: ='[2]DP8 CAIHUASI S1'!D13+'[2]DP6 CAIHUASI S2'!D13 -> 5 | E13: ='[2]DP8 CAIHUASI S1'!E13+'[2]DP6 CAIHUASI S2'!E13 -> 0 | F13: ='[2]DP8 CAIHUASI S1'!F13+'[2]DP6 CAIHUASI S2'!F13 -> 4 | G13: ='[2]DP8 CAIHUASI S1'!G13+'[2]DP6 CAIHUASI S2'!G13 -> 56 | H13: ='[2]DP8 CAIHUASI S1'!H13+'[2]DP6 CAIHUASI S2'!H13 -> 1 | I13: ='[2]DP8 CAIHUASI S1'!I13+'[2]DP6 CAIHUASI S2'!I13 -> 4 | ... N13: ='[2]DP8 CAIHUASI S1'!N13+'[2]DP6 CAIHUASI S2'!N13 -> 0 | O13: =SUM(B13:N13) -> 104 | P13: =O13/$O$35 -> 0.02613722
A14: 3 - 4 | B14: ='[2]DP8 CAIHUASI S1'!B14+'[2]DP6 CAIHUASI S2'!B14 -> 20 | C14: ='[2]DP8 CAIHUASI S1'!C14+'[2]DP6 CAIHUASI S2'!C14 -> 2 | D14: ='[2]DP8 CAIHUASI S1'!D14+'[2]DP6 CAIHUASI S2'!D14 -> 12 | E14: ='[2]DP8 CAIHUASI S1'!E14+'[2]DP6 CAIHUASI S2'!E14 -> 0 | F14: ='[2]DP8 CAIHUASI S1'!F14+'[2]DP6 CAIHUASI S2'!F14 -> 1 | G14: ='[2]DP8 CAIHUASI S1'!G14+'[2]DP6 CAIHUASI S2'!G14 -> 31 | H14: ='[2]DP8 CAIHUASI S1'!H14+'[2]DP6 CAIHUASI S2'!H14 -> 0 | I14: ='[2]DP8 CAIHUASI S1'!I14+'[2]DP6 CAIHUASI S2'!I14 -> 4 | ... N14: ='[2]DP8 CAIHUASI S1'!N14+'[2]DP6 CAIHUASI S2'!N14 -> 0 | O14: =SUM(B14:N14) -> 87 | P14: =O14/$O$35 -> 0.02186479
A15: 4 - 5 | B15: ='[2]DP8 CAIHUASI S1'!B15+'[2]DP6 CAIHUASI S2'!B15 -> 15 | C15: ='[2]DP8 CAIHUASI S1'!C15+'[2]DP6 CAIHUASI S2'!C15 -> 9 | D15: ='[2]DP8 CAIHUASI S1'!D15+'[2]DP6 CAIHUASI S2'!D15 -> 12 | E15: ='[2]DP8 CAIHUASI S1'!E15+'[2]DP6 CAIHUASI S2'!E15 -> 0 | F15: ='[2]DP8 CAIHUASI S1'!F15+'[2]DP6 CAIHUASI S2'!F15 -> 1 | G15: ='[2]DP8 CAIHUASI S1'!G15+'[2]DP6 CAIHUASI S2'!G15 -> 19 | H15: ='[2]DP8 CAIHUASI S1'!H15+'[2]DP6 CAIHUASI S2'!H15 -> 2 | I15: ='[2]DP8 CAIHUASI S1'!I15+'[2]DP6 CAIHUASI S2'!I15 -> 14 | ... N15: ='[2]DP8 CAIHUASI S1'!N15+'[2]DP6 CAIHUASI S2'!N15 -> 0 | O15: =SUM(B15:N15) -> 109 | P15: =O15/$O$35 -> 0.027393818
A16: 5 - 6 | B16: ='[2]DP8 CAIHUASI S1'!B16+'[2]DP6 CAIHUASI S2'!B16 -> 25 | C16: ='[2]DP8 CAIHUASI S1'!C16+'[2]DP6 CAIHUASI S2'!C16 -> 7 | D16: ='[2]DP8 CAIHUASI S1'!D16+'[2]DP6 CAIHUASI S2'!D16 -> 19 | E16: ='[2]DP8 CAIHUASI S1'!E16+'[2]DP6 CAIHUASI S2'!E16 -> 0 | F16: ='[2]DP8 CAIHUASI S1'!F16+'[2]DP6 CAIHUASI S2'!F16 -> 5 | G16: ='[2]DP8 CAIHUASI S1'!G16+'[2]DP6 CAIHUASI S2'!G16 -> 10 | H16: ='[2]DP8 CAIHUASI S1'!H16+'[2]DP6 CAIHUASI S2'!H16 -> 4 | I16: ='[2]DP8 CAIHUASI S1'!I16+'[2]DP6 CAIHUASI S2'!I16 -> 18 | ... N16: ='[2]DP8 CAIHUASI S1'!N16+'[2]DP6 CAIHUASI S2'!N16 -> 0 | O16: =SUM(B16:N16) -> 160 | P16: =O16/$O$35 -> 0.040211108
A17: 6 - 7 | B17: ='[2]DP8 CAIHUASI S1'!B17+'[2]DP6 CAIHUASI S2'!B17 -> 49 | C17: ='[2]DP8 CAIHUASI S1'!C17+'[2]DP6 CAIHUASI S2'!C17 -> 2 | D17: ='[2]DP8 CAIHUASI S1'!D17+'[2]DP6 CAIHUASI S2'!D17 -> 27 | E17: ='[2]DP8 CAIHUASI S1'!E17+'[2]DP6 CAIHUASI S2'!E17 -> 0 | F17: ='[2]DP8 CAIHUASI S1'!F17+'[2]DP6 CAIHUASI S2'!F17 -> 1 | G17: ='[2]DP8 CAIHUASI S1'!G17+'[2]DP6 CAIHUASI S2'!G17 -> 9 | H17: ='[2]DP8 CAIHUASI S1'!H17+'[2]DP6 CAIHUASI S2'!H17 -> 2 | I17: ='[2]DP8 CAIHUASI S1'!I17+'[2]DP6 CAIHUASI S2'!I17 -> 7 | ... N17: ='[2]DP8 CAIHUASI S1'!N17+'[2]DP6 CAIHUASI S2'!N17 -> 0 | O17: =SUM(B17:N17) -> 141 | P17: =O17/$O$35 -> 0.035436039
A18: 7 - 8 | B18: ='[2]DP8 CAIHUASI S1'!B18+'[2]DP6 CAIHUASI S2'!B18 -> 38 | C18: ='[2]DP8 CAIHUASI S1'!C18+'[2]DP6 CAIHUASI S2'!C18 -> 6 | D18: ='[2]DP8 CAIHUASI S1'!D18+'[2]DP6 CAIHUASI S2'!D18 -> 26 | E18: ='[2]DP8 CAIHUASI S1'!E18+'[2]DP6 CAIHUASI S2'!E18 -> 0 | F18: ='[2]DP8 CAIHUASI S1'!F18+'[2]DP6 CAIHUASI S2'!F18 -> 2 | G18: ='[2]DP8 CAIHUASI S1'!G18+'[2]DP6 CAIHUASI S2'!G18 -> 10 | H18: ='[2]DP8 CAIHUASI S1'!H18+'[2]DP6 CAIHUASI S2'!H18 -> 2 | I18: ='[2]DP8 CAIHUASI S1'!I18+'[2]DP6 CAIHUASI S2'!I18 -> 8 | ... N18: ='[2]DP8 CAIHUASI S1'!N18+'[2]DP6 CAIHUASI S2'!N18 -> 0 | O18: =SUM(B18:N18) -> 136 | P18: =O18/$O$35 -> 0.034179442
A19: 8 - 9 | B19: ='[2]DP8 CAIHUASI S1'!B19+'[2]DP6 CAIHUASI S2'!B19 -> 71 | C19: ='[2]DP8 CAIHUASI S1'!C19+'[2]DP6 CAIHUASI S2'!C19 -> 12 | D19: ='[2]DP8 CAIHUASI S1'!D19+'[2]DP6 CAIHUASI S2'!D19 -> 31 | E19: ='[2]DP8 CAIHUASI S1'!E19+'[2]DP6 CAIHUASI S2'!E19 -> 0 | F19: ='[2]DP8 CAIHUASI S1'!F19+'[2]DP6 CAIHUASI S2'!F19 -> 1 | G19: ='[2]DP8 CAIHUASI S1'!G19+'[2]DP6 CAIHUASI S2'!G19 -> 10 | H19: ='[2]DP8 CAIHUASI S1'!H19+'[2]DP6 CAIHUASI S2'!H19 -> 4 | I19: ='[2]DP8 CAIHUASI S1'!I19+'[2]DP6 CAIHUASI S2'!I19 -> 6 | ... N19: ='[2]DP8 CAIHUASI S1'!N19+'[2]DP6 CAIHUASI S2'!N19 -> 0 | O19: =SUM(B19:N19) -> 182 | P19: =O19/$O$35 -> 0.045740136
A20: 9 - 10 | B20: ='[2]DP8 CAIHUASI S1'!B20+'[2]DP6 CAIHUASI S2'!B20 -> 65 | C20: ='[2]DP8 CAIHUASI S1'!C20+'[2]DP6 CAIHUASI S2'!C20 -> 9 | D20: ='[2]DP8 CAIHUASI S1'!D20+'[2]DP6 CAIHUASI S2'!D20 -> 35 | E20: ='[2]DP8 CAIHUASI S1'!E20+'[2]DP6 CAIHUASI S2'!E20 -> 0 | F20: ='[2]DP8 CAIHUASI S1'!F20+'[2]DP6 CAIHUASI S2'!F20 -> 0 | G20: ='[2]DP8 CAIHUASI S1'!G20+'[2]DP6 CAIHUASI S2'!G20 -> 12 | H20: ='[2]DP8 CAIHUASI S1'!H20+'[2]DP6 CAIHUASI S2'!H20 -> 2 | I20: ='[2]DP8 CAIHUASI S1'!I20+'[2]DP6 CAIHUASI S2'!I20 -> 8 | ... N20: ='[2]DP8 CAIHUASI S1'!N20+'[2]DP6 CAIHUASI S2'!N20 -> 0 | O20: =SUM(B20:N20) -> 162 | P20: =O20/$O$35 -> 0.040713747
A21: 10 - 11 | B21: ='[2]DP8 CAIHUASI S1'!B21+'[2]DP6 CAIHUASI S2'!B21 -> 67 | C21: ='[2]DP8 CAIHUASI S1'!C21+'[2]DP6 CAIHUASI S2'!C21 -> 5 | D21: ='[2]DP8 CAIHUASI S1'!D21+'[2]DP6 CAIHUASI S2'!D21 -> 29 | E21: ='[2]DP8 CAIHUASI S1'!E21+'[2]DP6 CAIHUASI S2'!E21 -> 0 | F21: ='[2]DP8 CAIHUASI S1'!F21+'[2]DP6 CAIHUASI S2'!F21 -> 5 | G21: ='[2]DP8 CAIHUASI S1'!G21+'[2]DP6 CAIHUASI S2'!G21 -> 20 | H21: ='[2]DP8 CAIHUASI S1'!H21+'[2]DP6 CAIHUASI S2'!H21 -> 1 | I21: ='[2]DP8 CAIHUASI S1'!I21+'[2]DP6 CAIHUASI S2'!I21 -> 5 | ... N21: ='[2]DP8 CAIHUASI S1'!N21+'[2]DP6 CAIHUASI S2'!N21 -> 0 | O21: =SUM(B21:N21) -> 156 | P21: =O21/$O$35 -> 0.039205831
A22: 11 - 12 | B22: ='[2]DP8 CAIHUASI S1'!B22+'[2]DP6 CAIHUASI S2'!B22 -> 84 | C22: ='[2]DP8 CAIHUASI S1'!C22+'[2]DP6 CAIHUASI S2'!C22 -> 7 | D22: ='[2]DP8 CAIHUASI S1'!D22+'[2]DP6 CAIHUASI S2'!D22 -> 32 | E22: ='[2]DP8 CAIHUASI S1'!E22+'[2]DP6 CAIHUASI S2'!E22 -> 0 | F22: ='[2]DP8 CAIHUASI S1'!F22+'[2]DP6 CAIHUASI S2'!F22 -> 6 | G22: ='[2]DP8 CAIHUASI S1'!G22+'[2]DP6 CAIHUASI S2'!G22 -> 18 | H22: ='[2]DP8 CAIHUASI S1'!H22+'[2]DP6 CAIHUASI S2'!H22 -> 3 | I22: ='[2]DP8 CAIHUASI S1'!I22+'[2]DP6 CAIHUASI S2'!I22 -> 5 | ... N22: ='[2]DP8 CAIHUASI S1'!N22+'[2]DP6 CAIHUASI S2'!N22 -> 0 | O22: =SUM(B22:N22) -> 182 | P22: =O22/$O$35 -> 0.045740136
... A34: 23 - 24 | B34: ='[2]DP8 CAIHUASI S1'!B34+'[2]DP6 CAIHUASI S2'!B34 -> 35 | C34: ='[2]DP8 CAIHUASI S1'!C34+'[2]DP6 CAIHUASI S2'!C34 -> 2 | D34: ='[2]DP8 CAIHUASI S1'!D34+'[2]DP6 CAIHUASI S2'!D34 -> 8 | E34: ='[2]DP8 CAIHUASI S1'!E34+'[2]DP6 CAIHUASI S2'!E34 -> 0 | F34: ='[2]DP8 CAIHUASI S1'!F34+'[2]DP6 CAIHUASI S2'!F34 -> 6 | G34: ='[2]DP8 CAIHUASI S1'!G34+'[2]DP6 CAIHUASI S2'!G34 -> 27 | H34: ='[2]DP8 CAIHUASI S1'!H34+'[2]DP6 CAIHUASI S2'!H34 -> 0 | I34: ='[2]DP8 CAIHUASI S1'!I34+'[2]DP6 CAIHUASI S2'!I34 -> 17 | ... N34: ='[2]DP8 CAIHUASI S1'!N34+'[2]DP6 CAIHUASI S2'!N34 -> 0 | O34: =SUM(B34:N34) -> 136 | P34: =O34/$O$35 -> 0.034179442
A35: TOTAL | B35: =SUM(B11:B34) -> 1423 | C35: =SUM(C11:C34) -> 177 | D35: =SUM(D11:D34) -> 568 | E35: =SUM(E11:E34) -> 1 | F35: =SUM(F11:F34) -> 82 | G35: =SUM(G11:G34) -> 538 | H35: =SUM(H11:H34) -> 49 | I35: =SUM(I11:I34) -> 208 | ... P35: =SUM(P11:P34) -> 1
A36: (%) | B36: =B35/$O$35 -> 0.35762754 | C36: =C35/$O$35 -> 0.044483539 | D36: =D35/$O$35 -> 0.14274943 | E36: =E35/$O$35 -> 0.00025131943 | F36: =F35/$O$35 -> 0.020608193 | G36: =G35/$O$35 -> 0.13520985 | H36: =H35/$O$35 -> 0.012314652 | I36: =I35/$O$35 -> 0.052274441 | ... N36: =N35/$O$35 -> 0 | O36: =SUM(B36:N36) -> 1

Sheet dia 3
A3: RESUMEN DE CONTEO
A4: CLASIFICACIÓN DE VEHÍCULOS
A6: CAMINO:DOBLE VIA ORURO - COCHABAMBA | J6: DEPARTAMENTO:
A7: ESTACIÓN: cAHIHUASI | F7: Nº. | G7: S/N
A8: TRAMO: 1 | J8: FECHA:
A10: HORA DE - A | B10: AUTOMÓVILES VAGONETAS Y JEEP | C10: CAMIONETAS | D10: MINIBUSES | E10: MICROBUSES (DOS EJES) | F10: BÚS MEDIANO (DOS EJES) | G10: BÚS GRANDE (DOS O MAS EJES) | H10: CAMIÓN MEDIANO (DOS EJES) | I10: CAMIÓN GRANDE ( DOS EJES) | J10: CAMION GRANDE (TRES EJES) | K10: CAMIÓN CON SEMIRREMOLQUE | L10: CAMION CON REMOLQUE | M10: MOTOCICLETAS | N10: OTROS VEHICULOS | O10: TOTAL | P10: PORCENTAJE
A11: 0 - 1 | B11: ='[3]DP8 CAIHUASI S1'!B11+'[3]DP6 CAIHUASI S2'!B11 -> 43 | C11: ='[3]DP8 CAIHUASI S1'!C11+'[3]DP6 CAIHUASI S2'!C11 -> 3 | D11: ='[3]DP8 CAIHUASI S1'!D11+'[3]DP6 CAIHUASI S2'!D11 -> 5 | E11: ='[3]DP8 CAIHUASI S1'!E11+'[3]DP6 CAIHUASI S2'!E11 -> 0 | F11: ='[3]DP8 CAIHUASI S1'!F11+'[3]DP6 CAIHUASI S2'!F11 -> 6 | G11: ='[3]DP8 CAIHUASI S1'!G11+'[3]DP6 CAIHUASI S2'!G11 -> 23 | H11: ='[3]DP8 CAIHUASI S1'!H11+'[3]DP6 CAIHUASI S2'!H11 -> 1 | I11: ='[3]DP8 CAIHUASI S1'!I11+'[3]DP6 CAIHUASI S2'!I11 -> 7 | ... N11: ='[3]DP8 CAIHUASI S1'!N11+'[3]DP6 CAIHUASI S2'!N11 -> 0 | O11: =SUM(B11:N11) -> 112 | P11: =O11/$O$35 -> 0.031764039
A12: 1 - 2 | B12: ='[3]DP8 CAIHUASI S1'!B12+'[3]DP6 CAIHUASI S2'!B12 -> 19 | C12: ='[3]DP8 CAIHUASI S1'!C12+'[3]DP6 CAIHUASI S2'!C12 -> 3 | D12: ='[3]DP8 CAIHUASI S1'!D12+'[3]DP6 CAIHUASI S2'!D12 -> 7 | E12: ='[3]DP8 CAIHUASI S1'!E12+'[3]DP6 CAIHUASI S2'!E12 -> 0 | F12: ='[3]DP8 CAIHUASI S1'!F12+'[3]DP6 CAIHUASI S2'!F12 -> 3 | G12: ='[3]DP8 CAIHUASI S1'!G12+'[3]DP6 CAIHUASI S2'!G12 -> 52 | H12: ='[3]DP8 CAIHUASI S1'!H12+'[3]DP6 CAIHUASI S2'!H12 -> 0 | I12: ='[3]DP8 CAIHUASI S1'!I12+'[3]DP6 CAIHUASI S2'!I12 -> 8 | ... N12: ='[3]DP8 CAIHUASI S1'!N12+'[3]DP6 CAIHUASI S2'!N12 -> 0 | O12: =SUM(B12:N12) -> 111 | P12: =O12/$O$35 -> 0.031480431
A13: 2 - 3 | B13: ='[3]DP8 CAIHUASI S1'!B13+'[3]DP6 CAIHUASI S2'!B13 -> 23 | C13: ='[3]DP8 CAIHUASI S1'!C13+'[3]DP6 CAIHUASI S2'!C13 -> 3 | D13: ='[3]DP8 CAIHUASI S1'!D13+'[3]DP6 CAIHUASI S2'!D13 -> 8 | E13: ='[3]DP8 CAIHUASI S1'!E13+'[3]DP6 CAIHUASI S2'!E13 -> 0 | F13: ='[3]DP8 CAIHUASI S1'!F13+'[3]DP6 CAIHUASI S2'!F13 -> 0 | G13: ='[3]DP8 CAIHUASI S1'!G13+'[3]DP6 CAIHUASI S2'!G13 -> 66 | H13: ='[3]DP8 CAIHUASI S1'!H13+'[3]DP6 CAIHUASI S2'!H13 -> 1 | I13: ='[3]DP8 CAIHUASI S1'!I13+'[3]DP6 CAIHUASI S2'!I13 -> 4 | ... N13: ='[3]DP8 CAIHUASI S1'!N13+'[3]DP6 CAIHUASI S2'!N13 -> 0 | O13: =SUM(B13:N13) -> 118 | P13: =O13/$O$35 -> 0.033465683
A14: 3 - 4 | B14: ='[3]DP8 CAIHUASI S1'!B14+'[3]DP6 CAIHUASI S2'!B14 -> 17 | C14: ='[3]DP8 CAIHUASI S1'!C14+'[3]DP6 CAIHUASI S2'!C14 -> 9 | D14: ='[3]DP8 CAIHUASI S1'!D14+'[3]DP6 CAIHUASI S2'!D14 -> 5 | E14: ='[3]DP8 CAIHUASI S1'!E14+'[3]DP6 CAIHUASI S2'!E14 -> 0 | F14: ='[3]DP8 CAIHUASI S1'!F14+'[3]DP6 CAIHUASI S2'!F14 -> 46 | G14: ='[3]DP8 CAIHUASI S1'!G14+'[3]DP6 CAIHUASI S2'!G14 -> 35 | H14: ='[3]DP8 CAIHUASI S1'!H14+'[3]DP6 CAIHUASI S2'!H14 -> 2 | I14: ='[3]DP8 CAIHUASI S1'!I14+'[3]DP6 CAIHUASI S2'!I14 -> 6 | ... N14: ='[3]DP8 CAIHUASI S1'!N14+'[3]DP6 CAIHUASI S2'!N14 -> 0 | O14: =SUM(B14:N14) -> 152 | P14: =O14/$O$35 -> 0.043108338
A15: 4 - 5 | B15: ='[3]DP8 CAIHUASI S1'!B15+'[3]DP6 CAIHUASI S2'!B15 -> 30 | C15: ='[3]DP8 CAIHUASI S1'!C15+'[3]DP6 CAIHUASI S2'!C15 -> 2 | D15: ='[3]DP8 CAIHUASI S1'!D15+'[3]DP6 CAIHUASI S2'!D15 -> 18 | E15: ='[3]DP8 CAIHUASI S1'!E15+'[3]DP6 CAIHUASI S2'!E15 -> 0 | F15: ='[3]DP8 CAIHUASI S1'!F15+'[3]DP6 CAIHUASI S2'!F15 -> 2 | G15: ='[3]DP8 CAIHUASI S1'!G15+'[3]DP6 CAIHUASI S2'!G15 -> 41 | H15: ='[3]DP8 CAIHUASI S1'!H15+'[3]DP6 CAIHUASI S2'!H15 -> 1 | I15: ='[3]DP8 CAIHUASI S1'!I15+'[3]DP6 CAIHUASI S2'!I15 -> 7 | ... N15: ='[3]DP8 CAIHUASI S1'!N15+'[3]DP6 CAIHUASI S2'!N15 -> 0 | O15: =SUM(B15:N15) -> 142 | P15: =O15/$O$35 -> 0.040272263
A16: 5 - 6 | B16: ='[3]DP8 CAIHUASI S1'!B16+'[3]DP6 CAIHUASI S2'!B16 -> 33 | C16: ='[3]DP8 CAIHUASI S1'!C16+'[3]DP6 CAIHUASI S2'!C16 -> 3 | D16: ='[3]DP8 CAIHUASI S1'!D16+'[3]DP6 CAIHUASI S2'!D16 -> 18 | E16: ='[3]DP8 CAIHUASI S1'!E16+'[3]DP6 CAIHUASI S2'!E16 -> 0 | F16: ='[3]DP8 CAIHUASI S1'!F16+'[3]DP6 CAIHUASI S2'!F16 -> 6 | G16: ='[3]DP8 CAIHUASI S1'!G16+'[3]DP6 CAIHUASI S2'!G16 -> 17 | H16: ='[3]DP8 CAIHUASI S1'!H16+'[3]DP6 CAIHUASI S2'!H16 -> 7 | I16: ='[3]DP8 CAIHUASI S1'!I16+'[3]DP6 CAIHUASI S2'!I16 -> 22 | ... N16: ='[3]DP8 CAIHUASI S1'!N16+'[3]DP6 CAIHUASI S2'!N16 -> 0 | O16: =SUM(B16:N16) -> 159 | P16: =O16/$O$35 -> 0.04509359
A17: 6 - 7 | B17: ='[3]DP8 CAIHUASI S1'!B17+'[3]DP6 CAIHUASI S2'!B17 -> 27 | C17: ='[3]DP8 CAIHUASI S1'!C17+'[3]DP6 CAIHUASI S2'!C17 -> 9 | D17: ='[3]DP8 CAIHUASI S1'!D17+'[3]DP6 CAIHUASI S2'!D17 -> 13 | E17: ='[3]DP8 CAIHUASI S1'!E17+'[3]DP6 CAIHUASI S2'!E17 -> 0 | F17: ='[3]DP8 CAIHUASI S1'!F17+'[3]DP6 CAIHUASI S2'!F17 -> 0 | G17: ='[3]DP8 CAIHUASI S1'!G17+'[3]DP6 CAIHUASI S2'!G17 -> 10 | H17: ='[3]DP8 CAIHUASI S1'!H17+'[3]DP6 CAIHUASI S2'!H17 -> 1 | I17: ='[3]DP8 CAIHUASI S1'!I17+'[3]DP6 CAIHUASI S2'!I17 -> 1 | ... N17: ='[3]DP8 CAIHUASI S1'!N17+'[3]DP6 CAIHUASI S2'!N17 -> 0 | O17: =SUM(B17:N17) -> 82 | P17: =O17/$O$35 -> 0.023255814
A18: 7 - 8 | B18: ='[3]DP8 CAIHUASI S1'!B18+'[3]DP6 CAIHUASI S2'!B18 -> 32 | C18: ='[3]DP8 CAIHUASI S1'!C18+'[3]DP6 CAIHUASI S2'!C18 -> 2 | D18: ='[3]DP8 CAIHUASI S1'!D18+'[3]DP6 CAIHUASI S2'!D18 -> 19 | E18: ='[3]DP8 CAIHUASI S1'!E18+'[3]DP6 CAIHUASI S2'!E18 -> 1 | F18: ='[3]DP8 CAIHUASI S1'!F18+'[3]DP6 CAIHUASI S2'!F18 -> 3 | G18: ='[3]DP8 CAIHUASI S1'!G18+'[3]DP6 CAIHUASI S2'!G18 -> 5 | H18: ='[3]DP8 CAIHUASI S1'!H18+'[3]DP6 CAIHUASI S2'!H18 -> 1 | I18: ='[3]DP8 CAIHUASI S1'!I18+'[3]DP6 CAIHUASI S2'!I18 -> 5 | ... N18: ='[3]DP8 CAIHUASI S1'!N18+'[3]DP6 CAIHUASI S2'!N18 -> 0 | O18: =SUM(B18:N18) -> 94 | P18: =O18/$O$35 -> 0.026659104
A19: 8 - 9 | B19: ='[3]DP8 CAIHUASI S1'!B19+'[3]DP6 CAIHUASI S2'!B19 -> 62 | C19: ='[3]DP8 CAIHUASI S1'!C19+'[3]DP6 CAIHUASI S2'!C19 -> 10 | D19: ='[3]DP8 CAIHUASI S1'!D19+'[3]DP6 CAIHUASI S2'!D19 -> 34 | E19: ='[3]DP8 CAIHUASI S1'!E19+'[3]DP6 CAIHUASI S2'!E19 -> 0 | F19: ='[3]DP8 CAIHUASI S1'!F19+'[3]DP6 CAIHUASI S2'!F19 -> 2 | G19: ='[3]DP8 CAIHUASI S1'!G19+'[3]DP6 CAIHUASI S2'!G19 -> 13 | H19: ='[3]DP8 CAIHUASI S1'!H19+'[3]DP6 CAIHUASI S2'!H19 -> 1 | I19: ='[3]DP8 CAIHUASI S1'!I19+'[3]DP6 CAIHUASI S2'!I19 -> 9 | ... N19: ='[3]DP8 CAIHUASI S1'!N19+'[3]DP6 CAIHUASI S2'!N19 -> 0 | O19: =SUM(B19:N19) -> 165 | P19: =O19/$O$35 -> 0.046795235
A20: 9 - 10 | B20: ='[3]DP8 CAIHUASI S1'!B20+'[3]DP6 CAIHUASI S2'!B20 -> 36 | C20: ='[3]DP8 CAIHUASI S1'!C20+'[3]DP6 CAIHUASI S2'!C20 -> 6 | D20: ='[3]DP8 CAIHUASI S1'!D20+'[3]DP6 CAIHUASI S2'!D20 -> 15 | E20: ='[3]DP8 CAIHUASI S1'!E20+'[3]DP6 CAIHUASI S2'!E20 -> 0 | F20: ='[3]DP8 CAIHUASI S1'!F20+'[3]DP6 CAIHUASI S2'!F20 -> 1 | G20: ='[3]DP8 CAIHUASI S1'!G20+'[3]DP6 CAIHUASI S2'!G20 -> 9 | H20: ='[3]DP8 CAIHUASI S1'!H20+'[3]DP6 CAIHUASI S2'!H20 -> 0 | I20: ='[3]DP8 CAIHUASI S1'!I20+'[3]DP6 CAIHUASI S2'!I20 -> 2 | ... N20: ='[3]DP8 CAIHUASI S1'!N20+'[3]DP6 CAIHUASI S2'!N20 -> 0 | O20: =SUM(B20:N20) -> 88 | P20: =O20/$O$35 -> 0.024957459
A21: 10 - 11 | B21: ='[3]DP8 CAIHUASI S1'!B21+'[3]DP6 CAIHUASI S2'!B21 -> 55 | C21: ='[3]DP8 CAIHUASI S1'!C21+'[3]DP6 CAIHUASI S2'!C21 -> 7 | D21: ='[3]DP8 CAIHUASI S1'!D21+'[3]DP6 CAIHUASI S2'!D21 -> 27 | E21: ='[3]DP8 CAIHUASI S1'!E21+'[3]DP6 CAIHUASI S2'!E21 -> 2 | F21: ='[3]DP8 CAIHUASI S1'!F21+'[3]DP6 CAIHUASI S2'!F21 -> 2 | G21: ='[3]DP8 CAIHUASI S1'!G21+'[3]DP6 CAIHUASI S2'!G21 -> 19 | H21: ='[3]DP8 CAIHUASI S1'!H21+'[3]DP6 CAIHUASI S2'!H21 -> 1 | I21: ='[3]DP8 CAIHUASI S1'!I21+'[3]DP6 CAIHUASI S2'!I21 -> 8 | ... N21: ='[3]DP8 CAIHUASI S1'!N21+'[3]DP6 CAIHUASI S2'!N21 -> 0 | O21: =SUM(B21:N21) -> 148 | P21: =O21/$O$35 -> 0.041973908
A22: 11 - 12 | B22: ='[3]DP8 CAIHUASI S1'!B22+'[3]DP6 CAIHUASI S2'!B22 -> 62 | C22: ='[3]DP8 CAIHUASI S1'!C22+'[3]DP6 CAIHUASI S2'!C22 -> 11 | D22: ='[3]DP8 CAIHUASI S1'!D22+'[3]DP6 CAIHUASI S2'!D22 -> 31 | E22: ='[3]DP8 CAIHUASI S1'!E22+'[3]DP6 CAIHUASI S2'!E22 -> 1 | F22: ='[3]DP8 CAIHUASI S1'!F22+'[3]DP6 CAIHUASI S2'!F22 -> 0 | G22: ='[3]DP8 CAIHUASI S1'!G22+'[3]DP6 CAIHUASI S2'!G22 -> 25 | H22: ='[3]DP8 CAIHUASI S1'!H22+'[3]DP6 CAIHUASI S2'!H22 -> 1 | I22: ='[3]DP8 CAIHUASI S1'!I22+'[3]DP6 CAIHUASI S2'!I22 -> 5 | ... N22: ='[3]DP8 CAIHUASI S1'!N22+'[3]DP6 CAIHUASI S2'!N22 -> 0 | O22: =SUM(B22:N22) -> 157 | P22: =O22/$O$35 -> 0.044526375
... A34: 23 - 24 | B34: ='[3]DP8 CAIHUASI S1'!B34+'[3]DP6 CAIHUASI S2'!B34 -> 11 | C34: ='[3]DP8 CAIHUASI S1'!C34+'[3]DP6 CAIHUASI S2'!C34 -> 2 | D34: ='[3]DP8 CAIHUASI S1'!D34+'[3]DP6 CAIHUASI S2'!D34 -> 5 | E34: ='[3]DP8 CAIHUASI S1'!E34+'[3]DP6 CAIHUASI S2'!E34 -> 0 | F34: ='[3]DP8 CAIHUASI S1'!F34+'[3]DP6 CAIHUASI S2'!F34 -> 2 | G34: ='[3]DP8 CAIHUASI S1'!G34+'[3]DP6 CAIHUASI S2'!G34 -> 3 | H34: ='[3]DP8 CAIHUASI S1'!H34+'[3]DP6 CAIHUASI S2'!H34 -> 1 | I34: ='[3]DP8 CAIHUASI S1'!I34+'[3]DP6 CAIHUASI S2'!I34 -> 3 | ... N34: ='[3]DP8 CAIHUASI S1'!N34+'[3]DP6 CAIHUASI S2'!N34 -> 0 | O34: =SUM(B34:N34) -> 46 | P34: =O34/$O$35 -> 0.013045944
A35: TOTAL | B35: =SUM(B11:B34) -> 1108 | C35: =SUM(C11:C34) -> 169 | D35: =SUM(D11:D34) -> 535 | E35: =SUM(E11:E34) -> 6 | F35: =SUM(F11:F34) -> 102 | G35: =SUM(G11:G34) -> 578 | H35: =SUM(H11:H34) -> 45 | I35: =SUM(I11:I34) -> 219 | ... P35: =SUM(P11:P34) -> 1
A36: (%) | B36: =B35/$O$35 -> 0.3142371 | C36: =C35/$O$35 -> 0.047929665 | D36: =D35/$O$35 -> 0.15173001 | E36: =E35/$O$35 -> 0.0017016449 | F36: =F35/$O$35 -> 0.028927964 | G36: =G35/$O$35 -> 0.16392513 | H36: =H35/$O$35 -> 0.012762337 | I36: =I35/$O$35 -> 0.06211004 | ... N36: =N35/$O$35 -> 0 | O36: =SUM(B36:N36) -> 1

Sheet dia 4
A3: RESUMEN DE CONTEO
A4: CLASIFICACIÓN DE VEHÍCULOS
A6: CAMINO:DOBLE VIA ORURO - COCHABAMBA | J6: DEPARTAMENTO:
A7: ESTACIÓN: Villapata | F7: Nº. | G7: S/N
A8: TRAMO: 1 | J8: FECHA:
A10: HORA DE - A | B10: AUTOMÓVILES VAGONETAS Y JEEP | C10: CAMIONETAS | D10: MINIBUSES | E10: MICROBUSES (DOS EJES) | F10: BÚS MEDIANO (DOS EJES) | G10: BÚS GRANDE (DOS O MAS EJES) | H10: CAMIÓN MEDIANO (DOS EJES) | I10: CAMIÓN GRANDE ( DOS EJES) | J10: CAMION GRANDE (TRES EJES) | K10: CAMIÓN CON SEMIRREMOLQUE | L10: CAMION CON REMOLQUE | M10: MOTOCICLETAS | N10: OTROS VEHICULOS | O10: TOTAL | P10: PORCENTAJE
A11: 0 - 1 | B11: ='[4]DP8 CAIHUASI S1'!B11+'[4]DP6 CAIHUASI S2'!B11 -> 15 | C11: ='[4]DP8 CAIHUASI S1'!C11+'[4]DP6 CAIHUASI S2'!C11 -> 0 | D11: ='[4]DP8 CAIHUASI S1'!D11+'[4]DP6 CAIHUASI S2'!D11 -> 6 | E11: ='[4]DP8 CAIHUASI S1'!E11+'[4]DP6 CAIHUASI S2'!E11 -> 0 | F11: ='[4]DP8 CAIHUASI S1'!F11+'[4]DP6 CAIHUASI S2'!F11 -> 5 | G11: ='[4]DP8 CAIHUASI S1'!G11+'[4]DP6 CAIHUASI S2'!G11 -> 24 | H11: ='[4]DP8 CAIHUASI S1'!H11+'[4]DP6 CAIHUASI S2'!H11 -> 1 | I11: ='[4]DP8 CAIHUASI S1'!I11+'[4]DP6 CAIHUASI S2'!I11 -> 13 | ... N11: ='[4]DP8 CAIHUASI S1'!N11+'[4]DP6 CAIHUASI S2'!N11 -> 0 | O11: =SUM(B11:N11) -> 109 | P11: =O11/$O$35 -> 0.034051859
A12: 1 - 2 | B12: ='[4]DP8 CAIHUASI S1'!B12+'[4]DP6 CAIHUASI S2'!B12 -> 11 | C12: ='[4]DP8 CAIHUASI S1'!C12+'[4]DP6 CAIHUASI S2'!C12 -> 4 | D12: ='[4]DP8 CAIHUASI S1'!D12+'[4]DP6 CAIHUASI S2'!D12 -> 4 | E12: ='[4]DP8 CAIHUASI S1'!E12+'[4]DP6 CAIHUASI S2'!E12 -> 0 | F12: ='[4]DP8 CAIHUASI S1'!F12+'[4]DP6 CAIHUASI S2'!F12 -> 7 | G12: ='[4]DP8 CAIHUASI S1'!G12+'[4]DP6 CAIHUASI S2'!G12 -> 41 | H12: ='[4]DP8 CAIHUASI S1'!H12+'[4]DP6 CAIHUASI S2'!H12 -> 1 | I12: ='[4]DP8 CAIHUASI S1'!I12+'[4]DP6 CAIHUASI S2'!I12 -> 8 | ... N12: ='[4]DP8 CAIHUASI S1'!N12+'[4]DP6 CAIHUASI S2'!N12 -> 0 | O12: =SUM(B12:N12) -> 108 | P12: =O12/$O$35 -> 0.033739456
A13: 2 - 3 | B13: ='[4]DP8 CAIHUASI S1'!B13+'[4]DP6 CAIHUASI S2'!B13 -> 20 | C13: ='[4]DP8 CAIHUASI S1'!C13+'[4]DP6 CAIHUASI S2'!C13 -> 0 | D13: ='[4]DP8 CAIHUASI S1'!D13+'[4]DP6 CAIHUASI S2'!D13 -> 8 | E13: ='[4]DP8 CAIHUASI S1'!E13+'[4]DP6 CAIHUASI S2'!E13 -> 0 | F13: ='[4]DP8 CAIHUASI S1'!F13+'[4]DP6 CAIHUASI S2'!F13 -> 0 | G13: ='[4]DP8 CAIHUASI S1'!G13+'[4]DP6 CAIHUASI S2'!G13 -> 72 | H13: ='[4]DP8 CAIHUASI S1'!H13+'[4]DP6 CAIHUASI S2'!H13 -> 1 | I13: ='[4]DP8 CAIHUASI S1'!I13+'[4]DP6 CAIHUASI S2'!I13 -> 13 | ... N13: ='[4]DP8 CAIHUASI S1'!N13+'[4]DP6 CAIHUASI S2'!N13 -> 0 | O13: =SUM(B13:N13) -> 143 | P13: =O13/$O$35 -> 0.04467354
A14: 3 - 4 | B14: ='[4]DP8 CAIHUASI S1'!B14+'[4]DP6 CAIHUASI S2'!B14 -> 17 | C14: ='[4]DP8 CAIHUASI S1'!C14+'[4]DP6 CAIHUASI S2'!C14 -> 1 | D14: ='[4]DP8 CAIHUASI S1'!D14+'[4]DP6 CAIHUASI S2'!D14 -> 1 | E14: ='[4]DP8 CAIHUASI S1'!E14+'[4]DP6 CAIHUASI S2'!E14 -> 0 | F14: ='[4]DP8 CAIHUASI S1'!F14+'[4]DP6 CAIHUASI S2'!F14 -> 0 | G14: ='[4]DP8 CAIHUASI S1'!G14+'[4]DP6 CAIHUASI S2'!G14 -> 17 | H14: ='[4]DP8 CAIHUASI S1'!H14+'[4]DP6 CAIHUASI S2'!H14 -> 0 | I14: ='[4]DP8 CAIHUASI S1'!I14+'[4]DP6 CAIHUASI S2'!I14 -> 1 | ... N14: ='[4]DP8 CAIHUASI S1'!N14+'[4]DP6 CAIHUASI S2'!N14 -> 0 | O14: =SUM(B14:N14) -> 63 | P14: =O14/$O$35 -> 0.01968135
A15: 4 - 5 | B15: ='[4]DP8 CAIHUASI S1'!B15+'[4]DP6 CAIHUASI S2'!B15 -> 12 | C15: ='[4]DP8 CAIHUASI S1'!C15+'[4]DP6 CAIHUASI S2'!C15 -> 1 | D15: ='[4]DP8 CAIHUASI S1'!D15+'[4]DP6 CAIHUASI S2'!D15 -> 3 | E15: ='[4]DP8 CAIHUASI S1'!E15+'[4]DP6 CAIHUASI S2'!E15 -> 0 | F15: ='[4]DP8 CAIHUASI S1'!F15+'[4]DP6 CAIHUASI S2'!F15 -> 0 | G15: ='[4]DP8 CAIHUASI S1'!G15+'[4]DP6 CAIHUASI S2'!G15 -> 16 | H15: ='[4]DP8 CAIHUASI S1'!H15+'[4]DP6 CAIHUASI S2'!H15 -> 0 | I15: ='[4]DP8 CAIHUASI S1'!I15+'[4]DP6 CAIHUASI S2'!I15 -> 2 | ... N15: ='[4]DP8 CAIHUASI S1'!N15+'[4]DP6 CAIHUASI S2'!N15 -> 0 | O15: =SUM(B15:N15) -> 60 | P15: =O15/$O$35 -> 0.018744142
A16: 5 - 6 | B16: ='[4]DP8 CAIHUASI S1'!B16+'[4]DP6 CAIHUASI S2'!B16 -> 18 | C16: ='[4]DP8 CAIHUASI S1'!C16+'[4]DP6 CAIHUASI S2'!C16 -> 1 | D16: ='[4]DP8 CAIHUASI S1'!D16+'[4]DP6 CAIHUASI S2'!D16 -> 7 | E16: ='[4]DP8 CAIHUASI S1'!E16+'[4]DP6 CAIHUASI S2'!E16 -> 0 | F16: ='[4]DP8 CAIHUASI S1'!F16+'[4]DP6 CAIHUASI S2'!F16 -> 0 | G16: ='[4]DP8 CAIHUASI S1'!G16+'[4]DP6 CAIHUASI S2'!G16 -> 6 | H16: ='[4]DP8 CAIHUASI S1'!H16+'[4]DP6 CAIHUASI S2'!H16 -> 0 | I16: ='[4]DP8 CAIHUASI S1'!I16+'[4]DP6 CAIHUASI S2'!I16 -> 10 | ... N16: ='[4]DP8 CAIHUASI S1'!N16+'[4]DP6 CAIHUASI S2'!N16 -> 0 | O16: =SUM(B16:N16) -> 66 | P16: =O16/$O$35 -> 0.020618557
A17: 6 - 7 | B17: ='[4]DP8 CAIHUASI S1'!B17+'[4]DP6 CAIHUASI S2'!B17 -> 27 | C17: ='[4]DP8 CAIHUASI S1'!C17+'[4]DP6 CAIHUASI S2'!C17 -> 3 | D17: ='[4]DP8 CAIHUASI S1'!D17+'[4]DP6 CAIHUASI S2'!D17 -> 26 | E17: ='[4]DP8 CAIHUASI S1'!E17+'[4]DP6 CAIHUASI S2'!E17 -> 0 | F17: ='[4]DP8 CAIHUASI S1'!F17+'[4]DP6 CAIHUASI S2'!F17 -> 2 | G17: ='[4]DP8 CAIHUASI S1'!G17+'[4]DP6 CAIHUASI S2'!G17 -> 10 | H17: ='[4]DP8 CAIHUASI S1'!H17+'[4]DP6 CAIHUASI S2'!H17 -> 0 | I17: ='[4]DP8 CAIHUASI S1'!I17+'[4]DP6 CAIHUASI S2'!I17 -> 6 | ... N17: ='[4]DP8 CAIHUASI S1'!N17+'[4]DP6 CAIHUASI S2'!N17 -> 0 | O17: =SUM(B17:N17) -> 114 | P17: =O17/$O$35 -> 0.035613871
A18: 7 - 8 | B18: ='[4]DP8 CAIHUASI S1'!B18+'[4]DP6 CAIHUASI S2'!B18 -> 32 | C18: ='[4]DP8 CAIHUASI S1'!C18+'[4]DP6 CAIHUASI S2'!C18 -> 9 | D18: ='[4]DP8 CAIHUASI S1'!D18+'[4]DP6 CAIHUASI S2'!D18 -> 30 | E18: ='[4]DP8 CAIHUASI S1'!E18+'[4]DP6 CAIHUASI S2'!E18 -> 0 | F18: ='[4]DP8 CAIHUASI S1'!F18+'[4]DP6 CAIHUASI S2'!F18 -> 3 | G18: ='[4]DP8 CAIHUASI S1'!G18+'[4]DP6 CAIHUASI S2'!G18 -> 9 | H18: ='[4]DP8 CAIHUASI S1'!H18+'[4]DP6 CAIHUASI S2'!H18 -> 1 | I18: ='[4]DP8 CAIHUASI S1'!I18+'[4]DP6 CAIHUASI S2'!I18 -> 11 | ... N18: ='[4]DP8 CAIHUASI S1'!N18+'[4]DP6 CAIHUASI S2'!N18 -> 0 | O18: =SUM(B18:N18) -> 122 | P18: =O18/$O$35 -> 0.03811309
A19: 8 - 9 | B19: ='[4]DP8 CAIHUASI S1'!B19+'[4]DP6 CAIHUASI S2'!B19 -> 31 | C19: ='[4]DP8 CAIHUASI S1'!C19+'[4]DP6 CAIHUASI S2'!C19 -> 9 | D19: ='[4]DP8 CAIHUASI S1'!D19+'[4]DP6 CAIHUASI S2'!D19 -> 23 | E19: ='[4]DP8 CAIHUASI S1'!E19+'[4]DP6 CAIHUASI S2'!E19 -> 0 | F19: ='[4]DP8 CAIHUASI S1'!F19+'[4]DP6 CAIHUASI S2'!F19 -> 3 | G19: ='[4]DP8 CAIHUASI S1'!G19+'[4]DP6 CAIHUASI S2'!G19 -> 11 | H19: ='[4]DP8 CAIHUASI S1'!H19+'[4]DP6 CAIHUASI S2'!H19 -> 2 | I19: ='[4]DP8 CAIHUASI S1'!I19+'[4]DP6 CAIHUASI S2'!I19 -> 5 | ... N19: ='[4]DP8 CAIHUASI S1'!N19+'[4]DP6 CAIHUASI S2'!N19 -> 0 | O19: =SUM(B19:N19) -> 100 | P19: =O19/$O$35 -> 0.031240237
A20: 9 - 10 | B20: ='[4]DP8 CAIHUASI S1'!B20+'[4]DP6 CAIHUASI S2'!B20 -> 55 | C20: ='[4]DP8 CAIHUASI S1'!C20+'[4]DP6 CAIHUASI S2'!C20 -> 12 | D20: ='[4]DP8 CAIHUASI S1'!D20+'[4]DP6 CAIHUASI S2'!D20 -> 38 | E20: ='[4]DP8 CAIHUASI S1'!E20+'[4]DP6 CAIHUASI S2'!E20 -> 0 | F20: ='[4]DP8 CAIHUASI S1'!F20+'[4]DP6 CAIHUASI S2'!F20 -> 2 | G20: ='[4]DP8 CAIHUASI S1'!G20+'[4]DP6 CAIHUASI S2'!G20 -> 17 | H20: ='[4]DP8 CAIHUASI S1'!H20+'[4]DP6 CAIHUASI S2'!H20 -> 2 | I20: ='[4]DP8 CAIHUASI S1'!I20+'[4]DP6 CAIHUASI S2'!I20 -> 4 | ... N20: ='[4]DP8 CAIHUASI S1'!N20+'[4]DP6 CAIHUASI S2'!N20 -> 0 | O20: =SUM(B20:N20) -> 159 | P20: =O20/$O$35 -> 0.049671978
A21: 10 - 11 | B21: ='[4]DP8 CAIHUASI S1'!B21+'[4]DP6 CAIHUASI S2'!B21 -> 32 | C21: ='[4]DP8 CAIHUASI S1'!C21+'[4]DP6 CAIHUASI S2'!C21 -> 10 | D21: ='[4]DP8 CAIHUASI S1'!D21+'[4]DP6 CAIHUASI S2'!D21 -> 34 | E21: ='[4]DP8 CAIHUASI S1'!E21+'[4]DP6 CAIHUASI S2'!E21 -> 0 | F21: ='[4]DP8 CAIHUASI S1'!F21+'[4]DP6 CAIHUASI S2'!F21 -> 1 | G21: ='[4]DP8 CAIHUASI S1'!G21+'[4]DP6 CAIHUASI S2'!G21 -> 13 | H21: ='[4]DP8 CAIHUASI S1'!H21+'[4]DP6 CAIHUASI S2'!H21 -> 2 | I21: ='[4]DP8 CAIHUASI S1'!I21+'[4]DP6 CAIHUASI S2'!I21 -> 8 | ... N21: ='[4]DP8 CAIHUASI S1'!N21+'[4]DP6 CAIHUASI S2'!N21 -> 0 | O21: =SUM(B21:N21) -> 120 | P21: =O21/$O$35 -> 0.037488285
A22: 11 - 12 | B22: ='[4]DP8 CAIHUASI S1'!B22+'[4]DP6 CAIHUASI S2'!B22 -> 36 | C22: ='[4]DP8 CAIHUASI S1'!C22+'[4]DP6 CAIHUASI S2'!C22 -> 10 | D22: ='[4]DP8 CAIHUASI S1'!D22+'[4]DP6 CAIHUASI S2'!D22 -> 30 | E22: ='[4]DP8 CAIHUASI S1'!E22+'[4]DP6 CAIHUASI S2'!E22 -> 0 | F22: ='[4]DP8 CAIHUASI S1'!F22+'[4]DP6 CAIHUASI S2'!F22 -> 5 | G22: ='[4]DP8 CAIHUASI S1'!G22+'[4]DP6 CAIHUASI S2'!G22 -> 17 | H22: ='[4]DP8 CAIHUASI S1'!H22+'[4]DP6 CAIHUASI S2'!H22 -> 2 | I22: ='[4]DP8 CAIHUASI S1'!I22+'[4]DP6 CAIHUASI S2'!I22 -> 3 | ... N22: ='[4]DP8 CAIHUASI S1'!N22+'[4]DP6 CAIHUASI S2'!N22 -> 0 | O22: =SUM(B22:N22) -> 123 | P22: =O22/$O$35 -> 0.038425492
... A34: 23 - 24 | B34: ='[4]DP8 CAIHUASI S1'!B34+'[4]DP6 CAIHUASI S2'!B34 -> 31 | C34: ='[4]DP8 CAIHUASI S1'!C34+'[4]DP6 CAIHUASI S2'!C34 -> 4 | D34: ='[4]DP8 CAIHUASI S1'!D34+'[4]DP6 CAIHUASI S2'!D34 -> 11 | E34: ='[4]DP8 CAIHUASI S1'!E34+'[4]DP6 CAIHUASI S2'!E34 -> 1 | F34: ='[4]DP8 CAIHUASI S1'!F34+'[4]DP6 CAIHUASI S2'!F34 -> 11 | G34: ='[4]DP8 CAIHUASI S1'!G34+'[4]DP6 CAIHUASI S2'!G34 -> 35 | H34: ='[4]DP8 CAIHUASI S1'!H34+'[4]DP6 CAIHUASI S2'!H34 -> 1 | I34: ='[4]DP8 CAIHUASI S1'!I34+'[4]DP6 CAIHUASI S2'!I34 -> 15 | ... N34: ='[4]DP8 CAIHUASI S1'!N34+'[4]DP6 CAIHUASI S2'!N34 -> 0 | O34: =SUM(B34:N34) -> 176 | P34: =O34/$O$35 -> 0.054982818
A35: TOTAL | B35: =SUM(B11:B34) -> 779 | C35: =SUM(C11:C34) -> 140 | D35: =SUM(D11:D34) -> 499 | E35: =SUM(E11:E34) -> 2 | F35: =SUM(F11:F34) -> 67 | G35: =SUM(G11:G34) -> 527 | H35: =SUM(H11:H34) -> 37 | I35: =SUM(I11:I34) -> 241 | ... P35: =SUM(P11:P34) -> 1
A36: (%) | B36: =B35/$O$35 -> 0.24336145 | C36: =C35/$O$35 -> 0.043736332 | D36: =D35/$O$35 -> 0.15588878 | E36: =E35/$O$35 -> 0.00062480475 | F36: =F35/$O$35 -> 0.020930959 | G36: =G35/$O$35 -> 0.16463605 | H36: =H35/$O$35 -> 0.011558888 | I36: =I35/$O$35 -> 0.075288972 | ... N36: =N35/$O$35 -> 0 | O36: =SUM(B36:N36) -> 1

Sheet dia 5
A3: RESUMEN DE CONTEO | S3: Tramo Okinawa - Los Troncos
A4: CLASIFICACIÓN DE VEHÍCULOS
A6: CAMINO:DOBLE VIA ORURO - COCHABAMBA | J6: DEPARTAMENTO:
A7: ESTACIÓN: Villapata | F7: Nº. | G7: S/N
A8: TRAMO: 1 | J8: FECHA:
A10: HORA DE - A | B10: AUTOMÓVILES VAGONETAS Y JEEP | C10: CAMIONETAS | D10: MINIBUSES | E10: MICROBUSES (DOS EJES) | F10: BÚS MEDIANO (DOS EJES) | G10: BÚS GRANDE (DOS O MAS EJES) | H10: CAMIÓN MEDIANO (DOS EJES) | I10: CAMIÓN GRANDE ( DOS EJES) | J10: CAMION GRANDE (TRES EJES) | K10: CAMIÓN CON SEMIRREMOLQUE | L10: CAMION CON REMOLQUE | M10: MOTOCICLETAS | N10: OTROS VEHICULOS | O10: TOTAL | P10: PORCENTAJE
A11: 0 - 1 | B11: ='[5]DP8 CAIHUASI S1'!B11+'[5]DP6 CAIHUASI S2'!B11 -> 13 | C11: ='[5]DP8 CAIHUASI S1'!C11+'[5]DP6 CAIHUASI S2'!C11 -> 4 | D11: ='[5]DP8 CAIHUASI S1'!D11+'[5]DP6 CAIHUASI S2'!D11 -> 2 | E11: ='[5]DP8 CAIHUASI S1'!E11+'[5]DP6 CAIHUASI S2'!E11 -> 0 | F11: ='[5]DP8 CAIHUASI S1'!F11+'[5]DP6 CAIHUASI S2'!F11 -> 4 | G11: ='[5]DP8 CAIHUASI S1'!G11+'[5]DP6 CAIHUASI S2'!G11 -> 62 | H11: ='[5]DP8 CAIHUASI S1'!H11+'[5]DP6 CAIHUASI S2'!H11 -> 3 | I11: ='[5]DP8 CAIHUASI S1'!I11+'[5]DP6 CAIHUASI S2'!I11 -> 15 | ... N11: ='[5]DP8 CAIHUASI S1'!N11+'[5]DP6 CAIHUASI S2'!N11 -> 0 | O11: =SUM(B11:N11) -> 141 | P11: =O11/$O$35 -> 0.037630104
A12: 1 - 2 | B12: ='[5]DP8 CAIHUASI S1'!B12+'[5]DP6 CAIHUASI S2'!B12 -> 11 | C12: ='[5]DP8 CAIHUASI S1'!C12+'[5]DP6 CAIHUASI S2'!C12 -> 3 | D12: ='[5]DP8 CAIHUASI S1'!D12+'[5]DP6 CAIHUASI S2'!D12 -> 12 | E12: ='[5]DP8 CAIHUASI S1'!E12+'[5]DP6 CAIHUASI S2'!E12 -> 0 | F12: ='[5]DP8 CAIHUASI S1'!F12+'[5]DP6 CAIHUASI S2'!F12 -> 4 | G12: ='[5]DP8 CAIHUASI S1'!G12+'[5]DP6 CAIHUASI S2'!G12 -> 48 | H12: ='[5]DP8 CAIHUASI S1'!H12+'[5]DP6 CAIHUASI S2'!H12 -> 6 | I12: ='[5]DP8 CAIHUASI S1'!I12+'[5]DP6 CAIHUASI S2'!I12 -> 14 | ... N12: ='[5]DP8 CAIHUASI S1'!N12+'[5]DP6 CAIHUASI S2'!N12 -> 0 | O12: =SUM(B12:N12) -> 163 | P12: =O12/$O$35 -> 0.043501468
A13: 2 - 3 | B13: ='[5]DP8 CAIHUASI S1'!B13+'[5]DP6 CAIHUASI S2'!B13 -> 14 | C13: ='[5]DP8 CAIHUASI S1'!C13+'[5]DP6 CAIHUASI S2'!C13 -> 2 | D13: ='[5]DP8 CAIHUASI S1'!D13+'[5]DP6 CAIHUASI S2'!D13 -> 5 | E13: ='[5]DP8 CAIHUASI S1'!E13+'[5]DP6 CAIHUASI S2'!E13 -> 0 | F13: ='[5]DP8 CAIHUASI S1'!F13+'[5]DP6 CAIHUASI S2'!F13 -> 3 | G13: ='[5]DP8 CAIHUASI S1'!G13+'[5]DP6 CAIHUASI S2'!G13 -> 40 | H13: ='[5]DP8 CAIHUASI S1'!H13+'[5]DP6 CAIHUASI S2'!H13 -> 3 | I13: ='[5]DP8 CAIHUASI S1'!I13+'[5]DP6 CAIHUASI S2'!I13 -> 7 | ... N13: ='[5]DP8 CAIHUASI S1'!N13+'[5]DP6 CAIHUASI S2'!N13 -> 0 | O13: =SUM(B13:N13) -> 96 | P13: =O13/$O$35 -> 0.025620496
A14: 3 - 4 | B14: ='[5]DP8 CAIHUASI S1'!B14+'[5]DP6 CAIHUASI S2'!B14 -> 25 | C14: ='[5]DP8 CAIHUASI S1'!C14+'[5]DP6 CAIHUASI S2'!C14 -> 5 | D14: ='[5]DP8 CAIHUASI S1'!D14+'[5]DP6 CAIHUASI S2'!D14 -> 8 | E14: ='[5]DP8 CAIHUASI S1'!E14+'[5]DP6 CAIHUASI S2'!E14 -> 0 | F14: ='[5]DP8 CAIHUASI S1'!F14+'[5]DP6 CAIHUASI S2'!F14 -> 1 | G14: ='[5]DP8 CAIHUASI S1'!G14+'[5]DP6 CAIHUASI S2'!G14 -> 50 | H14: ='[5]DP8 CAIHUASI S1'!H14+'[5]DP6 CAIHUASI S2'!H14 -> 0 | I14: ='[5]DP8 CAIHUASI S1'!I14+'[5]DP6 CAIHUASI S2'!I14 -> 11 | ... N14: ='[5]DP8 CAIHUASI S1'!N14+'[5]DP6 CAIHUASI S2'!N14 -> 0 | O14: =SUM(B14:N14) -> 133 | P14: =O14/$O$35 -> 0.035495063
A15: 4 - 5 | B15: ='[5]DP8 CAIHUASI S1'!B15+'[5]DP6 CAIHUASI S2'!B15 -> 7 | C15: ='[5]DP8 CAIHUASI S1'!C15+'[5]DP6 CAIHUASI S2'!C15 -> 2 | D15: ='[5]DP8 CAIHUASI S1'!D15+'[5]DP6 CAIHUASI S2'!D15 -> 2 | E15: ='[5]DP8 CAIHUASI S1'!E15+'[5]DP6 CAIHUASI S2'!E15 -> 0 | F15: ='[5]DP8 CAIHUASI S1'!F15+'[5]DP6 CAIHUASI S2'!F15 -> 0 | G15: ='[5]DP8 CAIHUASI S1'!G15+'[5]DP6 CAIHUASI S2'!G15 -> 15 | H15: ='[5]DP8 CAIHUASI S1'!H15+'[5]DP6 CAIHUASI S2'!H15 -> 2 | I15: ='[5]DP8 CAIHUASI S1'!I15+'[5]DP6 CAIHUASI S2'!I15 -> 8 | ... N15: ='[5]DP8 CAIHUASI S1'!N15+'[5]DP6 CAIHUASI S2'!N15 -> 0 | O15: =SUM(B15:N15) -> 66 | P15: =O15/$O$35 -> 0.017614091
A16: 5 - 6 | B16: ='[5]DP8 CAIHUASI S1'!B16+'[5]DP6 CAIHUASI S2'!B16 -> 19 | C16: ='[5]DP8 CAIHUASI S1'!C16+'[5]DP6 CAIHUASI S2'!C16 -> 3 | D16: ='[5]DP8 CAIHUASI S1'!D16+'[5]DP6 CAIHUASI S2'!D16 -> 11 | E16: ='[5]DP8 CAIHUASI S1'!E16+'[5]DP6 CAIHUASI S2'!E16 -> 0 | F16: ='[5]DP8 CAIHUASI S1'!F16+'[5]DP6 CAIHUASI S2'!F16 -> 3 | G16: ='[5]DP8 CAIHUASI S1'!G16+'[5]DP6 CAIHUASI S2'!G16 -> 23 | H16: ='[5]DP8 CAIHUASI S1'!H16+'[5]DP6 CAIHUASI S2'!H16 -> 2 | I16: ='[5]DP8 CAIHUASI S1'!I16+'[5]DP6 CAIHUASI S2'!I16 -> 6 | ... N16: ='[5]DP8 CAIHUASI S1'!N16+'[5]DP6 CAIHUASI S2'!N16 -> 0 | O16: =SUM(B16:N16) -> 92 | P16: =O16/$O$35 -> 0.024552976
A17: 6 - 7 | B17: ='[5]DP8 CAIHUASI S1'!B17+'[5]DP6 CAIHUASI S2'!B17 -> 27 | C17: ='[5]DP8 CAIHUASI S1'!C17+'[5]DP6 CAIHUASI S2'!C17 -> 5 | D17: ='[5]DP8 CAIHUASI S1'!D17+'[5]DP6 CAIHUASI S2'!D17 -> 22 | E17: ='[5]DP8 CAIHUASI S1'!E17+'[5]DP6 CAIHUASI S2'!E17 -> 0 | F17: ='[5]DP8 CAIHUASI S1'!F17+'[5]DP6 CAIHUASI S2'!F17 -> 1 | G17: ='[5]DP8 CAIHUASI S1'!G17+'[5]DP6 CAIHUASI S2'!G17 -> 15 | H17: ='[5]DP8 CAIHUASI S1'!H17+'[5]DP6 CAIHUASI S2'!H17 -> 2 | I17: ='[5]DP8 CAIHUASI S1'!I17+'[5]DP6 CAIHUASI S2'!I17 -> 7 | ... N17: ='[5]DP8 CAIHUASI S1'!N17+'[5]DP6 CAIHUASI S2'!N17 -> 0 | O17: =SUM(B17:N17) -> 130 | P17: =O17/$O$35 -> 0.034694422
A18: 7 - 8 | B18: ='[5]DP8 CAIHUASI S1'!B18+'[5]DP6 CAIHUASI S2'!B18 -> 51 | C18: ='[5]DP8 CAIHUASI S1'!C18+'[5]DP6 CAIHUASI S2'!C18 -> 7 | D18: ='[5]DP8 CAIHUASI S1'!D18+'[5]DP6 CAIHUASI S2'!D18 -> 21 | E18: ='[5]DP8 CAIHUASI S1'!E18+'[5]DP6 CAIHUASI S2'!E18 -> 0 | F18: ='[5]DP8 CAIHUASI S1'!F18+'[5]DP6 CAIHUASI S2'!F18 -> 3 | G18: ='[5]DP8 CAIHUASI S1'!G18+'[5]DP6 CAIHUASI S2'!G18 -> 6 | H18: ='[5]DP8 CAIHUASI S1'!H18+'[5]DP6 CAIHUASI S2'!H18 -> 5 | I18: ='[5]DP8 CAIHUASI S1'!I18+'[5]DP6 CAIHUASI S2'!I18 -> 9 | ... N18: ='[5]DP8 CAIHUASI S1'!N18+'[5]DP6 CAIHUASI S2'!N18 -> 0 | O18: =SUM(B18:N18) -> 145 | P18: =O18/$O$35 -> 0.038697625
A19: 8 - 9 | B19: ='[5]DP8 CAIHUASI S1'!B19+'[5]DP6 CAIHUASI S2'!B19 -> 55 | C19: ='[5]DP8 CAIHUASI S1'!C19+'[5]DP6 CAIHUASI S2'!C19 -> 11 | D19: ='[5]DP8 CAIHUASI S1'!D19+'[5]DP6 CAIHUASI S2'!D19 -> 24 | E19: ='[5]DP8 CAIHUASI S1'!E19+'[5]DP6 CAIHUASI S2'!E19 -> 0 | F19: ='[5]DP8 CAIHUASI S1'!F19+'[5]DP6 CAIHUASI S2'!F19 -> 2 | G19: ='[5]DP8 CAIHUASI S1'!G19+'[5]DP6 CAIHUASI S2'!G19 -> 9 | H19: ='[5]DP8 CAIHUASI S1'!H19+'[5]DP6 CAIHUASI S2'!H19 -> 0 | I19: ='[5]DP8 CAIHUASI S1'!I19+'[5]DP6 CAIHUASI S2'!I19 -> 9 | ... N19: ='[5]DP8 CAIHUASI S1'!N19+'[5]DP6 CAIHUASI S2'!N19 -> 0 | O19: =SUM(B19:N19) -> 156 | P19: =O19/$O$35 -> 0.041633307
A20: 9 - 10 | B20: ='[5]DP8 CAIHUASI S1'!B20+'[5]DP6 CAIHUASI S2'!B20 -> 24 | C20: ='[5]DP8 CAIHUASI S1'!C20+'[5]DP6 CAIHUASI S2'!C20 -> 7 | D20: ='[5]DP8 CAIHUASI S1'!D20+'[5]DP6 CAIHUASI S2'!D20 -> 14 | E20: ='[5]DP8 CAIHUASI S1'!E20+'[5]DP6 CAIHUASI S2'!E20 -> 0 | F20: ='[5]DP8 CAIHUASI S1'!F20+'[5]DP6 CAIHUASI S2'!F20 -> 5 | G20: ='[5]DP8 CAIHUASI S1'!G20+'[5]DP6 CAIHUASI S2'!G20 -> 24 | H20: ='[5]DP8 CAIHUASI S1'!H20+'[5]DP6 CAIHUASI S2'!H20 -> 6 | I20: ='[5]DP8 CAIHUASI S1'!I20+'[5]DP6 CAIHUASI S2'!I20 -> 7 | ... N20: ='[5]DP8 CAIHUASI S1'!N20+'[5]DP6 CAIHUASI S2'!N20 -> 0 | O20: =SUM(B20:N20) -> 130 | P20: =O20/$O$35 -> 0.034694422
A21: 10 - 11 | B21: ='[5]DP8 CAIHUASI S1'!B21+'[5]DP6 CAIHUASI S2'!B21 -> 51 | C21: ='[5]DP8 CAIHUASI S1'!C21+'[5]DP6 CAIHUASI S2'!C21 -> 25 | D21: ='[5]DP8 CAIHUASI S1'!D21+'[5]DP6 CAIHUASI S2'!D21 -> 32 | E21: ='[5]DP8 CAIHUASI S1'!E21+'[5]DP6 CAIHUASI S2'!E21 -> 0 | F21: ='[5]DP8 CAIHUASI S1'!F21+'[5]DP6 CAIHUASI S2'!F21 -> 10 | G21: ='[5]DP8 CAIHUASI S1'!G21+'[5]DP6 CAIHUASI S2'!G21 -> 34 | H21: ='[5]DP8 CAIHUASI S1'!H21+'[5]DP6 CAIHUASI S2'!H21 -> 0 | I21: ='[5]DP8 CAIHUASI S1'!I21+'[5]DP6 CAIHUASI S2'!I21 -> 20 | ... N21: ='[5]DP8 CAIHUASI S1'!N21+'[5]DP6 CAIHUASI S2'!N21 -> 0 | O21: =SUM(B21:N21) -> 247 | P21: =O21/$O$35 -> 0.065919402
A22: 11 - 12 | B22: ='[5]DP8 CAIHUASI S1'!B22+'[5]DP6 CAIHUASI S2'!B22 -> 42 | C22: ='[5]DP8 CAIHUASI S1'!C22+'[5]DP6 CAIHUASI S2'!C22 -> 13 | D22: ='[5]DP8 CAIHUASI S1'!D22+'[5]DP6 CAIHUASI S2'!D22 -> 28 | E22: ='[5]DP8 CAIHUASI S1'!E22+'[5]DP6 CAIHUASI S2'!E22 -> 0 | F22: ='[5]DP8 CAIHUASI S1'!F22+'[5]DP6 CAIHUASI S2'!F22 -> 0 | G22: ='[5]DP8 CAIHUASI S1'!G22+'[5]DP6 CAIHUASI S2'!G22 -> 22 | H22: ='[5]DP8 CAIHUASI S1'!H22+'[5]DP6 CAIHUASI S2'!H22 -> 1 | I22: ='[5]DP8 CAIHUASI S1'!I22+'[5]DP6 CAIHUASI S2'!I22 -> 8 | ... N22: ='[5]DP8 CAIHUASI S1'!N22+'[5]DP6 CAIHUASI S2'!N22 -> 0 | O22: =SUM(B22:N22) -> 143 | P22: =O22/$O$35 -> 0.038163864
... A34: 23 - 24 | B34: ='[5]DP8 CAIHUASI S1'!B34+'[5]DP6 CAIHUASI S2'!B34 -> 16 | C34: ='[5]DP8 CAIHUASI S1'!C34+'[5]DP6 CAIHUASI S2'!C34 -> 7 | D34: ='[5]DP8 CAIHUASI S1'!D34+'[5]DP6 CAIHUASI S2'!D34 -> 16 | E34: ='[5]DP8 CAIHUASI S1'!E34+'[5]DP6 CAIHUASI S2'!E34 -> 0 | F34: ='[5]DP8 CAIHUASI S1'!F34+'[5]DP6 CAIHUASI S2'!F34 -> 1 | G34: ='[5]DP8 CAIHUASI S1'!G34+'[5]DP6 CAIHUASI S2'!G34 -> 17 | H34: ='[5]DP8 CAIHUASI S1'!H34+'[5]DP6 CAIHUASI S2'!H34 -> 0 | I34: ='[5]DP8 CAIHUASI S1'!I34+'[5]DP6 CAIHUASI S2'!I34 -> 7 | ... N34: ='[5]DP8 CAIHUASI S1'!N34+'[5]DP6 CAIHUASI S2'!N34 -> 0 | O34: =SUM(B34:N34) -> 121 | P34: =O34/$O$35 -> 0.032292501
A35: TOTAL | B35: =SUM(B11:B34) -> 787 | C35: =SUM(C11:C34) -> 176 | D35: =SUM(D11:D34) -> 509 | E35: =SUM(E11:E34) -> 3 | F35: =SUM(F11:F34) -> 81 | G35: =SUM(G11:G34) -> 621 | H35: =SUM(H11:H34) -> 62 | I35: =SUM(I11:I34) -> 287 | ... P35: =SUM(P11:P34) -> 1
A36: (%) | B36: =B35/$O$35 -> 0.21003469 | C36: =C35/$O$35 -> 0.04697091 | D36: =D35/$O$35 -> 0.13584201 | E36: =E35/$O$35 -> 0.00080064051 | F36: =F35/$O$35 -> 0.021617294 | G36: =G35/$O$35 -> 0.16573259 | H36: =H35/$O$35 -> 0.016546571 | I36: =I35/$O$35 -> 0.076594609 | ... N36: =N35/$O$35 -> 0 | O36: =SUM(B36:N36) -> 1

Sheet dia 6
A3: RESUMEN DE CONTEO
A4: CLASIFICACIÓN DE VEHÍCULOS
A6: CAMINO:DOBLE VIA ORURO - COCHABAMBA | J6: DEPARTAMENTO:
A7: ESTACIÓN: Villapata | F7: Nº. | G7: S/N
A8: TRAMO: 1 | J8: FECHA:
A10: HORA DE - A | B10: AUTOMÓVILES VAGONETAS Y JEEP | C10: CAMIONETAS | D10: MINIBUSES | E10: MICROBUSES (DOS EJES) | F10: BÚS MEDIANO (DOS EJES) | G10: BÚS GRANDE (DOS O MAS EJES) | H10: CAMIÓN MEDIANO (DOS EJES) | I10: CAMIÓN GRANDE ( DOS EJES) | J10: CAMION GRANDE (TRES EJES) | K10: CAMIÓN CON SEMIRREMOLQUE | L10: CAMION CON REMOLQUE | M10: MOTOCICLETAS | N10: OTROS VEHICULOS | O10: TOTAL | P10: PORCENTAJE
A11: 0 - 1 | B11: ='[6]DP8 CAIHUASI S1'!B11+'[6]DP6 CAIHUASI S2'!B11 -> 24 | C11: ='[6]DP8 CAIHUASI S1'!C11+'[6]DP6 CAIHUASI S2'!C11 -> 9 | D11: ='[6]DP8 CAIHUASI S1'!D11+'[6]DP6 CAIHUASI S2'!D11 -> 6 | E11: ='[6]DP8 CAIHUASI S1'!E11+'[6]DP6 CAIHUASI S2'!E11 -> 0 | F11: ='[6]DP8 CAIHUASI S1'!F11+'[6]DP6 CAIHUASI S2'!F11 -> 7 | G11: ='[6]DP8 CAIHUASI S1'!G11+'[6]DP6 CAIHUASI S2'!G11 -> 32 | H11: ='[6]DP8 CAIHUASI S1'!H11+'[6]DP6 CAIHUASI S2'!H11 -> 8 | I11: ='[6]DP8 CAIHUASI S1'!I11+'[6]DP6 CAIHUASI S2'!I11 -> 12 | ... N11: ='[6]DP8 CAIHUASI S1'!N11+'[6]DP6 CAIHUASI S2'!N11 -> 0 | O11: =SUM(B11:N11) -> 147 | P11: =O11/$O$35 -> 0.039558665
A12: 1 - 2 | B12: ='[6]DP8 CAIHUASI S1'!B12+'[6]DP6 CAIHUASI S2'!B12 -> 10 | C12: ='[6]DP8 CAIHUASI S1'!C12+'[6]DP6 CAIHUASI S2'!C12 -> 1 | D12: ='[6]DP8 CAIHUASI S1'!D12+'[6]DP6 CAIHUASI S2'!D12 -> 7 | E12: ='[6]DP8 CAIHUASI S1'!E12+'[6]DP6 CAIHUASI S2'!E12 -> 0 | F12: ='[6]DP8 CAIHUASI S1'!F12+'[6]DP6 CAIHUASI S2'!F12 -> 5 | G12: ='[6]DP8 CAIHUASI S1'!G12+'[6]DP6 CAIHUASI S2'!G12 -> 70 | H12: ='[6]DP8 CAIHUASI S1'!H12+'[6]DP6 CAIHUASI S2'!H12 -> 1 | I12: ='[6]DP8 CAIHUASI S1'!I12+'[6]DP6 CAIHUASI S2'!I12 -> 12 | ... N12: ='[6]DP8 CAIHUASI S1'!N12+'[6]DP6 CAIHUASI S2'!N12 -> 0 | O12: =SUM(B12:N12) -> 150 | P12: =O12/$O$35 -> 0.040365985
A13: 2 - 3 | B13: ='[6]DP8 CAIHUASI S1'!B13+'[6]DP6 CAIHUASI S2'!B13 -> 10 | C13: ='[6]DP8 CAIHUASI S1'!C13+'[6]DP6 CAIHUASI S2'!C13 -> 1 | D13: ='[6]DP8 CAIHUASI S1'!D13+'[6]DP6 CAIHUASI S2'!D13 -> 4 | E13: ='[6]DP8 CAIHUASI S1'!E13+'[6]DP6 CAIHUASI S2'!E13 -> 1 | F13: ='[6]DP8 CAIHUASI S1'!F13+'[6]DP6 CAIHUASI S2'!F13 -> 4 | G13: ='[6]DP8 CAIHUASI S1'!G13+'[6]DP6 CAIHUASI S2'!G13 -> 53 | H13: ='[6]DP8 CAIHUASI S1'!H13+'[6]DP6 CAIHUASI S2'!H13 -> 2 | I13: ='[6]DP8 CAIHUASI S1'!I13+'[6]DP6 CAIHUASI S2'!I13 -> 10 | ... N13: ='[6]DP8 CAIHUASI S1'!N13+'[6]DP6 CAIHUASI S2'!N13 -> 0 | O13: =SUM(B13:N13) -> 111 | P13: =O13/$O$35 -> 0.029870829
A14: 3 - 4 | B14: ='[6]DP8 CAIHUASI S1'!B14+'[6]DP6 CAIHUASI S2'!B14 -> 7 | C14: ='[6]DP8 CAIHUASI S1'!C14+'[6]DP6 CAIHUASI S2'!C14 -> 0 | D14: ='[6]DP8 CAIHUASI S1'!D14+'[6]DP6 CAIHUASI S2'!D14 -> 1 | E14: ='[6]DP8 CAIHUASI S1'!E14+'[6]DP6 CAIHUASI S2'!E14 -> 0 | F14: ='[6]DP8 CAIHUASI S1'!F14+'[6]DP6 CAIHUASI S2'!F14 -> 1 | G14: ='[6]DP8 CAIHUASI S1'!G14+'[6]DP6 CAIHUASI S2'!G14 -> 7 | H14: ='[6]DP8 CAIHUASI S1'!H14+'[6]DP6 CAIHUASI S2'!H14 -> 0 | I14: ='[6]DP8 CAIHUASI S1'!I14+'[6]DP6 CAIHUASI S2'!I14 -> 6 | ... N14: ='[6]DP8 CAIHUASI S1'!N14+'[6]DP6 CAIHUASI S2'!N14 -> 0 | O14: =SUM(B14:N14) -> 52 | P14: =O14/$O$35 -> 0.013993541
A15: 4 - 5 | B15: ='[6]DP8 CAIHUASI S1'!B15+'[6]DP6 CAIHUASI S2'!B15 -> 4 | C15: ='[6]DP8 CAIHUASI S1'!C15+'[6]DP6 CAIHUASI S2'!C15 -> 2 | D15: ='[6]DP8 CAIHUASI S1'!D15+'[6]DP6 CAIHUASI S2'!D15 -> 3 | E15: ='[6]DP8 CAIHUASI S1'!E15+'[6]DP6 CAIHUASI S2'!E15 -> 0 | F15: ='[6]DP8 CAIHUASI S1'!F15+'[6]DP6 CAIHUASI S2'!F15 -> 1 | G15: ='[6]DP8 CAIHUASI S1'!G15+'[6]DP6 CAIHUASI S2'!G15 -> 6 | H15: ='[6]DP8 CAIHUASI S1'!H15+'[6]DP6 CAIHUASI S2'!H15 -> 1 | I15: ='[6]DP8 CAIHUASI S1'!I15+'[6]DP6 CAIHUASI S2'!I15 -> 4 | ... N15: ='[6]DP8 CAIHUASI S1'!N15+'[6]DP6 CAIHUASI S2'!N15 -> 0 | O15: =SUM(B15:N15) -> 39 | P15: =O15/$O$35 -> 0.010495156
A16: 5 - 6 | B16: ='[6]DP8 CAIHUASI S1'!B16+'[6]DP6 CAIHUASI S2'!B16 -> 12 | C16: ='[6]DP8 CAIHUASI S1'!C16+'[6]DP6 CAIHUASI S2'!C16 -> 4 | D16: ='[6]DP8 CAIHUASI S1'!D16+'[6]DP6 CAIHUASI S2'!D16 -> 12 | E16: ='[6]DP8 CAIHUASI S1'!E16+'[6]DP6 CAIHUASI S2'!E16 -> 0 | F16: ='[6]DP8 CAIHUASI S1'!F16+'[6]DP6 CAIHUASI S2'!F16 -> 0 | G16: ='[6]DP8 CAIHUASI S1'!G16+'[6]DP6 CAIHUASI S2'!G16 -> 9 | H16: ='[6]DP8 CAIHUASI S1'!H16+'[6]DP6 CAIHUASI S2'!H16 -> 0 | I16: ='[6]DP8 CAIHUASI S1'!I16+'[6]DP6 CAIHUASI S2'!I16 -> 5 | ... N16: ='[6]DP8 CAIHUASI S1'!N16+'[6]DP6 CAIHUASI S2'!N16 -> 0 | O16: =SUM(B16:N16) -> 83 | P16: =O16/$O$35 -> 0.022335845
A17: 6 - 7 | B17: ='[6]DP8 CAIHUASI S1'!B17+'[6]DP6 CAIHUASI S2'!B17 -> 16 | C17: ='[6]DP8 CAIHUASI S1'!C17+'[6]DP6 CAIHUASI S2'!C17 -> 6 | D17: ='[6]DP8 CAIHUASI S1'!D17+'[6]DP6 CAIHUASI S2'!D17 -> 18 | E17: ='[6]DP8 CAIHUASI S1'!E17+'[6]DP6 CAIHUASI S2'!E17 -> 0 | F17: ='[6]DP8 CAIHUASI S1'!F17+'[6]DP6 CAIHUASI S2'!F17 -> 2 | G17: ='[6]DP8 CAIHUASI S1'!G17+'[6]DP6 CAIHUASI S2'!G17 -> 10 | H17: ='[6]DP8 CAIHUASI S1'!H17+'[6]DP6 CAIHUASI S2'!H17 -> 1 | I17: ='[6]DP8 CAIHUASI S1'!I17+'[6]DP6 CAIHUASI S2'!I17 -> 6 | ... N17: ='[6]DP8 CAIHUASI S1'!N17+'[6]DP6 CAIHUASI S2'!N17 -> 0 | O17: =SUM(B17:N17) -> 109 | P17: =O17/$O$35 -> 0.029332616
A18: 7 - 8 | B18: ='[6]DP8 CAIHUASI S1'!B18+'[6]DP6 CAIHUASI S2'!B18 -> 39 | C18: ='[6]DP8 CAIHUASI S1'!C18+'[6]DP6 CAIHUASI S2'!C18 -> 9 | D18: ='[6]DP8 CAIHUASI S1'!D18+'[6]DP6 CAIHUASI S2'!D18 -> 17 | E18: ='[6]DP8 CAIHUASI S1'!E18+'[6]DP6 CAIHUASI S2'!E18 -> 0 | F18: ='[6]DP8 CAIHUASI S1'!F18+'[6]DP6 CAIHUASI S2'!F18 -> 1 | G18: ='[6]DP8 CAIHUASI S1'!G18+'[6]DP6 CAIHUASI S2'!G18 -> 6 | H18: ='[6]DP8 CAIHUASI S1'!H18+'[6]DP6 CAIHUASI S2'!H18 -> 1 | I18: ='[6]DP8 CAIHUASI S1'!I18+'[6]DP6 CAIHUASI S2'!I18 -> 10 | ... N18: ='[6]DP8 CAIHUASI S1'!N18+'[6]DP6 CAIHUASI S2'!N18 -> 0 | O18: =SUM(B18:N18) -> 134 | P18: =O18/$O$35 -> 0.03606028
A19: 8 - 9 | B19: ='[6]DP8 CAIHUASI S1'!B19+'[6]DP6 CAIHUASI S2'!B19 -> 56 | C19: ='[6]DP8 CAIHUASI S1'!C19+'[6]DP6 CAIHUASI S2'!C19 -> 17 | D19: ='[6]DP8 CAIHUASI S1'!D19+'[6]DP6 CAIHUASI S2'!D19 -> 25 | E19: ='[6]DP8 CAIHUASI S1'!E19+'[6]DP6 CAIHUASI S2'!E19 -> 2 | F19: ='[6]DP8 CAIHUASI S1'!F19+'[6]DP6 CAIHUASI S2'!F19 -> 2 | G19: ='[6]DP8 CAIHUASI S1'!G19+'[6]DP6 CAIHUASI S2'!G19 -> 14 | H19: ='[6]DP8 CAIHUASI S1'!H19+'[6]DP6 CAIHUASI S2'!H19 -> 4 | I19: ='[6]DP8 CAIHUASI S1'!I19+'[6]DP6 CAIHUASI S2'!I19 -> 4 | ... N19: ='[6]DP8 CAIHUASI S1'!N19+'[6]DP6 CAIHUASI S2'!N19 -> 0 | O19: =SUM(B19:N19) -> 173 | P19: =O19/$O$35 -> 0.046555436
A20: 9 - 10 | B20: ='[6]DP8 CAIHUASI S1'!B20+'[6]DP6 CAIHUASI S2'!B20 -> 38 | C20: ='[6]DP8 CAIHUASI S1'!C20+'[6]DP6 CAIHUASI S2'!C20 -> 7 | D20: ='[6]DP8 CAIHUASI S1'!D20+'[6]DP6 CAIHUASI S2'!D20 -> 11 | E20: ='[6]DP8 CAIHUASI S1'!E20+'[6]DP6 CAIHUASI S2'!E20 -> 1 | F20: ='[6]DP8 CAIHUASI S1'!F20+'[6]DP6 CAIHUASI S2'!F20 -> 1 | G20: ='[6]DP8 CAIHUASI S1'!G20+'[6]DP6 CAIHUASI S2'!G20 -> 13 | H20: ='[6]DP8 CAIHUASI S1'!H20+'[6]DP6 CAIHUASI S2'!H20 -> 1 | I20: ='[6]DP8 CAIHUASI S1'!I20+'[6]DP6 CAIHUASI S2'!I20 -> 10 | ... N20: ='[6]DP8 CAIHUASI S1'!N20+'[6]DP6 CAIHUASI S2'!N20 -> 0 | O20: =SUM(B20:N20) -> 124 | P20: =O20/$O$35 -> 0.033369214
