Workbook

Sheet TRAFICO DIARIO
A4: DIA 1 Lunes
D6: Configuracion Vehicular | F6: 0-1 | G6: 1-2 | H6: 2-3 | I6: 3-4 | J6: 4-5 | K6: 5-6 | L6: 6-7 | M6: 7-8 | N6: 8-9 | O6: 9-10 | P6: 10-11 | Q6: 11-12 | R6: 12-13 | S6: 13-14 | T6: 14-15 | U6: 15-16 | V6: 16-17 | W6: 17-18 | X6: 18-19 | Y6: 19-20 | Z6: 20-21 | AA6: 21-22 | AB6: 22-23 | AC6: 23-24 | AD6: ∑TOTAL
C7: 1 | G7: 2 | H7: 2 | I7: 3 | J7: 5 | K7: 15 | L7: 18 | M7: 22 | N7: 12 | O7: 40 | P7: 12 | Q7: 12 | R7: 15 | S7: 5 | T7: 20 | U7: 15 | V7: 22 | W7: 25 | X7: 41 | Y7: 50 | Z7: 15 | AA7: 12 | AB7: 6 | AC7: 4 | AD7: =SUM(F7:AC7) -> 373
C8: 2 | K8: 3 | L8: 4 | M8: 4 | N8: 12 | O8: 10 | P8: 5 | Q8: 12 | R8: 8 | S8: 7 | T8: 7 | U8: 2 | W8: 4 | X8: 1 | Z8: 1 | AD8: =SUM(F8:AC8) -> 80
C9: 3 | K9: 4 | M9: 4 | N9: 2 | Q9: 3 | S9: 3 | V9: 2 | W9: 7 | Y9: 2 | AD9: =SUM(F9:AC9) -> 27
C10: 4 | K10: 5 | M10: 3 | N10: 3 | O10: 3 | Q10: 4 | U10: 4 | W10: 3 | X10: 3 | Y10: 3 | Z10: 3 | AD10: =SUM(F10:AC10) -> 34
C11: 5 | M11: 2 | N11: 2 | O11: 2 | P11: 2 | V11: 1 | X11: 1 | Y11: 2 | Z11: 2 | AD11: =SUM(F11:AC11) -> 14
C12: 6 | M12: 2 | N12: 3 | O12: 2 | R12: 3 | U12: 2 | V12: 2 | W12: 2 | X12: 2 | Y12: 2 | Z12: 2 | AD12: =SUM(F12:AC12) -> 22
C13: 7 | AD13: =SUM(F13:AC13) -> 0
F14: Total trafico | AD14: =SUM(AD7:AD13) -> 550
A17: DIA 2 Martes
D19: Configuracion Vehicular | F19: 0-1 | G19: 1-2 | H19: 2-3 | I19: 3-4 | J19: 4-5 | K19: 5-6 | L19: 6-7 | M19: 7-8 | N19: 8-9 | O19: 9-10 | P19: 10-11 | Q19: 11-12 | R19: 12-13 | S19: 13-14 | T19: 14-15 | U19: 15-16 | V19: 16-17 | W19: 17-18 | X19: 18-19 | Y19: 19-20 | Z19: 20-21 | AA19: 21-22 | AB19: 22-23 | AC19: 23-24 | AD19: ∑TOTAL
C20: 1 | G20: 2 | H20: 2 | I20: 3 | J20: 5 | K20: 15 | L20: 18 | M20: 22 | N20: 18 | O20: 15 | P20: 12 | Q20: 12 | R20: 15 | S20: 5 | T20: 15 | U20: 15 | V20: 23 | W20: 25 | X20: 22 | Y20: 25 | Z20: 15 | AA20: 12 | AB20: 6 | AC20: 4 | AD20: =SUM(F20:AC20) -> 306
C21: 2 | K21: 3 | L21: 8 | M21: 8 | N21: 8 | O21: 8 | P21: 5 | Q21: 4 | R21: 8 | S21: 7 | T21: 7 | U21: 4 | W21: 4 | X21: 3 | Y21: 2 | Z21: 1 | AD21: =SUM(F21:AC21) -> 80
C22: 3 | K22: 2 | L22: 2 | M22: 4 | N22: 5 | Q22: 5 | S22: 5 | V22: 2 | W22: 7 | Y22: 2 | AD22: =SUM(F22:AC22) -> 34
C23: 4 | K23: 5 | M23: 4 | N23: 4 | O23: 3 | Q23: 5 | U23: 3 | W23: 3 | X23: 3 | Y23: 3 | Z23: 3 | AD23: =SUM(F23:AC23) -> 36
C24: 5 | M24: 2 | N24: 2 | O24: 2 | P24: 2 | V24: 3 | W24: 3 | X24: 1 | Y24: 2 | Z24: 2 | AD24: =SUM(F24:AC24) -> 19
C25: 6 | M25: 2 | N25: 3 | O25: 4 | P25: 4 | R25: 3 | U25: 2 | V25: 4 | W25: 2 | X25: 4 | Y25: 2 | Z25: 2 | AD25: =SUM(F25:AC25) -> 32
C26: 7 | AD26: =SUM(F26:AC26) -> 0
F27: Total trafico | AD27: =SUM(AD20:AD26) -> 507
A30: DIA 3 Miercoles
D32: Configuracion Vehicular | F32: 0-1 | G32: 1-2 | H32: 2-3 | I32: 3-4 | J32: 4-5 | K32: 5-6 | L32: 6-7 | M32: 7-8 | N32: 8-9 | O32: 9-10 | P32: 10-11 | Q32: 11-12 | R32: 12-13 | S32: 13-14 | T32: 14-15 | U32: 15-16 | V32: 16-17 | W32: 17-18 | X32: 18-19 | Y32: 19-20 | Z32: 20-21 | AA32: 21-22 | AB32: 22-23 | AC32: 23-24 | AD32: ∑TOTAL
C33: 1 | G33: 2 | H33: 1 | I33: 1 | J33: 5 | K33: 15 | L33: 8 | M33: 22 | N33: 22 | O33: 15 | P33: 3 | Q33: 12 | R33: 16 | S33: 22 | T33: 15 | U33: 15 | V33: 23 | W33: 25 | X33: 22 | Y33: 25 | Z33: 15 | AA33: 12 | AB33: 6 | AC33: 4 | AD33: =SUM(F33:AC33) -> 306
C34: 2 | K34: 5 | L34: 5 | M34: 8 | N34: 11 | O34: 8 | P34: 2 | Q34: 3 | R34: 9 | S34: 7 | T34: 7 | U34: 10 | W34: 4 | X34: 3 | Y34: 2 | Z34: 1 | AA34: 1 | AD34: =SUM(F34:AC34) -> 86
C35: 3 | K35: 2 | L35: 2 | M35: 3 | N35: 3 | Q35: 5 | R35: 3 | S35: 5 | V35: 2 | W35: 4 | Y35: 3 | AA35: 1 | AD35: =SUM(F35:AC35) -> 33
C36: 4 | K36: 3 | M36: 3 | N36: 4 | O36: 3 | Q36: 5 | R36: 5 | U36: 3 | W36: 3 | X36: 3 | Y36: 3 | Z36: 3 | AD36: =SUM(F36:AC36) -> 38
C37: 5 | M37: 2 | N37: 2 | O37: 2 | P37: 2 | Q37: 2 | V37: 3 | W37: 5 | X37: 1 | Y37: 2 | Z37: 2 | AD37: =SUM(F37:AC37) -> 23
C38: 6 | M38: 2 | N38: 1 | O38: 2 | P38: 1 | R38: 3 | U38: 2 | V38: 4 | W38: 2 | X38: 4 | Y38: 2 | Z38: 2 | AD38: =SUM(F38:AC38) -> 25
C39: 7 | AD39: =SUM(F39:AC39) -> 0
F40: Total trafico | AD40: =SUM(AD33:AD39) -> 511
A43: DIA 4 Jueves
D45: Configuracion Vehicular | F45: 0-1 | G45: 1-2 | H45: 2-3 | I45: 3-4 | J45: 4-5 | K45: 5-6 | L45: 6-7 | M45: 7-8 | N45: 8-9 | O45: 9-10 | P45: 10-11 | Q45: 11-12 | R45: 12-13 | S45: 13-14 | T45: 14-15 | U45: 15-16 | V45: 16-17 | W45: 17-18 | X45: 18-19 | Y45: 19-20 | Z45: 20-21 | AA45: 21-22 | AB45: 22-23 | AC45: 23-24 | AD45: ∑TOTAL
C46: 1 | G46: 2 | H46: 2 | I46: 3 | J46: 10 | K46: 15 | L46: 18 | M46: 12 | N46: 18 | O46: 40 | P46: 12 | R46: 15 | T46: 20 | U46: 15 | V46: 22 | X46: 12 | Y46: 15 | Z46: 15 | AA46: 12 | AB46: 6 | AC46: 4 | AD46: =SUM(F46:AC46) -> 268
C47: 2 | K47: 2 | L47: 2 | M47: 4 | N47: 8 | P47: 4 | Q47: 7 | R47: 8 | U47: 4 | W47: 4 | X47: 4 | Y47: 4 | Z47: 8 | AD47: =SUM(F47:AC47) -> 59
C48: 3 | K48: 4 | M48: 4 | O48: 2 | Q48: 2 | S48: 6 | V48: 3 | W48: 4 | X48: 4 | Y48: 4 | Z48: 2 | AD48: =SUM(F48:AC48) -> 35
C49: 4 | K49: 5 | L49: 2 | M49: 2 | N49: 2 | P49: 2 | S49: 2 | U49: 4 | W49: 4 | Y49: 6 | AD49: =SUM(F49:AC49) -> 29
C50: 5 | N50: 2 | O50: 2 | R50: 1 | V50: 2 | W50: 3 | X50: 4 | AD50: =SUM(F50:AC50) -> 14
C51: 6 | M51: 2 | V51: 2 | W51: 3 | X51: 3 | Z51: 2 | AD51: =SUM(F51:AC51) -> 12
C52: 7 | AD52: =SUM(F52:AC52) -> 0
F53: Total trafico | AD53: =SUM(AD46:AD52) -> 417
...

Sheet GRAFICAS
BH1: Lunes | BI1: Martes | BJ1: Miércoles | BK1: Jueves | BL1: Viernes | BM1: Sábado | BN1: Domingo
BH2: 381 | BI2: 340 | BJ2: 354 | BK2: 409 | BL2: 409 | BM2: 362 | BN2: 343
BH3: 62 | BI3: 57 | BJ3: 46 | BK3: 55 | BL3: 61 | BM3: 37 | BN3: 40
BH4: 22 | BI4: 14 | BJ4: 10 | BK4: 28 | BL4: 22 | BM4: 24 | BN4: 6
BH5: 29 | BI5: 31 | BJ5: 22 | BK5: 25 | BL5: 26 | BM5: 22 | BN5: 14
BH6: 6 | BI6: 6 | BJ6: 4 | BK6: 7 | BL6: 5 | BM6: 3 | BN6: 2
BH7: 9 | BI7: 7 | BJ7: 4 | BK7: 6 | BL7: 3 | BM7: 3 | BN7: 1
BH8: 5 | BI8: 5 | BJ8: 4 | BK8: 4 | BL8: 4 | BM8: 1 | BN8: 2
BG9: Suma | BH9: =SUM(BH2:BH8) -> 514 | BI9: =SUM(BI2:BI8) -> 460 | BJ9: =SUM(BJ2:BJ8) -> 444 | BK9: =SUM(BK2:BK8) -> 534 | BL9: =SUM(BL2:BL8) -> 530 | BM9: =SUM(BM2:BM8) -> 452 | BN9: =SUM(BN2:BN8) -> 408

Sheet TPD
E2: Fe.M= Factor de correccion estacional | J2: 1.1
E3: IMDA= INTENSIDAD MEDIA ANUAL DE LA UNIDAD DE PEAJE
E4: IMDM: INTENSIDAD PROMEDIO DIARIA DEL MES DE LA UNIDAD DE PEAJE
E6: Tn=To(1+r)´N-1
E7: FACTOR DE CRECIMIENTO | J7: =((1+J9)^(J8-1)) -> 1.031
E8: N= NUMERO DE AÑOS DE CONCTRUCCION | J8: 2
E9: r= TASA DE CRECIMIENTO DEL TRAFICO | J9: 0.031 | K9: 0.031
C11: Configuracion vehicular | E11: No de ejes/llantas | F11: Long. Max metros | G11: Lunes | H11: Martes | I11: Miercoles | J11: Jueves | K11: Viernes | L11: Sabado | M11: Domingo | N11: ∑TOTAL TPD | P11: IMD
B12: 1 | E12: 1RS-1RS | G12: ='TRAFICO DIARIO'!AD7 -> 373 | H12: ='TRAFICO DIARIO'!AD20 -> 306 | I12: ='TRAFICO DIARIO'!AD33 -> 306 | J12: ='TRAFICO DIARIO'!AD46 -> 268 | K12: ='TRAFICO DIARIO'!AD59 -> 272 | L12: ='TRAFICO DIARIO'!AD72 -> 202 | M12: ='TRAFICO DIARIO'!AD85 -> 228 | N12: =SUM(G12:M12)/7 -> 279.28571 | P12: =N12*$J$7*$J$2 -> 316.73793
B13: 2 | E13: 1RS-1RS | G13: ='TRAFICO DIARIO'!AD8 -> 80 | H13: ='TRAFICO DIARIO'!AD21 -> 80 | I13: ='TRAFICO DIARIO'!AD34 -> 86 | J13: ='TRAFICO DIARIO'!AD47 -> 59 | K13: ='TRAFICO DIARIO'!AD60 -> 80 | L13: ='TRAFICO DIARIO'!AD73 -> 42 | M13: ='TRAFICO DIARIO'!AD86 -> 33 | N13: =SUM(G13:M13)/7 -> 65.714286 | P13: =N13*$J$7*$J$2 -> 74.526571
B14: 4 | E14: 1RS-2RD | G14: ='TRAFICO DIARIO'!AD9 -> 27 | H14: ='TRAFICO DIARIO'!AD22 -> 34 | I14: ='TRAFICO DIARIO'!AD35 -> 33 | J14: ='TRAFICO DIARIO'!AD48 -> 35 | K14: ='TRAFICO DIARIO'!AD61 -> 35 | L14: ='TRAFICO DIARIO'!AD74 -> 27 | M14: ='TRAFICO DIARIO'!AD87 -> 10 | N14: =SUM(G14:M14)/7 -> 28.714286 | P14: =N14*$J$7*$J$2 -> 32.564871
B15: 3 | E15: 1RS-1RD | G15: ='TRAFICO DIARIO'!AD10 -> 34 | H15: ='TRAFICO DIARIO'!AD23 -> 36 | I15: ='TRAFICO DIARIO'!AD36 -> 38 | J15: ='TRAFICO DIARIO'!AD49 -> 29 | K15: ='TRAFICO DIARIO'!AD62 -> 41 | L15: ='TRAFICO DIARIO'!AD75 -> 30 | M15: ='TRAFICO DIARIO'!AD88 -> 19 | N15: =SUM(G15:M15)/7 -> 32.428571 | P15: =N15*$J$7*$J$2 -> 36.777243
B16: 6 | E16: 1RS-2RD-3RD | F16: 18,6 | G16: ='TRAFICO DIARIO'!AD11 -> 14 | H16: ='TRAFICO DIARIO'!AD24 -> 19 | I16: ='TRAFICO DIARIO'!AD37 -> 23 | J16: ='TRAFICO DIARIO'!AD50 -> 14 | K16: ='TRAFICO DIARIO'!AD63 -> 15 | L16: 9 | M16: ='TRAFICO DIARIO'!AD89 -> 6 | N16: =SUM(G16:M16)/7 -> 14.285714 | P16: =N16*$J$7*$J$2 -> 16.201429
B17: 5 | E17: 1RS-2RD-2RD | F17: 18,6 | G17: ='TRAFICO DIARIO'!AD12 -> 22 | H17: ='TRAFICO DIARIO'!AD25 -> 32 | I17: ='TRAFICO DIARIO'!AD38 -> 25 | J17: ='TRAFICO DIARIO'!AD51 -> 12 | K17: ='TRAFICO DIARIO'!AD64 -> 16 | L17: ='TRAFICO DIARIO'!AD77 -> 5 | M17: ='TRAFICO DIARIO'!AD90 -> 8 | N17: =SUM(G17:M17)/7 -> 17.142857 | P17: =N17*$J$7*$J$2 -> 19.441714
B18: 7 | E18: 1RD-1RD-3RD | F18: 18,6 | G18: ='TRAFICO DIARIO'!AD13 -> 0 | H18: ='TRAFICO DIARIO'!AD26 -> 0 | I18: ='TRAFICO DIARIO'!AD39 -> 0 | J18: ='TRAFICO DIARIO'!AD52 -> 0 | K18: ='TRAFICO DIARIO'!AD65 -> 0 | L18: ='TRAFICO DIARIO'!AD78 -> 4 | M18: ='TRAFICO DIARIO'!AD91 -> 0 | N18: =SUM(G18:M18)/7 -> 0.57142857 | P18: =N18*$J$7*$J$2 -> 0.64805714
C19: TOTAL PROMEDIO DIARIO (VEHICULOS/DIA) | G19: =SUM(G12:G18)/7 -> 78.571429 | H19: =SUM(H12:H18)/7 -> 72.428571 | I19: =SUM(I12:I18)/7 -> 73 | J19: =SUM(J12:J18)/7 -> 59.571429 | K19: =SUM(K12:K18)/7 -> 65.571429 | L19: =SUM(L12:L18)/7 -> 45.571429 | M19: =SUM(M12:M18)/7 -> 43.428571 | N19: =SUM(N12:N18) -> 438.14286 | P19: =SUM(P12:P18) -> 496.89781
N20: SUMA | P20: SUMA

Sheet CALCULO DE ESALs
F4: EJE DELANTERO | G4: EJES TRASEROS | K4: PESO TOTAL PERMITIDO (Tn) | L4: FACTOR DE EQUIVALENCIA | Q4: IMDA PARA EL AÑO n | R4: F IMDA
B5: Configuracion Vehicular | D5: No de ejes/llantas | E5: Long. Max metros | F5: 1° EJE | G5: 2° EJE | H5: 3° EJE | I5: 4° EJE | J5: 5° EJE | L5: 1° EJE | M5: 2° EJE | N5: 3° EJE | O5: 4° EJE | P5: 5° EJE
A6: 1 | D6: 1RS-1RS | F6: 1 | G6: 1 | K6: =SUM(F6:J6) -> 2 | L6: =(F6/6.6)^4 -> 0.00052701656 | M6: =(G6/6.6)^4 -> 0.00052701656 | N6: =(H6/6.6)^4 -> 0 | Q6: =$I$19*TPD!P12 -> 11700.854 | R6: =SUM(L6:P6)*Q6 -> 12.333087
A7: 2 | D7: 1RS-1RS | F7: 7 | G7: 7 | K7: =SUM(F7:J7) -> 14 | L7: =(F7/6.6)^4 -> 1.2653667 | M7: =(G7/6.6)^4 -> 1.2653667 | N7: =(H7/6.6)^4 -> 0 | Q7: =$I$19*TPD!P13 -> 2753.1421 | R7: =SUM(L7:P7)*Q7 -> 6967.4688
A8: 3 | D8: 1RS-2RD | F8: 7 | G8: 18 | K8: =SUM(F8:J8) -> 25 | L8: =(F8/6.6)^4 -> 1.2653667 | M8: =(G8/15.1)^4 -> 2.0192135 | N8: =(H8/6.6)^4 -> 0 | Q8: =$I$19*TPD!P14 -> 1203.0034 | R8: =SUM(L8:P8)*Q8 -> 3951.3611
A9: 4 | D9: 1RS-1RD | F9: 7 | G9: 11 | K9: =SUM(F9:J9) -> 18 | L9: =(F9/6.6)^4 -> 1.2653667 | M9: =(G9/8.2)^4 -> 3.238287 | N9: 0 | Q9: =$I$19*TPD!P15 -> 1358.6158 | R9: =SUM(L9:P9)*Q9 -> 6118.7349
A10: 6 | D10: 1RS-2RD-3RD | F10: 7 | G10: 18 | H10: 25 | K10: =SUM(F10:J10) -> 50 | L10: =(F10/6.6)^4 -> 1.2653667 | M10: =(G10/15.1)^4 -> 2.0192135 | N10: =(H10/21.8)^3.9 -> 1.7060262 | Q10: =$I$19*TPD!P16 -> 598.50914 | R10: =SUM(L10:P10)*Q10 -> 2986.9236
A11: 5 | D11: 1RS-2RD-2RD | F11: 7 | G11: 18 | H11: 18 | K11: =SUM(F11:J11) -> 43 | L11: =(F11/6.6)^4 -> 1.2653667 | M11: =(G11/15.1)^4 -> 2.0192135 | N11: =(H11/15.1)^4 -> 2.0192135 | Q11: =$I$19*TPD!P17 -> 718.21097 | R11: =SUM(L11:P11)*Q11 -> 3809.2428
A12: 7 | D12: 1RD-1RD-3RD | F12: 7 | G12: 11 | H12: 25 | K12: =SUM(F12:J12) -> 43 | L12: =(F12/6.6)^4 -> 1.2653667 | M12: =(G12/8.2)^4 -> 3.238287 | N12: =(H12/21.8)^3.9 -> 1.7060262 | Q12: =$I$19*TPD!P18 -> 23.940366 | R12: =SUM(L12:P12)*Q12 -> 148.66201
P13: SUMA F IMDA | R13: =SUM(R6:R12) -> 23994.726
K16: N° DE CALZADAS | L16: N° DE SENTIDOS | M16: CARRILES/SENTIDO | N16: DIRECCIONAL Fd | O16: CARRIL Fc
D17: F IMDA | E17: FACTOR DE LA INTENSIDAD MEDIA DIARIA ANUAL | I17: =R13 -> 23994.726
D18: TPD | E18: TRAFICO PROMEDIO DIARIO | I18: =TPD!N19 -> 438.14286 | K18: 1 CALZADA | L18: 1 | M18: 1 | N18: 1 | O18: 1
D19: Fca | E19: FACTOR DE CRECIMIENTO ACUMULATIVO | I19: =(((1+I20)^(I21))-1)/I20 -> 36.941751 | L19: 1 | M19: 2 | N19: 1 | O19: 0.8
D20: r% | E20: TASA DE CRECIMIENTO | I20: 0.031 | L20: 1 | M20: 3 | N20: 1 | O20: 0.6
D21: n | E21: NUMERO DE AÑOS DEL PERIODO DE DISEÑO | I21: 25 | L21: 1 | M21: 4 | N21: 1 | O21: 0.5
D22: Fd | E22: FACTOR DIRECCIONAL Fd | I22: =N19 -> 1 | L22: 2 | M22: 1 | N22: 0.5 | O22: 1
D23: Fc | E23: FACTOR DE DISTRIBUCION POR CARRIL Fc | I23: =O19 -> 0.8 | L23: 2 | M23: 1 | N23: 0.5 | O23: 0.8
D24: EE= ESALs | I24: =I17*I22*I23*365 -> 7006460.1 | K24: CALZADA SEPARADA | L24: 2 | M24: 1 | N24: 0.5 | O24: 1
L25: 2 | M25: 2 | N25: 0.5 | O25: 0.8
L26: 2 | M26: 3 | N26: 0.5 | O26: 0.8
L27: 2 | M27: 4 | N27: 0.5 | O27: 0.8
J31: 505940.19

Sheet P. FLEXIBLE
B1: Autopista interurbana, de prinera importancia
B2: Ejes equivalentes de 8.2 TN según el estudio de trafico | E2: 8.2 | F2: Tn
B3: Suelo Sub rasante CBR=7% | E3: 11 | F3: %
B4: Temperatura media anual promedio, T=23.5° | E4: 18
B5: Dias promedio en los que llueve en el año 55 | E5: 66
B6: Velocidad media de circulacion de vehiculos pesados de 30km/h | E6: 30 | F6: km/h
A10: Paso 1 CONFIABILIDAD | D10: R= | E10: 90 | G10: Zr | H10: =H19 -> -1.282
A12: Tipo de camino | C12: CONFIABILIDAD RECOMENDADA | G12: CONFIABILIDAD ( R ) | H12: VALOR Zr
D13: Zona Urbana | E13: Zona Rural | G13: 50 | H13: 0
A14: Rutas Inter-estatales y autopistas | D14: 85-99.9 | E14: 80-99.9 | G14: 60 | H14: -0.253
A15: arterias principales | D15: 80-99 | E15: 75-99 | G15: 70 | H15: -0.524
A16: colectores | D16: 80-95 | E16: 75-95 | G16: 75 | H16: -0.671
A17: locales | D17: 50-80 | E17: 50-80 | G17: 80 | H17: -0.841
G18: 85 | H18: -1.037
G19: 90 | H19: -1.282
G20: 91 | H20: -1.34
A21: Paso 2 DESVIACION ESTANDAR | D21: S0 | E21: =C26 -> 0.45 | G21: 92 | H21: -1.405
G22: 93 | H22: -1.476
A23: PROYECTO DE PAVIMENTO | C23: S0 | G23: 94 | H23: -1.555
C24: P. Flexible | D24: P. Rigido | G24: 95 | H24: -1.645
C25: 0.40 - 0.50 | D25: 0.30 - 0.40 | G25: 96 | H25: -1.751
A26: CONSTRUCCION NUEVA | C26: 0.45 | D26: 0.35 | G26: 97 | H26: -1.881
A27: SOBRECAPAS | C27: 0.5 | D27: 0.4 | G27: 98 | H27: -2.054
G28: 99 | H28: -2.327
G29: 99.9 | H29: -3.09
G30: 99.99 | H30: -3.75
A34: Paso 3 INDICE DE SERVICIO
F35: Zonas Industriales
B36: Tipo de Via | C36: Serviciabilidad D final | F36: Pavimento Urbano Industrial | H36: 1.5 - 2.0
B38: Autopistas | C38: 2.5 - 3.0 | F38: Pavimento urbanoSecundario | H38: 1.5 - 2.0
B39: Carreteras | C39: 2.0 - 3.5
D41: Po= | E41: 4.2
D42: Pf = | E42: 2.5 | F42: Dato adoptado de la tabla ( Serv. Final)
D43: ΔPSI = | E43: =E41-E42 -> 1.7
A45: Paso 4 COEFICIENTES DE DRENAJE
A48: CALIDAD DE DRENAJE | C48: % DE HUMEADS EN QUE EL PAVIMENTO ESTA EXPUESTO A NIVELES DE HUMEDAD PROXIMO A LA SATURACION DURANTE EL ANO
H50: DIA DE LLUVIA/AÑO= | I50: =E5 -> 66
H51: % DIAS DE LLUVIA= | I51: =ROUND(I50/365,2) -> 0.18
A52: EXCELENTE | C52: 1.40-1.35 | D52: 1.35-1.30 | E52: 1.30-1.2 | F52: 1.2
A53: BUENO | C53: 1.35-1.25 | D53: 1.30-1.15 | E53: 1.2-1.00 | F53: 1 | H53: m2= | I53: 0.8
...

Sheet P. RIGIDO CAPA GRANULAR
B1: Autopista interurbana, de prinera importancia
B2: Ejes equivalentes de 8.2 TN según el estudio de trafico | E2: 8.2 | F2: Tn
B3: Suelo Sub rasante CBR=7% | E3: 11 | F3: %
B4: Temperatura media anual promedio, T=23.5° | E4: 18
B5: Dias promedio en los que llueve en el año 55 | E5: 66
B6: Velocidad media de circulacion de vehiculos pesados de 30km/h | E6: 30 | F6: km/h
A10: Paso 1 CONFIABILIDAD | D10: R= | E10: 90 | G10: Zr | H10: =H19 -> -1.282
A12: Tipo de camino | C12: CONFIABILIDAD RECOMENDADA | G12: CONFIABILIDAD ( R ) | H12: VALOR Zr
D13: Zona Urbana | E13: Zona Rural | G13: 50 | H13: 0
A14: Rutas Inter-estatales y autopistas | D14: 85-99.9 | E14: 80-99.9 | G14: 60 | H14: -0.253
A15: arterias principales | D15: 80-99 | E15: 75-99 | G15: 70 | H15: -0.524
A16: colectores | D16: 80-95 | E16: 75-95 | G16: 75 | H16: -0.671
A17: locales | D17: 50-80 | E17: 50-80 | G17: 80 | H17: -0.841
G18: 85 | H18: -1.037
G19: 90 | H19: -1.282
G20: 91 | H20: -1.34
A21: Paso 2 DESVIACION ESTANDAR | D21: S0 | E21: =D26 -> 0.35 | G21: 92 | H21: -1.405
G22: 93 | H22: -1.476
A23: PROYECTO DE PAVIMENTO | C23: S0 | G23: 94 | H23: -1.555
C24: P. Flexible | D24: P. Rigido | G24: 95 | H24: -1.645
C25: 0.40 - 0.50 | D25: 0.30 - 0.40 | G25: 96 | H25: -1.751
A26: CONSTRUCCION NUEVA | C26: 0.45 | D26: 0.35 | G26: 97 | H26: -1.881
A27: SOBRECAPAS | C27: 0.5 | D27: 0.4 | G27: 98 | H27: -2.054
G28: 99 | H28: -2.327
G29: 99.9 | H29: -3.09
G30: 99.99 | H30: -3.75
A34: Paso 3 INDICE DE SERVICIO
F35: Zonas Industriales
B36: Tipo de Via | C36: Serviciabilidad D final | F36: CALLE COMERCIALES E Industrial | H36: 2.25
B38: Autopistas | C38: 3 | F38: CALLES RESIDENCIALES Y ESTACIONAMIENTOS | H38: 2
B39: Carreteras | C39: 2.5
D41: Po= | E41: 4.2 | H41: Po= | I41: 4.0 - 4.2
D42: Pf = | E42: =C38 -> 3 | F42: Dato adoptado de la tabla ( Serv. Final)
D43: ΔPSI = | E43: =E41-E42 -> 1.2
A46: Paso 4 PERIODO DE DISEÑO
A48: TIPO DE CARRETRA | E48: PERIODO DE DISEÑOS EN AÑOS
A50: urbano de transito elevado | E50: 30 -50
A51: Interurbano de transito elevado | E51: 20-20
A52: Pavimento de baja intensidad de transito | E52: 15-25
A53: De baja intensidad de tranmsito pavimentacion con grava | E53: 10-20
...

Sheet P. RIGIDO BASE ESTABILIZADA
B1: Autopista interurbana, de prinera importancia
B2: Ejes equivalentes de 8.2 TN según el estudio de trafico | E2: 8.2 | F2: Tn
B3: Suelo Sub rasante CBR=7% | E3: 11 | F3: %
B4: Temperatura media anual promedio, T=23.5° | E4: 18
B5: Dias promedio en los que llueve en el año 55 | E5: 66
B6: Velocidad media de circulacion de vehiculos pesados de 30km/h | E6: 30 | F6: km/h
A10: Paso 1 CONFIABILIDAD | D10: R= | E10: 90 | G10: Zr | H10: =H19 -> -1.282
A12: Tipo de camino | C12: CONFIABILIDAD RECOMENDADA | G12: CONFIABILIDAD ( R ) | H12: VALOR Zr
D13: Zona Urbana | E13: Zona Rural | G13: 50 | H13: 0
A14: Rutas Inter-estatales y autopistas | D14: 85-99.9 | E14: 80-99.9 | G14: 60 | H14: -0.253
A15: arterias principales | D15: 80-99 | E15: 75-99 | G15: 70 | H15: -0.524
A16: colectores | D16: 80-95 | E16: 75-95 | G16: 75 | H16: -0.671
A17: locales | D17: 50-80 | E17: 50-80 | G17: 80 | H17: -0.841
G18: 85 | H18: -1.037
G19: 90 | H19: -1.282
G20: 91 | H20: -1.34
A21: Paso 2 DESVIACION ESTANDAR | D21: S0 | E21: =D26 -> 0.35 | G21: 92 | H21: -1.405
G22: 93 | H22: -1.476
A23: PROYECTO DE PAVIMENTO | C23: S0 | G23: 94 | H23: -1.555
C24: P. Flexible | D24: P. Rigido | G24: 95 | H24: -1.645
C25: 0.40 - 0.50 | D25: 0.30 - 0.40 | G25: 96 | H25: -1.751
A26: CONSTRUCCION NUEVA | C26: 0.45 | D26: 0.35 | G26: 97 | H26: -1.881
A27: SOBRECAPAS | C27: 0.5 | D27: 0.4 | G27: 98 | H27: -2.054
G28: 99 | H28: -2.327
G29: 99.9 | H29: -3.09
G30: 99.99 | H30: -3.75
L31: rural
L32: Cbr sub rasante 5%
L33: factor estacional 1.1
A34: Paso 3 INDICE DE SERVICIO | L34: tas de c fecimientoi 3.1
F35: Zonas Industriales | L35: periodo de diseño construccion 2 años
B36: Tipo de Via | C36: Serviciabilidad D final | F36: CALLE COMERCIALES E Industrial | H36: 2.25 | L36: autopista de 1 calzada
L37: 1 sentido
B38: Autopistas | C38: 3 | F38: CALLES RESIDENCIALES Y ESTACIONAMIENTOS | H38: 2 | L38: 2 carriles por sentido
B39: Carreteras | C39: 2.5 | L39: periodo de diseño 25 años
L40: construccion nueva
D41: Po= | E41: 4.2 | H41: Po= | I41: 4.0 - 4.2 | L41: dias de lluvia 65 dias al aaño
D42: Pf = | E42: =C38 -> 3 | F42: Dato adoptado de la tabla ( Serv. Final) | L42: junta con pasadores (confinada)
D43: ΔPSI = | E43: =E41-E42 -> 1.2 | L43: Longitud del tramo 1200 (m)
L44: anoche de carill 3.50 (m)
...
